Workbook

Sheet CHECKING
D7: CREDIT MOVMENTS AS PER STATEMENT | E7: =SUM(STATEMENT!C5:C1048576) -> 2747041369
D8: CREDIT MOVMENTS AS PER ALL ACCOUNTS | E8: =MVT_CAISSE!C9+BANQUE!C7+'VENTE_EXP_LOCAL_(CREDIT)'!C10 -> 2747041369
D9: DIFFRENCE | E9: =E7-E8 -> 0
D12: DEBIT MOVMENTS AS PER STATEMENT | E12: =SUM(STATEMENT!D5:D1048576) -> 2780145941
D13: DEBIT MOVMENTS AS PER ALL ACCOUNTS | E13: =MVT_CAISSE!D9+BANQUE!D7+'ACHAT_MP_(DEBIT)'!C10+'DEPENCES_EXP ACC_(DEBIT)'!C8+'AUTRES_DEPENSES_(DEBIT)'!C15 -> 2780145941
D14: DIFFRENCE | E14: =E12-E13 -> 0

Sheet STATEMENT
A1: NAP ATLANTIC BANK STATEMENT 2026
A3: Date | B3: DESCRIPTION | C3: CREDIT | D3: DEBIT | E3: SOLDE | F3: NUM DE CHEQUE | G3: MOTIF | H3: CATEGORIE | I3: DIFFERENCE
A4: 46023 | B4: SOLDE INITIAL | E4: 23372793
A5: 46027 | B5: ORDI TRADING (RAJIBER) EXP ACC | D5: 3400000 | E5: =E4+C5-D5 -> 19972793 | F5: 5447234 | H5: TRANSITER
A6: 46027 | B6: ORDI TRADING (RAJIBER) EXP ACC | D6: 1258530 | E6: =E5+C6-D6 -> 18714263 | F6: 5447233 | H6: TRANSITER
A7: 46029 | B7: ABDULSALAM OLAKOUNLE ABDULJELIL | D7: 2000000 | E7: =E6+C7-D7 -> 16714263 | F7: 5447235 | G7: ODJE NIGERIA CONTRACTOR ( ALL TANK FABRICATION) | H7: SERVICE
A8: 46029 | B8: SEGUB GUCE | D8: 1080382 | E8: =E7+C8-D8 -> 15633881 | G8: USN-26003902_bl MEDUCT180949_ SHEA DOC | H8: BFU
A9: 46034 | B9: DGI | D9: 10300265 | E9: =E8+C9-D9 -> 5333616 | G9: DECLARATION IMPOT DEC 2025 | H9: DGI
A10: 46034 | B10: VERSEMENT SAMBA SYLVERSTRE | C10: 5500000 | E10: =E9+C10-D10 -> 10833616 | G10: UD CAKE SALES_50MT@110K_OLD STOCK 2025 | H10: SALES/ UD CAKES
A11: 46034 | B11: ABOKI M. DIDER | D11: 1200000 | E11: =E10+C11-D11 -> 9633616 | F11: 5447238 | G11: HOUSE RENT OF GLO | H11: HOUSE RENT
A12: 46034 | B12: DGI | D12: 575278 | E12: =E11+C12-D12 -> 9058338 | H12: DGI
A13: 46035 | B13: PROSPERITY AND GLORY OF GOD | D13: 2646300 | E13: =E12+C13-D13 -> 6412038 | F13: 5447236 | G13: ALFRED TRANSITER EXP ACC | H13: TRANSITER
A14: 46036 | B14: VASWAMI MANOJ LAKHI (STE ASHASONU) | D14: 2640000 | E14: =E13+C14-D14 -> 3772038 | F14: 5447237 | G14: LOYER MAGASIN SEKOU | H14: HOUSE RENT
A15: 46038 | B15: VERSEMENT SAMBA SYLVERSTRE | C15: 14500000 | E15: =E14+C15-D15 -> 18272038 | G15: UD CAKE SALES_100MT@145K | H15: SALES/ UD CAKES
A16: 46038 | B16: VERSEMENT GARBA YBRAHIM | C16: 5000000 | E16: =E15+C16-D16 -> 23272038 | G16: CAISSE DEPOSIT BY NAP | H16: CAISSE DEPOSIT
A17: 46038 | B17: SEGUB GUCE | D17: 3978467 | E17: =E16+C17-D17 -> 19293571 | G17: USN-26008665_264186756_SHEA BUTTER | H17: BFU
A18: 46038 | B18: SEGUB GUCE | D18: 2004059 | E18: =E17+C18-D18 -> 17289512 | G18: USN-26008661_264169298_SHEA BUTTER | H18: BFU
A19: 46038 | B19: VERSEMENT SAMBA SYLVERSTRE | C19: 1500000 | E19: =E18+C19-D19 -> 18789512 | G19: UD CAKE SALES_300MT@145K_RGLMT | H19: SALES/ UD CAKES
A20: 46038 | B20: HOUESSOU GBETOHO EZECKIEL | D20: 660000 | E20: =E19+C20-D20 -> 18129512 | F20: 5447239 | G20: LOYER MAISON M. RAJ KUMAR | H20: HOUSE RENT
A21: 46038 | B21: SEGUB GUCE | D21: 65625 | E21: =E20+C21-D21 -> 18063887 | G21: RENOUVELLEMENT BFU_BL 265674057 | H21: BFU
A22: 46041 | B22: SEGUB GUCE | D22: 4372054 | E22: =E21+C22-D22 -> 13691833 | G22: USN-26010887_264186615_SHEA BUTTER | H22: BFU
A23: 46041 | B23: DOSSA SEMADO EUSTACHE RENE | D23: 4255000 | E23: =E22+C23-D23 -> 9436833 | F23: 5447241 | G23: TRAVAUX MISE EN TERRE_ 37 PRISES_UNITE 115K. | H23: SERVICE
A24: 46041 | B24: IDRISSOU APHISSOU | D24: 774522 | E24: =E23+C24-D24 -> 8662311 | F24: 5447242 | G24: OLABI LABOUR (COTTON-UD CAKE-SHEA NUT) | H24: LABOUR WORK
A25: 46041 | B25: ETS JKM EDITION | D25: 154715 | E25: =E24+C25-D25 -> 8507596 | F25: 5447240 | G25: ACHAT DE FOURNITURE_No facture EM1072646-610 | H25: PURCHASE/ OTHERS
A26: 46042 | B26: SEGUB GUCE | D26: 1037216 | E26: =E25+C26-D26 -> 7470380 | G26: USN-26013884_MEDUCT181871_SHEA DOC | H26: BFU
A27: 46043 | B27: VERSEMENT SAMBA SYLVERSTRE | C27: 14500000 | E27: =E26+C27-D27 -> 21970380 | G27: UD CAKE SALES_100MT@145K | H27: SALES/ UD CAKES
A28: 46044 | B28: NOCIBE | D28: 2471134 | E28: =E27+C28-D28 -> 19499246 | F28: 5662541 | G28: ACHAT DE CIMENT / COMPTE ARMEL/ PROJET 11 ETP PLANT | H28: PURCHASE/ OTHERS
A29: 46045 | B29: VERSEMENT SAMBA SYLVERSTRE | C29: 14500000 | E29: =E28+C29-D29 -> 33999246 | G29: UD CAKE SALES_100MT@145K | H29: SALES/ UD CAKES
A30: 46045 | B30: SEGUB GUCE | D30: 4706191 | E30: =E29+C30-D30 -> 29293055 | G30: USN-26015849_265085383_SHEA BUTTER | H30: BFU
A31: 46045 | B31: CERCLE DE DIEU | D31: 3000000 | E31: =E30+C31-D31 -> 26293055 | F31: 5447245 | G31: COTTON SEED TRANSPORT/ELIE | H31: TRANSPORT/COTTON SEED
A32: 46045 | B32: ETS DOS ESPOIR ET FILS | D32: 2000000 | E32: =E31+C32-D32 -> 24293055 | F32: 5447243 | G32: LABOUR WORK | H32: LABOUR WORK
A33: 46048 | B33: REGLEMENT REMISE DOCUMENTAIRE | D33: 12910170 | E33: =E32+C33-D33 -> 11382885 | G33: KH CHEMICAL (IMPORT OF HEXANE)_HLCURTM251200745 | H33: PURCHASE/ HEXANE
A34: 46049 | B34: ETS DOS ESPOIR ET FILS | D34: 1000000 | E34: =E33+C34-D34 -> 10382885 | F34: 5447246 | G34: LABOUR WORK | H34: LABOUR WORK
A35: 46050 | B35: EDS TRADE AND MORE (GABIN LCB) | D35: 5000000 | E35: =E34+C35-D35 -> 5382885 | F35: 5447247 | G35: COTTON SEED TRANSPORT/GABIN | H35: TRANSPORT/COTTON SEED
A36: 46050 | B36: SEGUB GUCE | D36: 2001241 | E36: =E35+C36-D36 -> 3381644 | G36: USN-26019619_265584223_SHEA BUTTER | H36: BFU
A37: 46050 | B37: SEGUB GUCE | D37: 1035448 | E37: =E36+C37-D37 -> 2346196 | G37: USN-26019610_MEDUCT182457_SHEA DOC | H37: BFU
A38: 46051 | B38: VERSEMENT SAMBA SYLVERSTRE | C38: 21750000 | E38: =E37+C38-D38 -> 24096196 | G38: UD CAKE SALES_150MT@145K | H38: SALES/ UD CAKES
A39: 46051 | B39: VERSEMENT SAMBA SYLVERSTRE | C39: 14500000 | E39: =E38+C39-D39 -> 38596196 | G39: UD CAKE SALES_100MT@145K | H39: SALES/ UD CAKES
A40: 46051 | B40: SEGUB GUCE | D40: 2389191 | E40: =E39+C40-D40 -> 36207005 | G40: USN-26019707_265584104_SHEA BUTTER | H40: BFU
A41: 46051 | B41: SEGUB GUCE | D41: 263900 | E41: =E40+C41-D41 -> 35943105 | G41: RENOUVELLEMENT BFU_USN-26020071 | H41: BFU
...

Sheet MVT_CAISSE
F3: CAISSE DEPOSIT | H3: =SUBTOTAL(9,H5:H5000) -> 251811400 | M3: WITHDRAWAL | O3: =SUBTOTAL(9,O5:O5000) -> 160953944 | T3: MITC | V3: =SUBTOTAL(9,V5:V5000) -> 1195000000 | AA3: REMBOURSEMENT | AC3: =SUBTOTAL(9,AC5:AC5000) -> 13767100
B4: PRODUIT | C4: MONTANT CREDIT | D4: MONTANT DEBIT | F4: DATE | G4: DESCRIPTION | H4: AMT | I4: CH NO | J4: MOTIF | K4: CATEGRIE | M4: DATE | N4: DESCRIPTION | O4: AMT | P4: CH NO | Q4: MOTIF | R4: CATEGRIE | T4: DATE | U4: DESCRIPTION | V4: AMT | W4: CH NO | X4: MOTIF | Y4: CATEGRIE | AA4: DATE | AB4: DESCRIPTION | AC4: AMT | AD4: CH NO | AE4: MOTIF | AF4: CATEGRIE
B5: CAISSE DEPOSIT | C5: =H3 -> 251811400 | F5: {=_xlfn.CHOOSECOLS(_xlfn._xlws.FILTER(STATEMENT!A3:H5027,STATEMENT!H3:H5027="CAISSE DEPOSIT"),1,2,3,6,7,8)} -> 46038 | G5: VERSEMENT GARBA YBRAHIM | H5: 5000000 | I5: 0 | J5: CAISSE DEPOSIT BY NAP | K5: CAISSE DEPOSIT | M5: {=_xlfn.CHOOSECOLS(_xlfn._xlws.FILTER(STATEMENT!A3:H5027,STATEMENT!H3:H5027="WITHDRAWAL"),1,2,4,6,7,8)} -> 46092 | N5: SANOUSSI MOUINOU | O5: 8000000 | P5: 5447259 | Q5: RETRAIT POUR NAP | R5: WITHDRAWAL | T5: {=_xlfn.CHOOSECOLS(_xlfn._xlws.FILTER(STATEMENT!A3:H5027,STATEMENT!H3:H5027="MITC"),1,2,4,6,7,8)} -> 46104 | U5: MITC | V5: 130000000 | W5: 5447269 | X5: REMISE POUR MITC | Y5: MITC | AA5: {=_xlfn.CHOOSECOLS(_xlfn._xlws.FILTER(STATEMENT!A3:H5027,STATEMENT!H3:H5027="REMBOURSEMENT"),1,2,4,6,7,8)} -> 46213 | AB5: DERE IMPORT EXPORT SARL U | AC5: 13767100 | AD5: 5822135 | AE5: REMBOURSEMENT DE COMMANDE NON EXECUTEE A DERE IMPORT EXPORT SARL U | AF5: REMBOURSEMENT
B6: WITHDRAWAL | D6: =O3 -> 160953944 | F6: 46059 | G6: VERSEMENT GARBA YBRAHIM | H6: 15000000 | I6: 0 | J6: CAISSE DEPOSIT BY NAP | K6: CAISSE DEPOSIT | M6: 46108 | N6: AFFO MOUSSA IBRAHIM | O6: 22000000 | P6: 5447270 | Q6: RETRAIT POUR NAP | R6: WITHDRAWAL | T6: 46104 | U6: MITC | V6: 95000000 | W6: 5447267 | X6: REMISE POUR MITC | Y6: MITC
B7: MITC | D7: =V3 -> 1195000000 | F7: 46063 | G7: VERSEMENT SANOUSSI MOUINOU | H7: 10000000 | I7: 0 | J7: CAISSE DEPOSIT BY NAP | K7: CAISSE DEPOSIT | M7: 46147 | N7: SANOUSSI MOUINOU | O7: 25000000 | P7: 0 | Q7: RETRAIT POUR NAP | R7: WITHDRAWAL | T7: 46122 | U7: MITC | V7: 60000000 | W7: 5447287 | X7: REMISE POUR MITC | Y7: MITC
B8: REMBOURSEMENT | D8: =AC3 -> 13767100 | F8: 46121 | G8: VERSEMENT ESPECES BY ABDOULAYE NADJIBATOU | H8: 61000000 | I8: 0 | J8: CAISSE DEPOSIT BY NAP | K8: CAISSE DEPOSIT | M8: 46163 | N8: AFFO MOUSSA IBRAHIM | O8: 20000000 | P8: 5822108 | Q8: RETRAIT POUR NAP | R8: WITHDRAWAL | T8: 46126 | U8: MITC | V8: 80000000 | W8: 5447293 | X8: REMISE POUR MITC | Y8: MITC
B9: TOTAL | C9: =SUM(C5:C8) -> 251811400 | D9: =SUM(D5:D8) -> 1369721044 | F9: 46121 | G9: VERSEMENT ESPECES BY KPEGLO GEORGES | H9: 7600000 | I9: 0 | J9: CAISSE DEPOSIT BY NAP | K9: CAISSE DEPOSIT | M9: 46175 | N9: CHEQUE 5822101 | O9: 1226972 | P9: 0 | Q9: 0 | R9: WITHDRAWAL | T9: 46127 | U9: MITC | V9: 105000000 | W9: 5447296 | X9: REMISE POUR MITC | Y9: MITC
F10: 46176 | G10: VERSEMENT ESPECES BY SHARMA RISHI | H10: 700000 | I10: 0 | J10: 0 | K10: CAISSE DEPOSIT | M10: 46175 | N10: 0 | O10: 1226972 | P10: 0 | Q10: 0 | R10: WITHDRAWAL | T10: 46141 | U10: MITC | V10: 50000000 | W10: ORDRE DE TRANSFERT | X10: VIREMENT POUR MITC | Y10: MITC
F11: 46212 | G11: MITC | H11: 30000000 | I11: 0 | J11: REMISE POUR NAP | K11: CAISSE DEPOSIT | M11: 46192 | N11: RETRAIT POUR NAP SARL/GARBA BOURAIMA | O11: 25000000 | P11: 5822119 | Q11: RETRAIT POUR NAP | R11: WITHDRAWAL | T11: 46149 | U11: MITC | V11: 120000000 | W11: 5822104 | X11: REMISE POUR MITC | Y11: MITC
F12: 46216 | G12: MITC | H12: 30000000 | I12: 0 | J12: REMISE POUR NAP | K12: CAISSE DEPOSIT | M12: 46251 | N12: REMISE POUR NAP ECOBANK | O12: 35000000 | P12: 5822141 | Q12: REMISE POUR NAP ECOBANK | R12: WITHDRAWAL | T12: 46170 | U12: MITC | V12: 120000000 | W12: 5822115 | X12: REMISE POUR MITC | Y12: MITC
F13: 46233 | G13: VERSEMENT ESPECES BY SHARMA RISHI | H13: 2500000 | I13: 0 | J13: 0 | K13: CAISSE DEPOSIT | M13: 46260 | N13: VERSEMENT ESPECES BY AFFO MOUSSA ABRAHIM | O13: 13500000 | P13: 5822167 | Q13: 0 | R13: WITHDRAWAL | T13: 46190 | U13: MITC | V13: 73000000 | W13: 5822117 | X13: REMISE POUR MITC | Y13: MITC
F14: 46234 | G14: VERSEMENT ESPECES BY AFFO MOUSSA ABRAHIM | H14: 500000 | I14: 0 | J14: 0 | K14: CAISSE DEPOSIT | M14: 46296 | N14: AFFO MOUSSA IBRAHIM | O14: 10000000 | P14: 5668780 | Q14: RETRAIT POUR NAP | R14: WITHDRAWAL | T14: 46195 | U14: MITC | V14: 200000000 | W14: 5822120 | X14: REMISE POUR MITC | Y14: MITC
F15: 46238 | G15: VERSEMENT ESPECES BY GARBA IBRAHIM | H15: 1200000 | I15: 0 | J15: 0 | K15: CAISSE DEPOSIT | T15: 46206 | U15: MITC | V15: 20000000 | W15: 0 | X15: REMISE POUR MITC | Y15: MITC
F16: 46244 | G16: VERSEMENT ESPECES BY GARBA IBRAHIM | H16: 1500000 | I16: 0 | J16: 0 | K16: CAISSE DEPOSIT | T16: 46206 | U16: MITC | V16: 130000000 | W16: 0 | X16: REMISE POUR MITC | Y16: MITC
F17: 46246 | G17: VERSEMENT ESPECES BY KPEGLO GEORGES KOUDOUS | H17: 17063900 | I17: 0 | J17: 0 | K17: CAISSE DEPOSIT | T17: 46206 | U17: MITC | V17: 12000000 | W17: 0 | X17: REMISE POUR MITC | Y17: MITC
F18: 46261 | G18: MITC | H18: 13999500 | I18: 0 | J18: REMISE POUR NAP | K18: CAISSE DEPOSIT
F19: 46266 | G19: MITC | H19: 15300000 | I19: 0 | J19: REMISE POUR NAP | K19: CAISSE DEPOSIT
F20: 46267 | G20: MITC | H20: 20448000 | I20: 0 | J20: REMISE POUR NAP | K20: CAISSE DEPOSIT
F21: 46272 | G21: MITC | H21: 20000000 | I21: 0 | J21: REMISE POUR NAP | K21: CAISSE DEPOSIT

Sheet BANQUE
F3: CONTRE ECRITURE | H3: =SUBTOTAL(9,H5:H5000) -> 8453944 | M3: FRAIS BANCAIRE | O3: =SUBTOTAL(9,O5:O5000) -> 925797
B4: PRODUIT | C4: MONTANT CREDIT | D4: MONTANT DEBIT | F4: DATE | G4: DESCRIPTION | H4: AMT | I4: CH NO | J4: MOTIF | K4: CATEGRIE | M4: DATE | N4: DESCRIPTION | O4: AMT | P4: CH NO | Q4: MOTIF | R4: CATEGRIE
B5: CONTRE ECRITURE | C5: =H3 -> 8453944 | F5: {=_xlfn.CHOOSECOLS(_xlfn._xlws.FILTER(STATEMENT!A3:H5027,STATEMENT!H3:H5027="CONTRE ECRITURE"),1,2,3,6,7,8)} -> 46170 | G5: REJET MONTANT ERRONE | H5: 226972 | I5: 0 | J5: 0 | K5: CONTRE ECRITURE | M5: {=_xlfn.CHOOSECOLS(_xlfn._xlws.FILTER(STATEMENT!A3:H5027,STATEMENT!H3:H5027="FRAIS BANCAIRE"),1,2,4,6,7,8)} -> 46085 | N5: COMMISION SUR DOMICILIATION EXPORT | O5: 33000 | P5: 0 | Q5: FRAIS BANCAIRE | R5: FRAIS BANCAIRE
B6: FRAIS BANCAIRE | D6: =O3 -> 925797 | F6: 46175 | G6: REJET CHEQUE 5822101 | H6: 1226972 | I6: 0 | J6: ABSENCE DE PROVISION | K6: CONTRE ECRITURE | M6: 46097 | N6: COMMISION SUR DOMICILIATION EXPORT | O6: 33000 | P6: 0 | Q6: FRAIS BANCAIRE | R6: FRAIS BANCAIRE
B7: TOTAL | C7: =SUM(C5:C6) -> 8453944 | D7: =SUM(D5:D6) -> 925797 | F7: 46262 | G7: REJET /REGLEMENT CHEQUE 5822169/ABSENCE DE PROVISION | H7: 7000000 | I7: 5822169 | J7: 0 | K7: CONTRE ECRITURE | M7: 46099 | N7: COMMISION SUR DOMICILIATION EXPORT | O7: 33000 | P7: 0 | Q7: FRAIS BANCAIRE | R7: FRAIS BANCAIRE
M8: 46111 | N8: COMMISION SUR DOMICILIATION EXPORT | O8: 33000 | P8: 0 | Q8: FRAIS BANCAIRE | R8: FRAIS BANCAIRE
M9: 46147 | N9: FRAIS SUR DEMANDE DE CHEQUIER | O9: 10000 | P9: 0 | Q9: 0 | R9: FRAIS BANCAIRE
M10: 46148 | N10: FRAIS SUR DEMANDE DE CHEQUIER | O10: 10000 | P10: 0 | Q10: 0 | R10: FRAIS BANCAIRE
M11: 46161 | N11: COMMISION SUR DOMICILIATION EXPORT | O11: 33000 | P11: 0 | Q11: FRAIS BANCAIRE | R11: FRAIS BANCAIRE
M12: 46161 | N12: COMMISION SUR DOMICILIATION EXPORT | O12: 33000 | P12: 0 | Q12: FRAIS BANCAIRE | R12: FRAIS BANCAIRE
M13: 46171 | N13: COMMISION SUR DOMICILIATION EXPORT | O13: 33000 | P13: 0 | Q13: FRAIS BANCAIRE | R13: FRAIS BANCAIRE
M14: 46171 | N14: COMMISION SUR DOMICILIATION EXPORT | O14: 33000 | P14: 0 | Q14: FRAIS BANCAIRE | R14: FRAIS BANCAIRE
M15: 46171 | N15: COMMISION SUR DOMICILIATION EXPORT | O15: 33000 | P15: 0 | Q15: FRAIS BANCAIRE | R15: FRAIS BANCAIRE
M16: 46175 | N16: COMMISION SUR CHEQUE IMPAYE | O16: 11000 | P16: 0 | Q16: FRAIS BANCAIRE | R16: FRAIS BANCAIRE
M17: 46178 | N17: FRAIS BANCAIRE | O17: 33000 | P17: 0 | Q17: FRAIS BANCAIRE | R17: FRAIS BANCAIRE
M18: 46189 | N18: FRAIS BANCAIRE | O18: 33000 | P18: 0 | Q18: FRAIS BANCAIRE | R18: FRAIS BANCAIRE
M19: 46192 | N19: FRAIS BANCAIRE | O19: 33000 | P19: 0 | Q19: FRAIS BANCAIRE | R19: FRAIS BANCAIRE
M20: 46192 | N20: FRAIS BANCAIRE | O20: 33000 | P20: 0 | Q20: FRAIS BANCAIRE | R20: FRAIS BANCAIRE
M21: 46192 | N21: FRAIS BANCAIRE | O21: 33000 | P21: 0 | Q21: FRAIS BANCAIRE | R21: FRAIS BANCAIRE
M22: 46198 | N22: FRAIS BANCAIRE | O22: 33000 | P22: 0 | Q22: FRAIS BANCAIRE | R22: FRAIS BANCAIRE
... M25: 46251 | N25: FRAIS BANCAIRE | O25: 36300 | P25: 0 | Q25: COMMISSION SUR DOMICILIATION EXPORT | R25: FRAIS BANCAIRE
M26: 46252 | N26: COMMISSION SUR DOMICILIATION | O26: 36300 | P26: 0 | Q26: 0 | R26: FRAIS BANCAIRE
M27: 46252 | N27: COMMISSION SUR DOMICILIATION | O27: 36300 | P27: 0 | Q27: 0 | R27: FRAIS BANCAIRE
M28: 46252 | N28: COMMISSION SUR DOMICILIATION | O28: 36300 | P28: 0 | Q28: 0 | R28: FRAIS BANCAIRE
M29: 46258 | N29: COMMISSION SUR DOMICILIATION | O29: 33000 | P29: 0 | Q29: 0 | R29: FRAIS BANCAIRE
M30: 46262 | N30: COMMIISION SUR REJET | O30: 11000 | P30: 0 | Q30: 0 | R30: FRAIS BANCAIRE
M31: 46265 | N31: INTERET DEBIT | O31: 45597 | P31: 0 | Q31: 0 | R31: FRAIS BANCAIRE
M32: 46265 | N32: COMMISSION SUR DOMICILIATION | O32: 33000 | P32: 0 | Q32: 0 | R32: FRAIS BANCAIRE
M33: 46274 | N33: COMMISION DOMICILIATION | O33: 33000 | P33: 0 | Q33: 0 | R33: FRAIS BANCAIRE
M34: 46276 | N34: COMMISION DOMICILIATION | O34: 33000 | P34: 0 | Q34: 0 | R34: FRAIS BANCAIRE

Sheet VENTE_EXP_LOCAL_(CREDIT)
E3: SALES/ UD CAKES | G3: =SUBTOTAL(9,G5:G5000) -> 552355048 | L3: SALES /COTTON SEED OIL | N3: =SUBTOTAL(9,N5:N5000) -> 638909287 | S3: SALES/ SOYA MEAL | U3: =SUBTOTAL(9,U5:U5000) -> 130207810 | Z3: SALES/ SOYABEAN | AB3: =SUBTOTAL(9,AB5:AB5000) -> 991312747 | AG3: SALES/ SOYABEAN | AI3: =SUBTOTAL(9,AI5:AI5000) -> 173991133
B4: PRODUIT | C4: MONTANT CREDIT | E4: DATE | F4: DESCRIPTION | G4: AMT | H4: CH NO | I4: MOTIF | J4: CATEGORIE | L4: DATE | M4: DESCRIPTION | N4: AMT | O4: CH NO | P4: MOTIF | Q4: CATEGORIE | S4: DATE | T4: DESCRIPTION | U4: AMT | V4: CH NO | W4: MOTIF | X4: CATEGORIE | Z4: DATE | AA4: DESCRIPTION | AB4: AMT | AC4: CH NO | AD4: MOTIF | AE4: CATEGORIE | AG4: DATE | AH4: DESCRIPTION | AI4: AMT | AJ4: CH NO | AK4: MOTIF | AL4: CATEGORIE
B5: SALES/ UD CAKES | C5: =G3 -> 552355048 | E5: {=_xlfn.CHOOSECOLS(_xlfn._xlws.FILTER(STATEMENT!A3:H5027,STATEMENT!H3:H5027="SALES/ UD CAKES"),1,2,3,6,7,8)} -> 46034 | F5: VERSEMENT SAMBA SYLVERSTRE | G5: 5500000 | H5: 0 | I5: UD CAKE SALES_50MT@110K_OLD STOCK 2025 | J5: SALES/ UD CAKES | L5: {=_xlfn.CHOOSECOLS(_xlfn._xlws.FILTER(STATEMENT!A3:H5027,STATEMENT!H3:H5027="SALES /COTTON SEED OIL"),1,2,3,6,7,8)} -> 46092 | M5: FLUDOR BENIN | N5: 23628994 | O5: 0 | P5: CHEQUE 3053255 FROM FLUDOR/ COTTON SEED OIL SALES | Q5: SALES /COTTON SEED OIL | S5: {=_xlfn.CHOOSECOLS(_xlfn._xlws.FILTER(STATEMENT!A3:H5027,STATEMENT!H3:H5027="SALES/ SOYA MEAL"),1,2,3,6,7,8)} -> 46248 | T5: MAHARASHTRA SOLVENT EXTRACTION LIMITED | U5: 65736084 | V5: 0 | W5: INV NO NAP-1087-2026_116713.76@563.22_271285360_Soyameal | X5: SALES/ SOYA MEAL | Z5: {=_xlfn.CHOOSECOLS(_xlfn._xlws.FILTER(STATEMENT!A3:H5027,STATEMENT!H3:H5027="SALES/ SOYABEAN"),1,2,3,6,7,8)} -> 46085 | AA5: PARGAN SINGAPORE | AB5: 64515397 | AC5: 0 | AD5: EXP OF SOYA BEAN_NAP/1028/2026_114629.18 USD | AE5: SALES/ SOYABEAN | AG5: {=_xlfn.CHOOSECOLS(_xlfn._xlws.FILTER(STATEMENT!A3:H5027,STATEMENT!H3:H5027="SALES/ SOYA CRUDE OIL"),1,2,3,6,7,8)} -> 46206 | AH5: SANJAY SOYA PRIVATE LIMITED_USD 142651.2@571 | AI5: 81421288 | AJ5: 0 | AK5: Soya crude oil _NAP-1080-2026_142,651.20 USD | AL5: SALES/ SOYA CRUDE OIL
B6: SALES /COTTON SEED OIL | C6: =N3 -> 638909287 | E6: 46038 | F6: VERSEMENT SAMBA SYLVERSTRE | G6: 14500000 | H6: 0 | I6: UD CAKE SALES_100MT@145K | J6: SALES/ UD CAKES | L6: 46146 | M6: SANJAY SOYA PRIVATE LIMITED | N6: 67427919 | O6: 0 | P6: Cotton seed oil Sales_NAP/1042/2026_102983.20 EUR | Q6: SALES /COTTON SEED OIL | S6: 46251 | T6: MAHARASHTRA SOLVENT EXTRACTION LIMITED | U6: 64471726 | V6: 0 | W6: INV NO NAP-1086-2026_114470@563.22_271321384_Soyameal | X6: SALES/ SOYA MEAL | Z6: 46091 | AA6: PARGAN SINGAPORE | AB6: 126635511 | AC6: 0 | AD6: EXP OF SOYA BEAN_NAP/1029/2026_112762.28 USD_NAP/1031/2026_112805.46 USD | AE6: SALES/ SOYABEAN | AG6: 46206 | AH6: SANJAY SOYA PRIVATE LIMITED_USD 137323@571 | AI6: 78378886 | AJ6: 0 | AK6: Soya crude oil _NAP-1083-2026_137,323 USD | AL6: SALES/ SOYA CRUDE OIL
B7: SALES/ SOYA MEAL | C7: =U3 -> 130207810 | E7: 46038 | F7: VERSEMENT SAMBA SYLVERSTRE | G7: 1500000 | H7: 0 | I7: UD CAKE SALES_300MT@145K_RGLMT | J7: SALES/ UD CAKES | L7: 46147 | M7: SANJAY SOYA PRIVATE LIMITED | N7: 71908460 | O7: 0 | P7: Cotton seed oil Sales_NAP/1045/2026_109813.74 EUR | Q7: SALES /COTTON SEED OIL | Z7: 46100 | AA7: PARGAN SINGAPORE | AB7: 68565602 | AC7: 0 | AD7: SOYA EXP_NAP/1037/2026_126433.14 USD | AE7: SALES/ SOYABEAN | AG7: 46248 | AH7: SANJAY SOYA PTE LTD | AI7: 14190959 | AJ7: 0 | AK7: INV NO NAP-1089-2026_25230.6@562.45_272299963_Soya crude oil | AL7: SALES/ SOYA CRUDE OIL
B8: SALES/ SOYABEAN | C8: =AB3 -> 991312747 | E8: 46043 | F8: VERSEMENT SAMBA SYLVERSTRE | G8: 14500000 | H8: 0 | I8: UD CAKE SALES_100MT@145K | J8: SALES/ UD CAKES | L8: 46161 | M8: SANJAY SOYA PRIVATE LIMITED | N8: 78387517 | O8: 0 | P8: Cotton seed oil Sales_NAP/1064/2026_1196911 EUR | Q8: SALES /COTTON SEED OIL | Z8: 46104 | AA8: PARGAN SINGAPORE | AB8: 130851241 | AC8: 0 | AD8: SOYA EXP | AE8: SALES/ SOYABEAN
B9: SALES/ SOYA CRUDE OIL | C9: =AI3 -> 173991133 | E9: 46045 | F9: VERSEMENT SAMBA SYLVERSTRE | G9: 14500000 | H9: 0 | I9: UD CAKE SALES_100MT@145K | J9: SALES/ UD CAKES | L9: 46161 | M9: SANJAY SOYA PRIVATE LIMITED | N9: 76689481 | O9: 0 | P9: Cotton seed oil Sales_NAP/1050/2026_117102.36 EUR | Q9: SALES /COTTON SEED OIL | Z9: 46108 | AA9: PARGAN SINGAPORE | AB9: 73759408 | AC9: 0 | AD9: SOYA EXP | AE9: SALES/ SOYABEAN
B10: TOTAL | C10: =SUM(C5:C9) -> 2486776025 | E10: 46051 | F10: VERSEMENT SAMBA SYLVERSTRE | G10: 21750000 | H10: 0 | I10: UD CAKE SALES_150MT@145K | J10: SALES/ UD CAKES | L10: 46168 | M10: SANJAY SOYA PRIVATE LIMITED | N10: 82831167 | O10: 0 | P10: Cotton seed oil Sales_NAP/1067/2026_126465.30 EUR | Q10: SALES /COTTON SEED OIL | Z10: 46112 | AA10: PARGAN SINGAPORE | AB10: 14166503 | AC10: 0 | AD10: SOYA EXP | AE10: SALES/ SOYABEAN
E11: 46051 | F11: VERSEMENT SAMBA SYLVERSTRE | G11: 14500000 | H11: 0 | I11: UD CAKE SALES_100MT@145K | J11: SALES/ UD CAKES | L11: 46191 | M11: SANJAY SOYA PRIVATE LIMITED | N11: 78737405 | O11: 0 | P11: Cotton seed oil_NAP/1073/2026 | Q11: SALES /COTTON SEED OIL | Z11: 46191 | AA11: PARGAN SINGAPORE | AB11: 97043275 | AC11: 0 | AD11: SOYABEAN SALES_NAP/1084/2026_170288.36 $ | AE11: SALES/ SOYABEAN
E12: 46058 | F12: VERSEMENT SAMBA SYLVERSTRE | G12: 23000000 | H12: 0 | I12: UD CAKE SALES_ | J12: SALES/ UD CAKES | L12: 46191 | M12: SANJAY SOYA PRIVATE LIMITED | N12: 78468200 | O12: 0 | P12: Cotton seed oil_NAP/1068/2026 | Q12: SALES /COTTON SEED OIL | Z12: 46191 | AA12: PARGAN SINGAPORE | AB12: 87746089 | AC12: 0 | AD12: SOYABEAN SALES_NAP/1085/2026_155891.51 $ | AE12: SALES/ SOYABEAN
E13: 46078 | F13: VERSEMENT SAMBA SYLVERSTRE | G13: 20000000 | H13: 0 | I13: UD CAKE SALES_350MT@160K | J13: SALES/ UD CAKES | L13: 46196 | M13: SANJAY SOYA PRIVATE LIMITED | N13: 80830144 | O13: 0 | P13: Cotton seed oil Sales_NAP/1066/2026_123414.76 EUR | Q13: SALES /COTTON SEED OIL | Z13: 46247 | AA13: MAHARASHTRA SOLVENT EXTRACTION LIMITED | AB13: 45616720 | AC13: 0 | AD13: INV NO NAP-1088-2026_80831.07@564.35_271172498_Soyabean | AE13: SALES/ SOYABEAN
E14: 46079 | F14: VERSEMENT SAMBA SYLVERSTRE | G14: 32000000 | H14: 0 | I14: UD CAKE SALES_350MT@160K | J14: SALES/ UD CAKES | Z14: 46258 | AA14: MAHARASHTRA SOLVENT EXTRACTION LIMITED | AB14: 90677888 | AC14: 0 | AD14: INV NO NAP-1092-2026_162054.12@559.55_271172507_Soyabean | AE14: SALES/ SOYABEAN
E15: 46091 | F15: VERSEMENT SAMBA SYLVERSTRE | G15: 4000000 | H15: 0 | I15: UD CAKE SALES_350MT@160K | J15: SALES/ UD CAKES | Z15: 46274 | AA15: PAN TRADING FZ LLC | AB15: 191735113 | AC15: 0 | AD15: INV NO NAP-1025-2026_115242.34@561_266451339//INV NO NAP-1026-2026_114695.732@561_266420310//INV NO NAP-1027-2026_111902.75@561_266446250_Soyabean | AE15: SALES/ SOYABEAN
E16: 46107 | F16: VERSEMENT MENANYI NICOLAS | G16: 32000000 | H16: 0 | I16: UD CAKE SALES_200MT@165K | J16: SALES/ UD CAKES
E17: 46122 | F17: VERSEMENT SAMBA SYLVERSTRE | G17: 16000000 | H17: 0 | I17: UD CAKE SALES_100MT@160K | J17: SALES/ UD CAKES
E18: 46125 | F18: VERSEMENT ESPECES BY ADETONAH DAMIAN DERE/ DERE IMPORT EXPORT | G18: 87000000 | H18: 0 | I18: UD CAKE SALES_DAMIAN_1500MT@155K_FACT 1012 | J18: SALES/ UD CAKES
E19: 46126 | F19: VERSEMENT SAMBA SYLVERSTRE | G19: 16000000 | H19: 0 | I19: UD CAKE SALES_100MT@160K | J19: SALES/ UD CAKES
E20: 46127 | F20: VERSEMENT ESPECES BY BACHIROU SEYDOU NASSER | G20: 51840000 | H20: 0 | I20: BANTHAL SARL SENEGAL_NAP/1014/2026_324MT@160K | J20: SALES/ UD CAKES
E21: 46127 | F21: VERSEMENT ESPECES BY PENTAGONE BUILDING SARL | G21: 32000000 | H21: 0 | I21: ALADJI LAMINE_DRISS_NAP/1008/2026_200MT@165K | J21: SALES/ UD CAKES
E22: 46133 | F22: VERSEMENT ESPECES BY AZIZ KA FAV | G22: 46080000 | H22: 0 | I22: KA AZIZ_NAP/1010/2026_UD CAKE SALES_TEL 97688750_288MT@160K | J22: SALES/ UD CAKES
E23: 46141 | F23: VERSEMENT MENANYI NICOLAS | G23: 41250000 | H23: 0 | I23: UD CAKE SALES_250MT@165K | J23: SALES/ UD CAKES
E24: 46260 | F24: PAN TRADING FZ LLC | G24: 34252276 | H24: 0 | I24: INV NO 1003/2025 _USD 61,109.75@560.50_Cotton Seed Cake | J24: SALES/ UD CAKES
E25: 46276 | F25: PAN TRADING FZ LLC | G25: 30182772 | H25: 0 | I25: INV NO NAP-1049-2026_53768@562_267328038_UD CAKE | J25: SALES/ UD CAKES

Sheet ACHAT_MP_(DEBIT)
E3: PURCHASE OF SOYA | G3: =SUBTOTAL(9,G5:G5000) -> 99082760 | L3: PURCHASE/ COTTON SEED | N3: =SUBTOTAL(9,N5:N5000) -> 60000000 | S3: PURCHASE OF SHEA | U3: =SUBTOTAL(9,U5:U5000) -> 417880000
B4: PRODUIT | C4: MONTANT DEBIT | E4: DATE | F4: DESCRIPTION | G4: AMT | H4: CH NO | I4: MOTIF | J4: CATEGORIE | L4: DATE | M4: DESCRIPTION | N4: AMT | O4: CH NO | P4: MOTIF | Q4: CATEGORIE | S4: DATE | T4: DESCRIPTION | U4: AMT | V4: CH NO | W4: MOTIF | X4: CATEGORIE
B5: PURCHASE OF SOYA | C5: =G3 -> 99082760 | E5: {=_xlfn.CHOOSECOLS(_xlfn._xlws.FILTER(STATEMENT!A3:H5027,STATEMENT!H3:H5027="PURCHASE OF SOYA"),1,2,4,6,7,8)} -> 46092 | F5: TCHANIGA SAMSON | G5: 3634400 | H5: 5447262 | I5: PURCHASE OF SOYA | J5: PURCHASE OF SOYA | L5: {=_xlfn.CHOOSECOLS(_xlfn._xlws.FILTER(STATEMENT!A3:H5027,STATEMENT!H3:H5027="PURCHASE/ COTTON SEED"),1,2,4,6,7,8)} -> 46090 | M5: SODECO | N5: 60000000 | O5: 5447256 | P5: ACHAT DE COTON SEED | Q5: PURCHASE/ COTTON SEED | S5: {=_xlfn.CHOOSECOLS(_xlfn._xlws.FILTER(STATEMENT!A3:H5027,STATEMENT!H3:H5027="PURCHASE OF SHEA"),1,2,4,6,7,8)} -> 46248 | T5: TCHANIGA SAMSON | U5: 16552800 | V5: 5822154 | W5: PURCHASE OF SHEA | X5: PURCHASE OF SHEA
B6: PURCHASE/ COTTON SEED | C6: =N3 -> 60000000 | E6: 46092 | F6: GOUDOU DOSSOU ROMAIN | G6: 1909100 | H6: 5447263 | I6: PURCHASE OF SOYA | J6: PURCHASE OF SOYA | S6: 46251 | T6: ISMAEL WASSIOU | U6: 32835000 | V6: 5822143 | W6: PURCHASE OF SHEA | X6: PURCHASE OF SHEA
B7: PURCHASE OF SHEA | C7: =U3 -> 417880000 | E7: 46163 | F7: HOUEDANOU JUSTIN | G7: 14005640 | H7: 5822109 | I7: PURCHASE OF SOYA | J7: PURCHASE OF SOYA | S7: 46252 | T7: VLAVONOU PIERRE | U7: 12949200 | V7: 5822144 | W7: PURCHASE OF SHEA | X7: PURCHASE OF SHEA
E8: 46163 | F8: CHABI BORO HALISSOU | G8: 14481500 | H8: 5822107 | I8: PURCHASE OF SOYA | J8: PURCHASE OF SOYA | S8: 46252 | T8: TCHANIGA SAMSON | U8: 25990200 | V8: 5822146 | W8: PURCHASE OF SHEA | X8: PURCHASE OF SHEA
E9: 46164 | F9: TCHANIGA SAMSON | G9: 11144000 | H9: 0 | I9: PURCHASE OF SOYA | J9: PURCHASE OF SOYA | S9: 46252 | T9: BADJOGOUN EVELINE NESTORINE / NOEL DOLEME | U9: 7000000 | V9: 5822147 | W9: PURCHASE OF SHEA | X9: PURCHASE OF SHEA
B10: TOTAL | C10: =SUM(C5:C9) -> 576962760 | E10: 46164 | F10: TCHANIGA ADEKOUNLE LEONARD | G10: 12921440 | H10: 0 | I10: PURCHASE OF SOYA | J10: PURCHASE OF SOYA | S10: 46254 | T10: TCHANIGA SAMSON | U10: 15622200 | V10: 5822156 | W10: PURCHASE OF SHEA | X10: PURCHASE OF SHEA
E11: 46164 | F11: AHEGNI HIPPOLYTE | G11: 27176800 | H11: 0 | I11: PURCHASE OF SOYA | J11: PURCHASE OF SOYA | S11: 46254 | T11: VLAVONOU PIERRE | U11: 15001800 | V11: 5822157 | W11: PURCHASE OF SHEA | X11: PURCHASE OF SHEA
E12: 46190 | F12: PURCHASE OF SOYABEAN | G12: 13809880 | H12: 5822117 | I12: PURCHASE OF SOYA | J12: PURCHASE OF SOYA | S12: 46254 | T12: NOEL DOLEME | U12: 8675000 | V12: 5822158 | W12: PURCHASE OF SHEA | X12: PURCHASE OF SHEA
S13: 46255 | T13: TCHANIGA SAMSON | U13: 8000000 | V13: 5822159 | W13: PURCHASE OF SHEA | X13: PURCHASE OF SHEA
S14: 46258 | T14: TCHANIGA SAMSON | U14: 15036000 | V14: 5822162 | W14: PURCHASE OF SHEA | X14: PURCHASE OF SHEA
S15: 46258 | T15: YENAFO MOISE | U15: 10546800 | V15: 5822160 | W15: PURCHASE OF SHEA | X15: PURCHASE OF SHEA
S16: 46258 | T16: PIERRE VLAVONOU/DAOUDA MACHOUDI | U16: 13206600 | V16: 5822163 | W16: PURCHASE OF SHEA | X16: PURCHASE OF SHEA
S17: 46259 | T17: DOSSOU GOUDOU ROMAIN | U17: 11343400 | V17: 5822164 | W17: PURCHASE OF SHEA | X17: PURCHASE OF SHEA
S18: 46261 | T18: ALLASSANE MARWANE | U18: 15199800 | V18: 5822170 | W18: PURCHASE OF SHEA | X18: PURCHASE OF SHEA
S19: 46261 | T19: GBAGBE MATHIAS | U19: 9000000 | V19: 5822172 | W19: PURCHASE OF SHEA | X19: PURCHASE OF SHEA
S20: 46261 | T20: MEHSAN DANIEL JOEL | U20: 9000000 | V20: 5822174 | W20: PURCHASE OF SHEA | X20: PURCHASE OF SHEA
S21: 46267 | T21: KOBOLOU HERVE | U21: 10000000 | V21: 5822180 | W21: PURCHASE OF SHEA | X21: PURCHASE OF SHEA
S22: 46268 | T22: BADAROU SAID | U22: 5000000 | V22: 5822183 | W22: PURCHASE OF SHEA | X22: PURCHASE OF SHEA
S23: 46270 | T23: DOSSA DOGNON MATHURIN | U23: 4670100 | V23: 5822185 | W23: PURCHASE OF SHEA | X23: PURCHASE OF SHEA
S24: 46270 | T24: KOBOLOU HERVE | U24: 6202000 | V24: 5822186 | W24: PURCHASE OF SHEA | X24: PURCHASE OF SHEA
... S36: 46274 | T36: NOEL DOLEME | U36: 2972800 | V36: 5822195 | W36: PURCHASE OF SHEA | X36: PURCHASE OF SHEA

Sheet DEPENCES_EXP ACC_(DEBIT)
E3: TRANSITER | G3: =SUBTOTAL(9,G5:G5000) -> 158174827 | L3: BFU | N3: =SUBTOTAL(9,N5:N5000) -> 349147438 | S3: EXP/ FRET PAYMENT | U3: =SUBTOTAL(9,U5:U5000) -> 1013456
B4: PRODUIT | C4: MONTANT DEBIT | E4: DATE | F4: DESCRIPTION | G4: AMT | H4: CH NO | I4: MOTIF | J4: CATEGORIE | L4: DATE | M4: DESCRIPTION | N4: AMT | O4: CH NO | P4: MOTIF | Q4: CATEGORIE | S4: DATE | T4: DESCRIPTION | U4: AMT | V4: CH NO | W4: MOTIF | X4: CATEGORIE
B5: TRANSITER | C5: =G3 -> 158174827 | E5: {=_xlfn.CHOOSECOLS(_xlfn._xlws.FILTER(STATEMENT!A3:H5027,STATEMENT!H3:H5027="TRANSITER"),1,2,4,6,7,8)} -> 46027 | F5: ORDI TRADING (RAJIBER) EXP ACC | G5: 3400000 | H5: 5447234 | I5: 0 | J5: TRANSITER | L5: {=_xlfn.CHOOSECOLS(_xlfn._xlws.FILTER(STATEMENT!A3:H5027,STATEMENT!H3:H5027="BFU"),1,2,4,6,7,8)} -> 46029 | M5: SEGUB GUCE | N5: 1080382 | O5: 0 | P5: USN-26003902_bl MEDUCT180949_ SHEA DOC | Q5: BFU | S5: {=_xlfn.CHOOSECOLS(_xlfn._xlws.FILTER(STATEMENT!A3:H5027,STATEMENT!H3:H5027="EXP/ FRET PAYMENT"),1,2,4,6,7,8)} -> 46107 | T5: M/SC BENIN | U5: 1013456 | V5: 5758923 | W5: PAYEMENT FRET | X5: EXP/ FRET PAYMENT
B6: BFU | C6: =N3 -> 349147438 | E6: 46027 | F6: ORDI TRADING (RAJIBER) EXP ACC | G6: 1258530 | H6: 5447233 | I6: 0 | J6: TRANSITER | L6: 46038 | M6: SEGUB GUCE | N6: 3978467 | O6: 0 | P6: USN-26008665_264186756_SHEA BUTTER | Q6: BFU
B7: EXP/ FRET PAYMENT | C7: =U3 -> 1013456 | E7: 46035 | F7: PROSPERITY AND GLORY OF GOD | G7: 2646300 | H7: 5447236 | I7: ALFRED TRANSITER EXP ACC | J7: TRANSITER | L7: 46038 | M7: SEGUB GUCE | N7: 2004059 | O7: 0 | P7: USN-26008661_264169298_SHEA BUTTER | Q7: BFU
B8: TOTAL | C8: =SUM(C5:C7) -> 508335721 | E8: 46093 | F8: HAMA INTER | G8: 20000000 | H8: 5447258 | I8: EXP ACC | J8: TRANSITER | L8: 46038 | M8: SEGUB GUCE | N8: 65625 | O8: 0 | P8: RENOUVELLEMENT BFU_BL 265674057 | Q8: BFU
E9: 46093 | F9: ORDI TRADING (RAJIBER) EXP ACC | G9: 15000000 | H9: 5447257 | I9: EXP ACC | J9: TRANSITER | L9: 46041 | M9: SEGUB GUCE | N9: 4372054 | O9: 0 | P9: USN-26010887_264186615_SHEA BUTTER | Q9: BFU
E10: 46099 | F10: ORDI TRADING (RAJIBER) EXP ACC | G10: 3000000 | H10: 5447265 | I10: EXP ACC | J10: TRANSITER | L10: 46042 | M10: SEGUB GUCE | N10: 1037216 | O10: 0 | P10: USN-26013884_MEDUCT181871_SHEA DOC | Q10: BFU
E11: 46100 | F11: ORDI TRADING / MMAF COMMODITIES (RAJIBER) | G11: 7000000 | H11: 5447266 | I11: EXP ACC | J11: TRANSITER | L11: 46045 | M11: SEGUB GUCE | N11: 4706191 | O11: 0 | P11: USN-26015849_265085383_SHEA BUTTER | Q11: BFU
E12: 46112 | F12: ORDI TRADING (RAJIBER) EXP ACC | G12: 15000000 | H12: 5447274 | I12: EXP ACC | J12: TRANSITER | L12: 46050 | M12: SEGUB GUCE | N12: 2001241 | O12: 0 | P12: USN-26019619_265584223_SHEA BUTTER | Q12: BFU
E13: 46113 | F13: PROSPERITY AND GLORY OF GOD | G13: 7000000 | H13: 5447277 | I13: ALFRED TRANSITER EXP ACC | J13: TRANSITER | L13: 46050 | M13: SEGUB GUCE | N13: 1035448 | O13: 0 | P13: USN-26019610_MEDUCT182457_SHEA DOC | Q13: BFU
E14: 46147 | F14: TRANS SOHA | G14: 6000000 | H14: 5822102 | I14: EXPORT ACC | J14: TRANSITER | L14: 46051 | M14: SEGUB GUCE | N14: 2389191 | O14: 0 | P14: USN-26019707_265584104_SHEA BUTTER | Q14: BFU
E15: 46170 | F15: TRANS SOHA | G15: 7000000 | H15: 5822110 | I15: EXPORT ACC | J15: TRANSITER | L15: 46051 | M15: SEGUB GUCE | N15: 263900 | O15: 0 | P15: RENOUVELLEMENT BFU_USN-26020071 | Q15: BFU
E16: 46191 | F16: TRANS SOHA | G16: 10000000 | H16: 5822118 | I16: FRAIS DE PRESTATION_TRANSITAIRE TRANS SOHA | J16: TRANSITER | L16: 46051 | M16: SEGUB GUCE | N16: 131250 | O16: 0 | P16: RENOUVELLEMENT BFU_USN-26008665 | Q16: BFU
E17: 46204 | F17: RAJIBER MMAF | G17: 7000000 | H17: 5822122 | I17: FRAIS DE PRESTATION POUR LE TRANSITAIRE RAJIBER - MMAF | J17: TRANSITER | L17: 46051 | M17: SEGUB GUCE | N17: 65625 | O17: 0 | P17: RENOUVELLEMENT BFU_USN-26008661 | Q17: BFU
E18: 46207 | F18: HAMA INTER | G18: 9000000 | H18: 0 | I18: FRAIS DE PRESTATION POUR LE TRANSITAIRE HAMA INTER | J18: TRANSITER | L18: 46055 | M18: SEGUB GUCE | N18: 762190 | O18: 0 | P18: USN-26015476 _HLCURTM251200745 | Q18: BFU
E19: 46213 | F19: CEVA LOGISTICS | G19: 2869997 | H19: 5822129 | I19: Frais de prestation sur importation | J19: TRANSITER | L19: 46056 | M19: SEGUB GUCE | N19: 1142162 | O19: 0 | P19: USN-26021639_MEDUCT182978_SHEA DOC | Q19: BFU
E20: 46252 | F20: HAMA INTER | G20: 8000000 | H20: 5822145 | I20: FRAIS DE PRESTATION POUR LE TRANSITAIRE HAMA INTER | J20: TRANSITER | L20: 46062 | M20: SEGUB GUCE | N20: 2386092 | O20: 0 | P20: USN-26025244_265903956_SHEA BUTTER | Q20: BFU
... E24: 46274 | F24: TRANS SOHA | G24: 10000000 | H24: 5862904 | I24: FRAIS DE PRESTATION_TRANSITAIRE TRANS SOHA | J24: TRANSITER | L24: 46064 | M24: SEGUB GUCE | N24: 2008848 | O24: 0 | P24: USN-26029896_MEDUCT183786_Shea Butter | Q24: BFU
L25: 46064 | M25: SEGUB GUCE | N25: 1176855 | O25: 0 | P25: USN-26029887_265928839_CRUDE OIL | Q25: BFU
L26: 46072 | M26: SEGUB GUCE | N26: 65625 | O26: 0 | P26: USN-26025244_265903956_Shea Butter | Q26: BFU
L27: 46073 | M27: SEGUB GUCE | N27: 301875 | O27: 0 | P27: USN-26029936_265903694_Shea Butter | Q27: BFU
L28: 46073 | M28: SEGUB GUCE | N28: 170625 | O28: 0 | P28: USN-26025394_265904812_Shea Butter | Q28: BFU
L29: 46073 | M29: SEGUB GUCE | N29: 52500 | O29: 0 | P29: USN-26029942_MEDUCT183753_Shea Doc | Q29: BFU
L30: 46076 | M30: SEGUB GUCE | N30: 1218012 | O30: 0 | P30: USN-26037152_266489622_Shea Butter | Q30: BFU
L31: 46080 | M31: SEGUB GUCE | N31: 8442437 | O31: 0 | P31: USN-26038150_266451339_SOYA BEANS | Q31: BFU
L32: 46080 | M32: SEGUB GUCE | N32: 8406883 | O32: 0 | P32: USN-26040633_266420310_SOYA BEANS | Q32: BFU
L33: 46080 | M33: SEGUB GUCE | N33: 8225767 | O33: 0 | P33: USN-26040635_266446250_SOYA BEANS | Q33: BFU
L34: 46084 | M34: SEGUB GUCE | N34: 8402899 | O34: 0 | P34: USN-26042828_266451157_SOYA BEANS | Q34: BFU
L35: 46084 | M35: SEGUB GUCE | N35: 8284376 | O35: 0 | P35: USN-26042575_MEDUCT186003_SOYA BEANS | Q35: BFU
L36: 46084 | M36: SEGUB GUCE | N36: 8281727 | O36: 0 | P36: USN-26042789_OK26089MB_ | Q36: BFU
... L48: 46099 | M48: SEGUB GUCE | N48: 8449336 | O48: 0 | P48: USN-26053327_266896858_SOYA BEANS | Q48: BFU
L49: 46099 | M49: SEGUB GUCE | N49: 1363447 | O49: 0 | P49: 0 | Q49: BFU
L50: 46100 | M50: SEGUB GUCE | N50: 1252096 | O50: 0 | P50: USN-26053644_267214087_CRUDE OIL | Q50: BFU
L51: 46108 | M51: SEGUB GUCE | N51: 3542736 | O51: 0 | P51: USN-26060478_267482495_Shea Butter | Q51: BFU
L52: 46111 | M52: SEGUB GUCE | N52: 3719533 | O52: 0 | P52: USN-26061254_267482433_Shea Butter | Q52: BFU
L53: 46111 | M53: SEGUB GUCE | N53: 1620987 | O53: 0 | P53: USN-26060119_267482578_Shea Butter | Q53: BFU
L54: 46111 | M54: SEGUB GUCE | N54: 1340716 | O54: 0 | P54: USN-26061741_267523523_CRUDE OIL | Q54: BFU
L55: 46111 | M55: SEGUB GUCE | N55: 262500 | O55: 0 | P55: USN-26021639_MEDUCT182978_Shea Doc | Q55: BFU
L56: 46112 | M56: SEGUB GUCE | N56: 1295563 | O56: 0 | P56: USN-26060100_267328038_UD CAKE | Q56: BFU
...

Sheet AUTRES_DEPENSES_(DEBIT)
E3: DGI | G3: =SUBTOTAL(9,G5:G5000) -> 31499825 | L3: PURCHASE/ PP BAGS | N3: =SUBTOTAL(9,N5:N5000) -> 5340000 | S3: PURCHASE/ FLEXITANK | U3: =SUBTOTAL(9,U5:U5000) -> 43280268 | Z3: PURCHASE/ HEXANE | AB3: =SUBTOTAL(9,AB5:AB5000) -> 28233940 | AG3: PURCHASE/ OTHERS | AI3: =SUBTOTAL(9,AI5:AI5000) -> 6166983 | AN3: LABOUR WORK | AP3: =SUBTOTAL(9,AP5:AP5000) -> 26106222 | AU3: TRANSPORT/COTTON SEED | AW3: =SUBTOTAL(9,AW5:AW5000) -> 41420260 | BB3: HOUSE RENT | BD3: =SUBTOTAL(9,BD5:BD5000) -> 9606800 | BI3: SERVICE | BK3: =SUBTOTAL(9,BK5:BK5000) -> 121046321 | BP3: CONSTRUCTION | BR3: =SUBTOTAL(9,BR5:BR5000) -> 11500000
B4: PRODUIT | C4: MONTANT DEBIT | E4: DATE | F4: DESCRIPTION | G4: AMT | H4: CH NO | I4: MOTIF | J4: CATEGRIE | L4: DATE | M4: DESCRIPTION | N4: AMT | O4: CH NO | P4: MOTIF | Q4: CATEGRIE | S4: DATE | T4: DESCRIPTION | U4: AMT | V4: CH NO | W4: MOTIF | X4: CATEGRIE | Z4: DATE | AA4: DESCRIPTION | AB4: AMT | AC4: CH NO | AD4: MOTIF | AE4: CATEGRIE | AG4: DATE | AH4: DESCRIPTION | AI4: AMT | AJ4: CH NO | AK4: MOTIF | AL4: CATEGRIE | AN4: DATE | AO4: DESCRIPTION | AP4: AMT | AQ4: CH NO | AR4: MOTIF | AS4: CATEGRIE | AU4: DATE | AV4: DESCRIPTION | AW4: AMT | AX4: CH NO | AY4: MOTIF | AZ4: CATEGRIE | BB4: DATE | BC4: DESCRIPTION | BD4: AMT | BE4: CH NO | BF4: MOTIF | BG4: CATEGRIE | BI4: DATE | BJ4: DESCRIPTION | BK4: AMT | BL4: CH NO | BM4: MOTIF | BN4: CATEGRIE | BP4: DATE | BQ4: DESCRIPTION | BR4: AMT | BS4: CH NO | BT4: MOTIF | BU4: CATEGRIE
B5: DGI | C5: =G3 -> 31499825 | E5: {=_xlfn.CHOOSECOLS(_xlfn._xlws.FILTER(STATEMENT!A3:H5027,STATEMENT!H3:H5027="DGI"),1,2,4,6,7,8)} -> 46034 | F5: DGI | G5: 10300265 | H5: 0 | I5: DECLARATION IMPOT DEC 2025 | J5: DGI | L5: {=_xlfn.CHOOSECOLS(_xlfn._xlws.FILTER(STATEMENT!A3:H5027,STATEMENT!H3:H5027="PURCHASE/ PP BAGS"),1,2,4,6,7,8)} -> 46093 | M5: AFRICA ROUTE | N5: 5340000 | O5: 5447264 | P5: ACHAT PP BAGS AFFRICA ROUTE / FACTURE EM1060296-108/ MONTANT 1.940 _ FACTURE EM1060296-105/MONTANT 3.400K | Q5: PURCHASE/ PP BAGS | S5: {=_xlfn.CHOOSECOLS(_xlfn._xlws.FILTER(STATEMENT!A3:H5027,STATEMENT!H3:H5027="PURCHASE/ FLEXITANK"),1,2,4,6,7,8)} -> 46059 | T5: REGLEMENT REMISE DOCUMENTAIRE | U5: 43280268 | V5: 0 | W5: PHILTON POLYTHENE CONVERTERS (IMPORTATION DE FLEXI TANK)_ OOLU2316179190 | X5: PURCHASE/ FLEXITANK | Z5: {=_xlfn.CHOOSECOLS(_xlfn._xlws.FILTER(STATEMENT!A3:H5027,STATEMENT!H3:H5027="PURCHASE/ HEXANE"),1,2,4,6,7,8)} -> 46048 | AA5: REGLEMENT REMISE DOCUMENTAIRE | AB5: 12910170 | AC5: 0 | AD5: KH CHEMICAL (IMPORT OF HEXANE)_HLCURTM251200745 | AE5: PURCHASE/ HEXANE | AG5: {=_xlfn.CHOOSECOLS(_xlfn._xlws.FILTER(STATEMENT!A3:H5027,STATEMENT!H3:H5027="PURCHASE/ OTHERS"),1,2,4,6,7,8)} -> 46041 | AH5: ETS JKM EDITION | AI5: 154715 | AJ5: 5447240 | AK5: ACHAT DE FOURNITURE_No facture EM1072646-610 | AL5: PURCHASE/ OTHERS | AN5: {=_xlfn.CHOOSECOLS(_xlfn._xlws.FILTER(STATEMENT!A3:H5027,STATEMENT!H3:H5027="LABOUR WORK"),1,2,4,6,7,8)} -> 46041 | AO5: IDRISSOU APHISSOU | AP5: 774522 | AQ5: 5447242 | AR5: OLABI LABOUR (COTTON-UD CAKE-SHEA NUT) | AS5: LABOUR WORK | AU5: {=_xlfn.CHOOSECOLS(_xlfn._xlws.FILTER(STATEMENT!A3:H5027,STATEMENT!H3:H5027="TRANSPORT/COTTON SEED"),1,2,4,6,7,8)} -> 46045 | AV5: CERCLE DE DIEU | AW5: 3000000 | AX5: 5447245 | AY5: COTTON SEED TRANSPORT/ELIE | AZ5: TRANSPORT/COTTON SEED | BB5: {=_xlfn.CHOOSECOLS(_xlfn._xlws.FILTER(STATEMENT!A3:H5027,STATEMENT!H3:H5027="HOUSE RENT"),1,2,4,6,7,8)} -> 46034 | BC5: ABOKI M. DIDER | BD5: 1200000 | BE5: 5447238 | BF5: HOUSE RENT OF GLO | BG5: HOUSE RENT | BI5: {=_xlfn.CHOOSECOLS(_xlfn._xlws.FILTER(STATEMENT!A3:H5027,STATEMENT!H3:H5027="SERVICE"),1,2,4,6,7,8)} -> 46029 | BJ5: ABDULSALAM OLAKOUNLE ABDULJELIL | BK5: 2000000 | BL5: 5447235 | BM5: ODJE NIGERIA CONTRACTOR ( ALL TANK FABRICATION) | BN5: SERVICE | BP5: {=_xlfn.CHOOSECOLS(_xlfn._xlws.FILTER(STATEMENT!A3:H5027,STATEMENT!H3:H5027="CONSTRUCTION"),1,2,4,6,7,8)} -> 46246 | BQ5: VOYELO FINANGNON | BR5: 11000000 | BS5: 5822140 | BT5: TANK FORM - SOAP PIT AREA - PARKING | BU5: CONSTRUCTION
B6: PURCHASE/ PP BAGS | C6: =N3 -> 5340000 | E6: 46034 | F6: DGI | G6: 575278 | H6: 0 | I6: 0 | J6: DGI | Z6: 46097 | AA6: ETS OCAMISS | AB6: 327100 | AC6: 5447261 | AD6: CHEMICAL PURCHAS | AE6: PURCHASE/ HEXANE | AG6: 46044 | AH6: NOCIBE | AI6: 2471134 | AJ6: 5662541 | AK6: ACHAT DE CIMENT / COMPTE ARMEL/ PROJET 11 ETP PLANT | AL6: PURCHASE/ OTHERS | AN6: 46045 | AO6: ETS DOS ESPOIR ET FILS | AP6: 2000000 | AQ6: 5447243 | AR6: LABOUR WORK | AS6: LABOUR WORK | AU6: 46050 | AV6: EDS TRADE AND MORE (GABIN LCB) | AW6: 5000000 | AX6: 5447247 | AY6: COTTON SEED TRANSPORT/GABIN | AZ6: TRANSPORT/COTTON SEED | BB6: 46036 | BC6: VASWAMI MANOJ LAKHI (STE ASHASONU) | BD6: 2640000 | BE6: 5447237 | BF6: LOYER MAGASIN SEKOU | BG6: HOUSE RENT | BI6: 46041 | BJ6: DOSSA SEMADO EUSTACHE RENE | BK6: 4255000 | BL6: 5447241 | BM6: TRAVAUX MISE EN TERRE_ 37 PRISES_UNITE 115K. | BN6: SERVICE | BP6: 46261 | BQ6: AHOUANSOTODE BAUDELAIRE AIME | BR6: 500000 | BS6: 5822171 | BT6: ROOFING BOILER | BU6: CONSTRUCTION
B7: PURCHASE/ FLEXITANK | C7: =U3 -> 43280268 | E7: 46065 | F7: DGI | G7: 575155 | H7: 0 | I7: 0 | J7: DGI | Z7: 46120 | AA7: SUPER SONIC | AB7: 428400 | AC7: 5447283 | AD7: DRUM HYDRAULIC PURCHASE | AE7: PURCHASE/ HEXANE | AG7: 46056 | AH7: STE UNITED TRADEX SARL | AI7: 1070000 | AJ7: 5447248 | AK7: ACHAT DE MOTO | AL7: PURCHASE/ OTHERS | AN7: 46049 | AO7: ETS DOS ESPOIR ET FILS | AP7: 1000000 | AQ7: 5447246 | AR7: LABOUR WORK | AS7: LABOUR WORK | AU7: 46052 | AV7: CERCLE DE DIEU | AW7: 9000000 | AX7: 5447249 | AY7: COTTON SEED TRANSPORT/ELIE | AZ7: TRANSPORT/COTTON SEED | BB7: 46038 | BC7: HOUESSOU GBETOHO EZECKIEL | BD7: 660000 | BE7: 5447239 | BF7: LOYER MAISON M. RAJ KUMAR | BG7: HOUSE RENT | BI7: 46056 | BJ7: ACE GLOBAL | BK7: 2134000 | BL7: 5447250 | BM7: Paiement de facture Novembre 2025 (Ref ) et Decembre 2024 (Ref ) | BN7: SERVICE
B8: PURCHASE/ HEXANE | C8: =AB3 -> 28233940 | E8: 46065 | F8: DGI | G8: 36419 | H8: 0 | I8: 0 | J8: DGI | Z8: 46125 | AA8: REGLEMENT REMISE DOCUMENTAIRE | AB8: 12910170 | AC8: 0 | AD8: KH CHEMICAL (IMPORT OF HEXANE)_263903490 | AE8: PURCHASE/ HEXANE | AG8: 46210 | AH8: NOCIBE | AI8: 2471134 | AJ8: 5822128 | AK8: ACHAT DE CIMENT / COMPTE ARMEL/ PROJET 11 ETP PLANT | AL8: PURCHASE/ OTHERS | AN8: 46055 | AO8: IDRISSOU APHISSOU | AP8: 3000000 | AQ8: 5447252 | AR8: OLABI LABOUR SOYA ACC | AS8: LABOUR WORK | AU8: 46093 | AV8: CERCLE DE DIEU | AW8: 7500000 | AX8: 5447260 | AY8: COTTON SEED TRANSPORT/ELIE | AZ8: TRANSPORT/COTTON SEED | BB8: 46062 | BC8: AJEYA BABU NARALASETTI | BD8: 250000 | BE8: 5447254 | BF8: LOCAL ALLOWNESS FEVRIER | BG8: HOUSE RENT | BI8: 46126 | BJ8: HELIOS SECURITY SERVICES SARL | BK8: 349200 | BL8: 5447292 | BM8: SECURITY GDIZ | BN8: SERVICE
B9: PURCHASE/ OTHERS | C9: =AI3 -> 6166983 | E9: 46091 | F9: DGI | G9: 13776224 | H9: 0 | I9: 0 | J9: DGI | Z9: 46212 | AA9: ETS OCAMISS | AB9: 465600 | AC9: 5822131 | AD9: ACHAT DE PRODUIT CHIMIQUE | AE9: PURCHASE/ HEXANE | AN9: 46055 | AO9: IDRISSOU APHISSOU | AP9: 2630430 | AQ9: 5447251 | AR9: OLABI LABOUR COTTON- UD CAKE- SHEA | AS9: LABOUR WORK | AU9: 46112 | AV9: CERCLE DE DIEU | AW9: 10000000 | AX9: 5447281 | AY9: COTTON SEED TRANSPORT/ AVANCE TRANSPORT NIKKI | AZ9: TRANSPORT/COTTON SEED | BB9: 46120 | BC9: KPATINDE AKODEA EMMANUEL | BD9: 1260000 | BE9: 5447279 | BF9: HOUSE RENT OF AJAY BABO MACH TO AUGUST | BG9: HOUSE RENT | BI9: 46203 | BJ9: MANGLAM TOURS ET TRAVELS | BK9: 9012200 | BL9: 5822121 | BM9: FORMALITES DE VOYAGE | BN9: SERVICE
B10: LABOUR WORK | C10: =AP3 -> 26106222 | E10: 46091 | F10: DGI | G10: 496433 | H10: 0 | I10: 0 | J10: DGI | Z10: 46254 | AA10: ETS OCAMISS | AB10: 1192500 | AC10: 5822155 | AD10: ACHAT DE PRODUIT CHIMIQUE | AE10: PURCHASE/ HEXANE | AN10: 46057 | AO10: ETS DOS ESPOIR ET FILS | AP10: 594760 | AQ10: 5447253 | AR10: LABOUR WORK | AS10: LABOUR WORK | AU10: 46112 | AV10: CERCLE DE DIEU | AW10: 4496460 | AX10: 5447282 | AY10: COTTON SEED TRANSPORT / SOLD ANCIEN COMPTE | AZ10: TRANSPORT/COTTON SEED | BB10: 46125 | BC10: ABOKI M. DIDER | BD10: 1200000 | BE10: 5447289 | BF10: RENT OF GLO HOUSE MARCH TO SEPT | BG10: HOUSE RENT | BI10: 46212 | BJ10: ETS KOKO SUPER | BK10: 2381000 | BL10: 5822133 | BM10: INSTALLATION PARA SOL ET TONNERE | BN10: SERVICE
B11: TRANSPORT/COTTON SEED | C11: =AW3 -> 41420260 | E11: 46091 | F11: DGI | G11: 57600 | H11: 0 | I11: 0 | J11: DGI | AN11: 46062 | AO11: IDRISSOU APHISSOU | AP11: 2960667 | AQ11: 5447255 | AR11: OLABI LABOUR COTTON- UD CAKE- SHEA | AS11: LABOUR WORK | AU11: 46115 | AV11: BON BERGER | AW11: 2384300 | AX11: 5447278 | AY11: COTTON SEED TRANSPORT | AZ11: TRANSPORT/COTTON SEED | BB11: 46139 | BC11: AJEYA BABU NARALASETTI | BD11: 250000 | BE11: 5447300 | BF11: HOUSE RENT OF AJEYA BABU APRIL | BG11: HOUSE RENT | BI11: 46213 | BJ11: HELIOS SECURITY SERVICES SARL | BK11: 349200 | BL11: 5822134 | BM11: SECURITY GDIZ | BN11: SERVICE
B12: HOUSE RENT | C12: =BD3 -> 9606800 | E12: 46125 | F12: DGI | G12: 1098946 | H12: 0 | I12: 0 | J12: DGI | AN12: 46112 | AO12: ETS OLAITAN COMMUNICATION/ OLABI LABOUR | AP12: 2000000 | AQ12: 5447272 | AR12: OLABI LABOUR SOYA ACC | AS12: LABOUR WORK | AU12: 46132 | AV12: EDS TRADE AND MORE (GABIN LCB) | AW12: 39500 | AX12: 5447288 | AY12: COTTON SEED TRANSPORT/GABIN | AZ12: TRANSPORT/COTTON SEED | BB12: 46216 | BC12: ABOKY MIDOKPE DIDIER | BD12: 1200000 | BE12: 5822136 | BF12: LOYER MAISON GLO | BG12: HOUSE RENT | BI12: 46212 | BJ12: ITM BENIN | BK12: 4383739 | BL12: 5822132 | BM12: DOC/PREPARATORY/CHAUDIERE/ENTRETIEN/RAFINERIE/ FRAIS DE GESTION PERSONNEL | BN12: SERVICE
B13: SERVICE | C13: =BK3 -> 121046321 | E13: 46154 | F13: DGI | G13: 504915 | H13: 0 | I13: 0 | J13: DGI | AN13: 46112 | AO13: ETS OLAITAN COMMUNICATION/ OLABI LABOUR | AP13: 788678 | AQ13: 5447271 | AR13: OLABI LABOUR COTTON- UD CAKE- SHEA | AS13: LABOUR WORK | BB13: 46267 | BC13: LOKOSSOU URBAIN | BD13: 630000 | BE13: 5822182 | BF13: HOUSE RENT SEPT-OCT-NOV 2026 : AJAY BABU | BG13: HOUSE RENT | BI13: 46216 | BJ13: SIAB SA | BK13: 2995539 | BL13: 5822130 | BM13: ACHAT DE FER A BETON 6/8/14 PC ARMEL_PROJECT 12 : TANK FORM - SOAP PIT AREA - PARKING | BN13: SERVICE
B14: CONSTRUCTION | C14: =BR3 -> 11500000 | E14: 46154 | F14: DGI | G14: 1118946 | H14: 0 | I14: 0 | J14: DGI | AN14: 46112 | AO14: ETS DOS ESPOIR ET FILS | AP14: 385371 | AQ14: 5447275 | AR14: LABOUR WORK /FACTURE EM01335995-320 | AS14: LABOUR WORK | BB14: 46274 | BC14: DEGLA SOTONGNON ARMAND | BD14: 316800 | BE14: 5822192 | BF14: HOUSE RENT : GLO | BG14: HOUSE RENT | BI14: 46217 | BJ14: MB TECHNOLOGIES | BK14: 700000 | BL14: 5822137 | BM14: PRODUCTION DES NOTES DE CALCULS DES SCHEMAS ELECTRIQUES / PRESTATION POUR LA CERTIFICATION/REDEVANCE A REVERSER A CONTRELEC | BN14: SERVICE
B15: TOTAL | C15: =SUM(C5:C14) -> 324200619 | E15: 46212 | F15: DGI | G15: 60000 | H15: 0 | I15: 0 | J15: DGI | AN15: 46120 | AO15: ETS WYM DJIBRIL ALBARKA | AP15: 302931 | AQ15: 5447284 | AR15: UD CAKE LABOUR | AS15: LABOUR WORK | BI15: 46246 | BJ15: HELIOS SECURITY SERVICES SARL | BK15: 338400 | BL15: 5822138 | BM15: MISE A DISPOSITIOM D'AGENT DE SECURITE POUR LE MOIS DE JUILLET | BN15: SERVICE
E16: 46245 | F16: DGI | G16: 1442854 | H16: 0 | I16: 0 | J16: DGI | AN16: 46128 | AO16: IDRISSOU APHISSOU | AP16: 501917 | AQ16: 5447294 | AR16: OLABI LABOUR WORK COTTON SEED_A VERIFIER LA COPIE CHQ | AS16: LABOUR WORK | BI16: 46252 | BJ16: AVHEC BENI | BK16: 436500 | BL16: 5822152 | BM16: SIGN BOARD | BN16: SERVICE
E17: 46276 | F17: DGI | G17: 252204 | H17: 0 | I17: 0 | J17: DGI | AN17: 46128 | AO17: IDRISSOU APHISSOU | AP17: 1000000 | AQ17: 5447295 | AR17: OLABI LABOUR SOYA ACC | AS17: LABOUR WORK | BI17: 46267 | BJ17: ADEDJOUMOU ZACHARIE | BK17: 1595000 | BL17: 5822181 | BM17: OIL MILL MATERIAL | BN17: SERVICE
E18: 46276 | F18: DGI | G18: 1204586 | H18: 0 | I18: 0 | J18: DGI | AN18: 46129 | AO18: ETS DOS ESPOIR ET FILS | AP18: 396158 | AQ18: 5447298 | AR18: LABOUR WORK _ EM01335995-324 | AS18: LABOUR WORK | BI18: 46267 | BJ18: GEDC | BK18: 35760708 | BL18: 5822175 | BM18: FRAIS DE CONSOMMATION ELECTRICITE FEV, MAR & AVR 2026 | BN18: SERVICE
AN19: 46164 | AO19: ETS OLAITAN COMMUNICATION/ OLABI LABOUR | AP19: 1875495 | AQ19: 5822106 | AR19: OLABI LABOUR WORK COTTON SEED | AS19: LABOUR WORK | BI19: 46267 | BJ19: SIPI BENIN SA | BK19: 4550160 | BL19: 5822176 | BM19: FRAIS DE CONSOMMATION EAU FEV, MAR, AVR 2026 | BN19: SERVICE
AN20: 46170 | AO20: UD CAKE LABOUR WORK | AP20: 226972 | AQ20: 5822101 | AR20: LABOUR WORK | AS20: LABOUR WORK | BI20: 46267 | BJ20: SIPI BENIN SA | BK20: 8460000 | BL20: 5822177 | BM20: PESAGE CAMION NOV, FEV, MAR, AVR 2026 | BN20: SERVICE
AN21: 46253 | AO21: OLAITAN COMMUNICATION | AP21: 1500000 | AQ21: 5822153 | AR21: LABOUR WORK ACC SHEA | AS21: LABOUR WORK | BI21: 46269 | BJ21: CEFOSI | BK21: 2421000 | BL21: 5822184 | BM21: RECHARGE,FOURNITURE, VERIFICATION ET ENTRETIEN D'EXTINCTEURS | BN21: SERVICE
AN22: 46259 | AO22: OLAITAN COMMUNICATION | AP22: 769336 | AQ22: 5822165 | AR22: LABOUR WORK ACC SHEA | AS22: LABOUR WORK | BI22: 46274 | BJ22: HELIOS SECURITY SERVICES SARL | BK22: 349200 | BL22: 5822194 | BM22: MISE A DISPOSITIOM D'AGENT DE SECURITE POUR LE MOIS DE AOUT | BN22: SERVICE
AN23: 46267 | AO23: OLAITAN COMMUNICATION | AP23: 2091198 | AQ23: 5822179 | AR23: LABOUR WORK SHEA ACC | AS23: LABOUR WORK | BI23: 46275 | BJ23: SALARY | BK23: 7000000 | BL23: 5862905 | BM23: SALARIES AND LOCAL ALLOWANCE OF INDIAN PEOPLE | BN23: SERVICE
AN24: 46274 | AO24: OLAITAN COMMUNICATION | AP24: 1307787 | AQ24: 5822191 | AR24: LABOUR WORK SHEA ACC | AS24: LABOUR WORK | BI24: 46276 | BJ24: GEDC | BK24: 26410425 | BL24: 5862906 | BM24: FRAIS DE CONSOMMATION ELECTRICITE MAI, JUIN & JUL 2026 | BN24: SERVICE
BI25: 46276 | BJ25: SIPI BENIN SA | BK25: 1535050 | BL25: 5862907 | BM25: FRAIS DE CONSOMMATION EAU MAI, JUN, JUL 2026 | BN25: SERVICE
BI26: 46276 | BJ26: SIPI BENIN SA | BK26: 3630000 | BL26: 5862908 | BM26: PESAGE CAMION NOV, MAI, JUN, JUL 2026 | BN26: SERVICE

Sheet Sheet1
A4: 46241 | B4: SEGUB GUCE | D4: 105000 | E4: =STATEMENT!E302+C4-D4 -> 2112557 | G4: USN-26172392_EBKG17812040_Soyabean_renew | H4: BFU | I4: UBA

Sheet SUIVI CHEQUIER
B3: Date | C3: DESCRIPTION | D3: MONTANT | E3: NUM DE CHEQUE | F3: MOTIF
B4: 46113 | C4: ALFRED RAJIBER | D4: 7000000 | E4: 5447277 | F4: EXPORT ACC
B5: 46115 | C5: BON BERGER | D5: 2384300 | E5: 5447278 | F5: COTTON SEED TRANSPORT
B6: 46120 | C6: KPATINDE AKODEA EMMANUEL | D6: 1260000 | E6: 5447279 | F6: HOUSE RENT OF AJAY BABO MACH TO AUGUST
C7: CANCELED | E7: 5447280 | F7: CANCELED
C8: ELI COTTON SEED | D8: 10000000 | E8: 5447281 | F8: ACC
C9: ELI COTTON SEED | D9: 4496460 | E9: 5447282 | F9: ACC
B10: 46120 | C10: SUPER SONIC | D10: 428400 | E10: 5447283 | F10: DRUM HYDRAULIC PURCHASE
B11: 46120 | C11: ETS WYM DJIBRIL ALBARKA | D11: 302931 | E11: 5447284 | F11: UD CAKE LABOUR
C12: CANCELED | E12: 5447285 | F12: CANCELED
C13: CANCELED | E13: 5447286 | F13: CANCELED
B14: 46122 | C14: REMISE POUR MITC | D14: 60000000 | E14: 5447287 | F14: Depot pour MITC
B15: 46132 | C15: GABIN | D15: 39500 | E15: 5447288 | F15: COTTON SEED
B16: 46125 | C16: DIDIER | D16: 1200000 | E16: 5447289 | F16: RENT OF GLO HOUSE MARCH TO SEPT
C17: CANCELED | E17: 5447290 | F17: CANCELED
C18: CANCELED | E18: 5447291 | F18: CANCELED
B19: 46126 | C19: HELIOS SECURITY | D19: 349200 | E19: 5447292 | F19: SECURITY GDIZ
B20: 46126 | C20: REMISE POUR MITC | D20: 80000000 | E20: 5447293 | F20: Depot pour MITC
B21: 46128 | C21: IDRISSOU APHISSOU | D21: 501917 | E21: 5447294 | F21: OLABI LABOUR WORK COTTON SEED
B22: 46128 | C22: IDRISSOU APHISSOU | D22: 1000000 | E22: 5447295 | F22: OLABI LABOUR SOYA ACC
B23: 46127 | C23: REMISE POUR MITC | D23: 105000000 | E23: 5447296 | F23: Depot pour MITC
C24: CANCELED | E24: 5447297 | F24: CANCELED
B25: 46129 | C25: ETS DOS ESPOIR ET FILS | D25: 396158 | E25: 5447298 | F25: LABOUR WORK
C26: CANCELED | E26: 5447299 | F26: CANCELED
B27: 46139 | C27: AJEYA BABU NARALASETTI | D27: 250000 | E27: 5447300 | F27: HOUSE RENT OF AJEYA BABU
B28: 46170 | C28: UD CAKE LABOUR WORK | D28: 226972 | E28: 5822101 | F28: LABOUR WORK
B29: 46147 | C29: TRANS SOHA | D29: 6000000 | E29: 5822102 | F29: EXPORT ACC
B30: 46147 | D30: 25000000 | E30: 5822103 | F30: RETRAIT POUR NAP
B31: 46149 | C31: REMISE POUR MITC | D31: 120000000 | E31: 5822104 | F31: Depot pour MITC
C32: CANCELED | E32: 5822105 | F32: CANCELED
C33: OLABI LABOUR WORK | D33: 1875495 | E33: 5822106
B34: 46163 | C34: CHABI BORO HALISSOU | D34: 14481500 | E34: 5822107 | F34: PURCHASE OF SOYA
B35: 46163 | C35: AFFO MOUSSA IBRAHIM | D35: 20000000 | E35: 5822108 | F35: PURCHASE OF SOYA
B36: 46163 | C36: HOUEDANOU JUSTIN | D36: 14005640 | E36: 5822109 | F36: PURCHASE OF SOYA
B37: 46164 | C37: TRANS SOHA | D37: 7000000 | E37: 5822110 | F37: EXPORT ACC
B38: 46164 | C38: TCHANIGA SAMSON | D38: 11144000 | E38: 5822111 | F38: PURCHASE OF SOYA
C39: CANCELED | E39: 5822112 | F39: CANCELED
B40: 46164 | C40: CASIMIR | D40: 27176800 | E40: 5822113 | F40: PURCHASE OF SOYA
B41: 46164 | C41: LEONARD | D41: 12921440 | E41: 5822114 | F41: PURCHASE OF SOYA
B42: 46170 | C42: REMISE POUR MITC | D42: 120000000 | E42: 5822115 | F42: Depot pour MITC

Sheet CHEQUE GIVEB ON COMPANYS NAME,
B2: BON BERGER | G2: SUPER SONIC | L2: HELIOS SECURITY | Q2: OLABI
A3: DATE | B3: AMT | C3: CH NO | D3: REASON | F3: DATE | G3: AMT | H3: CH NO | I3: REASON | K3: DATE | L3: AMT | M3: CH NO | N3: REASON | P3: DATE | Q3: AMT | R3: CH NO | S3: REASON | V3: ETS WYM DJIBRIL ALBARKA
A4: 46115 | B4: 2384300 | C4: 5447278 | D4: COTTON SEED TRANSPORT | F4: 46119 | G4: 428400 | H4: 5447283 | I4: DRUM HYDRAULIC PURCHASE | K4: 46126 | L4: 349200 | M4: 5447292 | N4: SECURITY GDIZ | P4: 46128 | Q4: 501917 | R4: 5447294 | S4: OLABI LABOUR WORK COTTON SEED | U4: DATE | V4: AMT | W4: CH NO | X4: REASON
P5: 46128 | Q5: 1000000 | R5: 5447295 | S5: OLABI LABOUR SOYA ACC | U5: 46120 | V5: 302931 | W5: 5447284 | X5: UD CAKE LABOUR
P6: 46038 | Q6: 774522 | R6: 5447242 | S6: OLABI LABOUR (COTTON-UD CAKE-SHEA NUT)
P7: 46055 | Q7: 3000000 | R7: 5447252 | S7: OLABI LABOUR SOYA ACC
P8: 46055 | Q8: 2630430 | R8: 5447251 | S8: OLABI LABOUR COTTON- UD CAKE- SHEA
P9: 46062 | Q9: 2960667 | R9: 5447255 | S9: OLABI LABOUR COTTON- UD CAKE- SHEA
P10: 46112 | Q10: 2000000 | R10: 5447272 | S10: OLABI LABOUR SOYA ACC
P11: 46112 | Q11: 788678 | R11: 5447271 | S11: OLABI LABOUR COTTON- UD CAKE- SHEA
P12: 46164 | Q12: 1875495 | R12: 5822106 | S12: OLABI LABOUR WORK COTTON SEED
B16: ETS DOS ESPOIR | G16: CERCLE DE DIEU | L16: ACE GLOBAL | Q16: STE UNITED TRADEX SARL
A17: DATE | B17: AMT | C17: CH NO | D17: REASON | F17: DATE | G17: AMT | H17: CH NO | I17: REASON | K17: DATE | L17: AMT | M17: CH NO | N17: REASON | P17: DATE | Q17: AMT | R17: CH NO | S17: REASON
A18: 46045 | B18: 2000000 | C18: 5447243 | D18: LABOUR WORK | F18: 46045 | G18: 3000000 | H18: 5447245 | I18: COTTON SEED TRANSPORT | K18: 46056 | L18: 2134000 | M18: 5447250 | P18: 46056 | Q18: 1070000 | R18: 5447248 | S18: ACHAT DE MOTO
A19: 46049 | B19: 1000000 | C19: 5447246 | D19: LABOUR WORK | F19: 46051 | G19: 9000000 | H19: 5447249 | I19: COTTON SEED TRANSPORT
A20: 46057 | B20: 594760 | C20: 5447253 | D20: LABOUR WORK | F20: 46093 | G20: 7500000 | H20: 5447260 | I20: COTTON SEED TRANSPORT
A21: 46112 | B21: 385371 | C21: 5447275 | D21: LABOUR WORK | F21: 46112 | G21: 10000000 | H21: 5447281 | I21: COTTON SEED TRANSPORT/ AVANCE TRANSPORT NIKKI
A22: 46129 | B22: 396158 | C22: 5447298 | D22: LABOUR WORK | F22: 46112 | G22: 4496460 | H22: 5447282 | I22: COTTON SEED TRANSPORT / SOLD ANCIEN COMPTE

Sheet UD CAKE
C3: SAMBA | H3: MENANYI NICOLAS | M3: DANIEL | R3: BANTHAL | W3: KA AZIZ
B4: DATE | C4: AMT | D4: CH NO | E4: REASON | G4: DATE | H4: AMT | I4: CH NO | J4: REASON | L4: DATE | M4: AMT | N4: CH NO | O4: REASON | Q4: DATE | R4: AMT | S4: CH NO | T4: REASON | V4: DATE | W4: AMT | X4: CH NO | Y4: REASON
B5: 46034 | C5: 5500000 | D5: VERSEMENT | E5: UD CAKE SALES | G5: 46107 | H5: 32000000 | I5: VERSEMENT | J5: UD CAKE SALES | L5: 46125 | M5: 87000000 | N5: VERSEMENT | O5: UD CAKE SALES | Q5: 46127 | R5: 51840000 | S5: VERSEMENT | T5: UD CAKE SALES | V5: 46133 | W5: 46080000 | X5: VERSEMENT | Y5: UD CAKE SALES
B6: 46038 | C6: 14500000 | D6: VERSEMENT | E6: UD CAKE SALES_100MT_160K/MT | G6: 46141 | H6: 41250000 | I6: VERSEMENT | J6: UD CAKE SALES
B7: 46038 | C7: 1500000 | D7: VERSEMENT
B8: 46043 | C8: 14500000 | D8: VERSEMENT | E8: UD CAKE SALES
B9: 46045 | C9: 14500000 | D9: VERSEMENT | E9: UD CAKE SALES
B10: 46051 | C10: 21750000 | D10: VERSEMENT | E10: UD CAKE SALES
B11: 46051 | C11: 14500000 | D11: VERSEMENT | E11: UD CAKE SALES
B12: 46058 | C12: 23000000 | D12: VERSEMENT | E12: UD CAKE SALES
B13: 46078 | C13: 20000000 | D13: VERSEMENT | E13: UD CAKE SALES
B14: 46079 | C14: 32000000 | D14: VERSEMENT | E14: UD CAKE SALES
B15: 46091 | C15: 4000000 | D15: VERSEMENT | E15: UD CAKE SALES
B16: 46122 | C16: 16000000 | D16: VERSEMENT | E16: UD CAKE SALES
B17: 46126 | C17: 16000000 | D17: VERSEMENT | E17: UD CAKE SALES
