Workbook

Sheet CHECKING
D7: CREDIT MOVMENTS AS PER STATEMENT | E7: =SUM(STATEMENT!C5:C1048576) -> 897904740
D8: CREDIT MOVMENTS AS PER ALL ACCOUNTS | E8: =MVT_CAISSE!C8+BANQUE!C9+'VENTE_EXP_LOCAL_(CREDIT)'!C8 -> 897904740
D9: DIFFRENCE | E9: =E7-E8 -> 0
D12: DEBIT MOVMENTS AS PER STATEMENT | E12: =SUM(STATEMENT!D5:D1048576) -> 681781336
D13: DEBIT MOVMENTS AS PER ALL ACCOUNTS | E13: =MVT_CAISSE!D8+BANQUE!D9+'ACHAT_MP_(DEBIT)'!C7+'DEPENCES_EXP ACC_(DEBIT)'!C8+'AUTRES_DEPENSES_(DEBIT)'!C14 -> 681781336
D14: DIFFRENCE | E14: =E12-E13 -> 0

Sheet STATEMENT
A1: NAP BIIC BANK STATEMENT 2026
A3: Date | B3: DESCRIPTION | C3: CREDIT | D3: DEBIT | E3: SOLDE | F3: NUM DE CHEQUE | G3: MOTIF | H3: CATEGORIE
A4: 46023 | B4: SOLDE INITIAL | C4: 190299124 | E4: =C4-D4 -> 190299124
A5: 46022 | B5: KIKI FLORENT/ JOSPIN | D5: 20653060 | E5: =E4+C5-D5 -> 169646064 | F5: 3898137 | G5: SOYA PURCHASE | H5: PURCHASE OF SOYA
A6: 46022 | B6: GOUDOU DOSSOU ROMAIN | D6: 26548700 | E6: =E5+C6-D6 -> 143097364 | F6: 3898138 | G6: SOYA PURCHASE | H6: PURCHASE OF SOYA
A7: 46022 | B7: VLAVONOU ZINSOU PIERRE | D7: 20020200 | E7: =E6+C7-D7 -> 123077164 | F7: 3898139 | G7: SOYA PURCHASE | H7: PURCHASE OF SOYA
A8: 46024 | B8: GOUNOU GOUGNON ELISABETH | D8: 22816000 | E8: =E7+C8-D8 -> 100261164 | F8: 3898140 | G8: SOYA PURCHASE | H8: PURCHASE OF SOYA
A9: 46024 | B9: CERCLE DE DIEU | D9: 5000000 | E9: =E8+C9-D9 -> 95261164 | F9: 3898141 | G9: COTTON SEED TRANSPORT ACC/ ELIE | H9: TRANSPORT/COTTON SEED
A10: 46022 | B10: DAA-HINGBANOU A. ZANMENOU VIRG | D10: 21529800 | E10: =E9+C10-D10 -> 73731364 | F10: 3898142 | G10: SOYA PURCHASE | H10: PURCHASE OF SOYA
A11: 46022 | B11: TRANSFERT SUR COMPTE DECAISSEMENT | D11: 1000000 | E11: =E10+C11-D11 -> 72731364 | G11: COMPTE DECAISSEMENT | H11: COMPTE DECAISSEMENT
A12: 46024 | B12: HOUEDANOU ENAGNON JUSTIN | D12: 18384640 | E12: =E11+C12-D12 -> 54346724 | F12: 3898143 | G12: SOYA PURCHASE | H12: PURCHASE OF SOYA
A13: 46035 | B13: ACE GLOBAL | D13: 1067000 | E13: =E12+C13-D13 -> 53279724 | G13: Paiement de facture Octobre 2025 (Ref ) | H13: SERVICES
A14: 46045 | B14: ELHADJ GUEYE | C14: 72500000 | E14: =E13+C14-D14 -> 125779724 | G14: UD CAKE SALES/ SENEGAL_500MT@145K XOF_ FACT PROFORMA 1001 | H14: SALES/ UD CAKES
A15: 46048 | B15: AMADOU ABDOUL GANIOU/ ALADJI MAIGA | C15: 30000000 | E15: =E14+C15-D15 -> 155779724 | G15: UD CAKE SALES/ ALADJI MAIGA_500MT@148K XOF_AVANCE 1_FACT PROFORMA 1002 | H15: SALES/ UD CAKES
A16: 46048 | B16: AMADOU ABDOUL GANIOU/ ALADJI MAIGA | C16: 30000000 | E16: =E15+C16-D16 -> 185779724 | G16: UD CAKE SALES/ ALADJI MAIGA_500MT@148K XOF_AVANCE 2_FACT PROFORMA 1002 | H16: SALES/ UD CAKES
A17: 46054 | B17: FRAIS BANCAIRE | D17: 5500 | E17: =E16+C17-D17 -> 185774224 | G17: FRAIS BANCAIRE | H17: FRAIS BANCAIRE
A18: 46055 | B18: AMADOU ABDOUL GANIOU/ ALADJI MAIGA | C18: 14000000 | E18: =E17+C18-D18 -> 199774224 | G18: UD CAKE SALES/ ALADJI MAIGA_500MT@148K XOF_AVANCE 3_FACT PROFORMA 1002 | H18: SALES/ UD CAKES
A19: 46056 | B19: GOUNON MAHUSSI OCEANE | C19: 15300000 | E19: =E18+C19-D19 -> 215074224 | G19: UD CAKE SALES/ MME OCEANE_100MT@153K XOF | H19: SALES/ UD CAKES
A20: 46058 | B20: REMBOURSEMENT PRET | D20: 202000000 | E20: =E19+C20-D20 -> 13074224 | G20: REMBOURSEMENT ECHEANCE DE 05/01/2026 | H20: REMBOURSEMENT PRET
A21: 46064 | B21: GOUNON MAHUSSI OCEANE | C21: 30600000 | E21: =E20+C21-D21 -> 43674224 | G21: UD CAKE SALES/ MME OCEANE_200MT@158K XOF_AVANCE 1 | H21: SALES/ UD CAKES
A22: 46064 | B22: SEGUB GUCE | D22: 3588261 | E22: =E21+C22-D22 -> 40085963 | G22: USN-26029936_265903694_Shea Butter | H22: BFU
A23: 46064 | B23: SEGUB GUCE | D23: 1038681 | E23: =E22+C23-D23 -> 39047282 | G23: USN-26029942_MEDUCT183752_Shea Doc | H23: BFU
A24: 46064 | B24: SEGUB GUCE | D24: 2006594 | E24: =E23+C24-D24 -> 37040688 | G24: USN-26029947_MEDUCT184040_Shea Butter | H24: BFU
A25: 46064 | B25: SEGUB GUCE | D25: 2007439 | E25: =E24+C25-D25 -> 35033249 | G25: USN-26030058_MEDUCT184412_Shea Butter | H25: BFU
A26: 46064 | B26: SEGUB GUCE | D26: 1224773 | E26: =E25+C26-D26 -> 33808476 | G26: USN-26030075_MEDUCT183984_Shea Butter | H26: BFU
A27: 46069 | B27: GOUNON MAHUSSI OCEANE | C27: 1000000 | E27: =E26+C27-D27 -> 34808476 | G27: UD CAKE SALES/ MME OCEANE_200MT@158K XOF_REGLEMENT | H27: SALES/ UD CAKES
A28: 46065 | B28: SEGUB GUCE | D28: 2399616 | E28: =E27+C28-D28 -> 32408860 | G28: USN-26030010_MEDUCT183943_Shea Butter | H28: BFU
A29: 46065 | B29: TRANSFERT SUR COMPTE DECAISSEMENT | D29: 1550000 | E29: =E28+C29-D29 -> 30858860 | G29: COMPTE DECAISSEMENT | H29: COMPTE DECAISSEMENT
A30: 46066 | B30: SEGUB GUCE | D30: 1953418 | E30: =E29+C30-D30 -> 28905442 | G30: USN-26032271_TMR260093EFC_ | H30: BFU
A31: 46070 | B31: SEGUB GUCE | D31: 2011384 | E31: =E30+C31-D31 -> 26894058 | G31: USN-26032428_MEDUCT184644_Shea Butter | H31: BFU
A32: 46072 | B32: SEGUB GUCE | D32: 1053192 | E32: =E31+C32-D32 -> 25840866 | G32: USN-26034909_MEDUCT185039_Shea Doc | H32: BFU
A33: 46073 | B33: SEGUB GUCE | D33: 3574035 | E33: =E32+C33-D33 -> 22266831 | G33: USN-26034867_MEDUCT185070_Shea Butter | H33: BFU
A34: 46077 | B34: ENTREPRISE SIBY MOHAMED-EXPORT | C34: 3200000 | E34: =E33+C34-D34 -> 25466831 | G34: UD CAKE SALES 540 MT@ 150K TO MAURTANIA CLIENT | H34: SALES/ UD CAKES
A35: 46077 | B35: SEGUB GUCE | D35: 153161 | E35: =E34+C35-D35 -> 25313670 | G35: USN-26037812__ | H35: BFU
A36: 46078 | B36: RETRAIT POUR NAP | D36: 20000000 | E36: =E35+C36-D36 -> 5313670 | F36: 3898144 | G36: MANGALAM | H36: WITHDRAWAL
A37: 46079 | B37: DEMANDE DE CHEQUIER | D37: 20000 | E37: =E36+C37-D37 -> 5293670 | H37: FRAIS BANCAIRE
A38: 46082 | B38: FRAIS BANCAIRE | D38: 5500 | E38: =E37+C38-D38 -> 5288170 | G38: FRAIS BANCAIRE | H38: FRAIS BANCAIRE
A39: 46085 | B39: AMADOU ABDOUL GANIOU/ ALADJI MAIGA | C39: 358160 | E39: =E38+C39-D39 -> 5646330 | G39: UD CAKE_SALES_2MT@148K | H39: SALES/ UD CAKES
A40: 46085 | B40: SEGUB GUCE | D40: 1808977 | E40: =E39+C40-D40 -> 3837353 | G40: USN-26043603_266361527/267487925_UD CAKE | H40: BFU
A41: 46085 | B41: TRANSFERT SUR COMPTE DECAISSEMENT | D41: 1250000 | E41: =E40+C41-D41 -> 2587353 | G41: COMPTE DECAISSEMENT | H41: COMPTE DECAISSEMENT
...

Sheet MVT_CAISSE
F3: CAISSE DEPOSIT | H3: =SUBTOTAL(9,H5:H5000) -> 462249900 | M3: WITHDRAWAL | O3: =SUBTOTAL(9,O5:O5000) -> 30000000 | T3: REMBOURSEMENT | V3: =SUBTOTAL(9,V5:V15) -> 296800
B4: PRODUIT | C4: MONTANT CREDIT | D4: MONTANT DEBIT | F4: DATE | G4: DESCRIPTION | H4: AMT | I4: CH NO | J4: MOTIF | K4: CATEGRIE | M4: DATE | N4: DESCRIPTION | O4: AMT | P4: CH NO | Q4: MOTIF | R4: CATEGRIE | T4: DATE | U4: DESCRIPTION | V4: AMT | W4: CH NO | X4: MOTIF | Y4: CATEGRIE
B5: CAISSE DEPOSIT | C5: =H3 -> 462249900 | F5: {=_xlfn.CHOOSECOLS(_xlfn._xlws.FILTER(STATEMENT!A3:H5000,STATEMENT!H3:H5000="CAISSE DEPOSIT"),1,2,3,6,7,8)} -> 46136 | G5: VERSEMENT BY NAP | H5: 25000000 | I5: 0 | J5: CAISSE DEPOSIT | K5: CAISSE DEPOSIT | M5: {=_xlfn.CHOOSECOLS(_xlfn._xlws.FILTER(STATEMENT!A3:H5000,STATEMENT!H3:H5000="WITHDRAWAL"),1,2,4,6,7,8)} -> 46078 | N5: RETRAIT POUR NAP | O5: 20000000 | P5: 3898144 | Q5: MANGALAM | R5: WITHDRAWAL | T5: {=_xlfn.CHOOSECOLS(_xlfn._xlws.FILTER(STATEMENT!A3:H5000,STATEMENT!H3:H5000="REMBOURSEMENT"),1,2,4,6,7,8)} -> 46244 | U5: REMBOURSEMENT | V5: 296800 | W5: 3898156 | X5: REMBOURSEMENT DE COMMANDE NON EXECUTEE A GOUNOU OCEANE | Y5: REMBOURSEMENT
B6: WITHDRAWAL | D6: =O3 -> 30000000 | F6: 46147 | G6: VERSEMENT BY NAP | H6: 500000 | I6: 0 | J6: CAISSE DEPOSIT | K6: CAISSE DEPOSIT | M6: 46178 | N6: MOUSSA IBRAHIM | O6: 10000000 | P6: 3898152 | Q6: RETRAIT POUR NAP SARL/MOUSSA IBRAHIM | R6: WITHDRAWAL
B7: REMBOURSEMENT | D7: =V3 -> 296800 | F7: 46154 | G7: VERSEMENT BY NAP | H7: 3500000 | I7: 0 | J7: CAISSE DEPOSIT | K7: CAISSE DEPOSIT
B8: TOTAL | C8: =SUM(C5:C7) -> 462249900 | D8: =SUM(D5:D7) -> 30296800 | F8: 46182 | G8: VERSEMENT BY AFFO MOUSSA IBRAHIM | H8: 8000000 | I8: 0 | J8: RECETTE | K8: CAISSE DEPOSIT
F9: 46186 | G9: VERSEMENT BY AFFO MOUSSA IBRAHIM | H9: 999900 | I9: 0 | J9: RECETTE | K9: CAISSE DEPOSIT
F10: 46188 | G10: VERSEMENT BY GARBA IBRAHIM | H10: 1250000 | I10: 0 | J10: RECETTE | K10: CAISSE DEPOSIT
F11: 46219 | G11: REMISE PAR NAP | H11: 100000000 | I11: 0 | J11: 0 | K11: CAISSE DEPOSIT
F12: 46233 | G12: REMISE PAR NAP | H12: 112000000 | I12: 0 | J12: 0 | K12: CAISSE DEPOSIT
F13: 46248 | G13: VERSEMENT CASH | H13: 6000000 | I13: 0 | J13: 0 | K13: CAISSE DEPOSIT
F14: 46290 | G14: NAP ECOBANK | H14: 55000000 | I14: 0 | J14: 0 | K14: CAISSE DEPOSIT
F15: 46296 | G15: NAP ECOBANK | H15: 60000000 | I15: 0 | J15: 0 | K15: CAISSE DEPOSIT
F16: 46302 | G16: NAP ECOBANK | H16: 90000000 | I16: 0 | J16: 0 | K16: CAISSE DEPOSIT

Sheet BANQUE
F3: COMPTE DECAISSEMENT | H3: =SUBTOTAL(9,H5:H5000) -> 6730000 | I3: DEBIT | M3: REMBOURSEMENT PRET | O3: =SUBTOTAL(9,O5:O5000) -> 404000000 | P3: DEBIT | T3: FRAIS BANCAIRE | V3: =SUBTOTAL(9,V5:V5000) -> 83904 | W3: DEBIT | AA3: RECOUVREMENT IMPAYE | AC3: =SUBTOTAL(9,AC5:AC5000) -> 9129320 | AD3: DEBIT
B4: PRODUIT | C4: MONTANT CREDIT | D4: MONTANT DEBIT | F4: DATE | G4: DESCRIPTION | H4: AMT | I4: CH NO | J4: MOTIF | K4: CATEGRIE | M4: DATE | N4: DESCRIPTION | O4: AMT | P4: CH NO | Q4: MOTIF | R4: CATEGRIE | T4: DATE | U4: DESCRIPTION | V4: AMT | W4: CH NO | X4: MOTIF | Y4: CATEGRIE | AA4: DATE | AB4: DESCRIPTION | AC4: AMT | AD4: CH NO | AE4: MOTIF | AF4: CATEGRIE
B5: COMPTE DECAISSEMENT | D5: =H3 -> 6730000 | F5: {=_xlfn.CHOOSECOLS(_xlfn._xlws.FILTER(STATEMENT!A3:H5000,STATEMENT!H3:H5000="COMPTE DECAISSEMENT"),1,2,4,6,7,8)} -> 46022 | G5: TRANSFERT SUR COMPTE DECAISSEMENT | H5: 1000000 | I5: 0 | J5: COMPTE DECAISSEMENT | K5: COMPTE DECAISSEMENT | M5: {=_xlfn.CHOOSECOLS(_xlfn._xlws.FILTER(STATEMENT!A3:H5000,STATEMENT!H3:H5000="REMBOURSEMENT PRET"),1,2,4,6,7,8)} -> 46058 | N5: REMBOURSEMENT PRET | O5: 202000000 | P5: 0 | Q5: REMBOURSEMENT ECHEANCE DE 05/01/2026 | R5: REMBOURSEMENT PRET | T5: {=_xlfn.CHOOSECOLS(_xlfn._xlws.FILTER(STATEMENT!A3:H5000,STATEMENT!H3:H5000="FRAIS BANCAIRE"),1,2,4,6,7,8)} -> 46054 | U5: FRAIS BANCAIRE | V5: 5500 | W5: 0 | X5: FRAIS BANCAIRE | Y5: FRAIS BANCAIRE | AA5: {=_xlfn.CHOOSECOLS(_xlfn._xlws.FILTER(STATEMENT!A3:H5000,STATEMENT!H3:H5000="RECOUVREMENT IMPAYE"),1,2,4,6,7,8)} -> 46220 | AB5: RECOUVREMENT IMPAYE 16979 | AC5: 78019 | AD5: 0 | AE5: 0 | AF5: RECOUVREMENT IMPAYE
B6: REMBOURSEMENT PRET | D6: =O3 -> 404000000 | F6: 46065 | G6: TRANSFERT SUR COMPTE DECAISSEMENT | H6: 1550000 | I6: 0 | J6: COMPTE DECAISSEMENT | K6: COMPTE DECAISSEMENT | M6: 46139 | N6: REMBOURSEMENT PRET | O6: 202000000 | P6: 0 | Q6: REMBOURSEMENT ECHEANCE DE 05/04/2026 _ COMPTE PRET INSTALLATION DE SITE | R6: REMBOURSEMENT PRET | T6: 46079 | U6: DEMANDE DE CHEQUIER | V6: 20000 | W6: 0 | X6: 0 | Y6: FRAIS BANCAIRE | AA6: 46220 | AB6: RECOUVREMENT IMPAYE 16979 | AC6: 9051301 | AD6: 0 | AE6: 0 | AF6: RECOUVREMENT IMPAYE
B7: FRAIS BANCAIRE | D7: =V3 -> 83904 | F7: 46085 | G7: TRANSFERT SUR COMPTE DECAISSEMENT | H7: 1250000 | I7: 0 | J7: COMPTE DECAISSEMENT | K7: COMPTE DECAISSEMENT | T7: 46082 | U7: FRAIS BANCAIRE | V7: 5500 | W7: 0 | X7: FRAIS BANCAIRE | Y7: FRAIS BANCAIRE
B8: RECOUVREMENT IMPAYE | D8: =AC3 -> 9129320 | F8: 46147 | G8: TRANSFERT SUR COMPTE DECAISSEMENT | H8: 2930000 | I8: 0 | J8: COMPTE DECAISSEMENT | K8: COMPTE DECAISSEMENT | T8: 46113 | U8: FRAIS BANCAIRE | V8: 5500 | W8: 0 | X8: FRAIS BANCAIRE | Y8: FRAIS BANCAIRE
C9: =SUM(C5:C8) -> 0 | D9: =SUM(D5:D8) -> 419943224 | T9: 46139 | U9: FRAIS BANCAIRE | V9: 4950 | W9: 0 | X9: FRAIS BANCAIRE | Y9: FRAIS BANCAIRE
T10: 46143 | U10: FRAIS BANCAIRE | V10: 5500 | W10: 0 | X10: FRAIS BANCAIRE | Y10: FRAIS BANCAIRE
T11: 46174 | U11: FRAIS BANCAIRE | V11: 5500 | W11: 0 | X11: FRAIS BANCAIRE | Y11: FRAIS BANCAIRE
T12: 46182 | U12: FRAIS BANCAIRE | V12: 4950 | W12: 0 | X12: 0 | Y12: FRAIS BANCAIRE
T13: 46220 | U13: FRAIS BANCAIRE | V13: 17133 | W13: 0 | X13: 0 | Y13: FRAIS BANCAIRE
T14: 46234 | U14: FRAIS BANCAIRE | V14: 9371 | W14: 0 | X14: 0 | Y14: FRAIS BANCAIRE

Sheet VENTE_EXP_LOCAL_(CREDIT)
E3: SALES/ UD CAKES | G3: =SUBTOTAL(9,G5:G5000) -> 380178160 | H3: CREDIT | L3: SALES/ COTTON SEED | N3: =SUBTOTAL(9,N5:N5000) -> 54916680 | O3: CREDIT | S3: SALES/ SOYA MEAL | U3: =SUBTOTAL(9,U5:U5000) -> 560000 | V3: CREDIT
B4: PRODUIT | C4: MONTANT CREDIT | E4: DATE | F4: DESCRIPTION | G4: AMT | H4: CH NO | I4: MOTIF | J4: CATEGORIE | L4: DATE | M4: DESCRIPTION | N4: AMT | O4: CH NO | P4: MOTIF | Q4: CATEGORIE | S4: DATE | T4: DESCRIPTION | U4: AMT | V4: CH NO | W4: MOTIF | X4: CATEGORIE
B5: SALES/ UD CAKES | C5: =G3 -> 380178160 | E5: {=_xlfn.CHOOSECOLS(_xlfn._xlws.FILTER(STATEMENT!A3:H5000,STATEMENT!H3:H5000="SALES/ UD CAKES"),1,2,3,6,7,8)} -> 46045 | F5: ELHADJ GUEYE | G5: 72500000 | H5: 0 | I5: UD CAKE SALES/ SENEGAL_500MT@145K XOF_ FACT PROFORMA 1001 | J5: SALES/ UD CAKES | L5: {=_xlfn.CHOOSECOLS(_xlfn._xlws.FILTER(STATEMENT!A3:H5000,STATEMENT!H3:H5000="SALES/ COTTON SEED"),1,2,3,6,7,8)} -> 46177 | M5: BENIN COTON | N5: 54916680 | O5: 0 | P5: Encaissement cheque 4839552 BIIC | Q5: SALES/ COTTON SEED | S5: {=_xlfn.CHOOSECOLS(_xlfn._xlws.FILTER(STATEMENT!A3:H5000,STATEMENT!H3:H5000="SALES/ SOYA MEAL"),1,2,3,6,7,8)} -> 46234 | T5: HOUNKANRIN MARTIN | U5: 560000 | V5: 0 | W5: SALES SOYABEAN MEAL | X5: SALES/ SOYA MEAL
B6: SALES/ COTTON SEED | C6: =N3 -> 54916680 | E6: 46048 | F6: AMADOU ABDOUL GANIOU/ ALADJI MAIGA | G6: 30000000 | H6: 0 | I6: UD CAKE SALES/ ALADJI MAIGA_500MT@148K XOF_AVANCE 1_FACT PROFORMA 1002 | J6: SALES/ UD CAKES
B7: SALES/ SOYA MEAL | C7: =U3 -> 560000 | E7: 46048 | F7: AMADOU ABDOUL GANIOU/ ALADJI MAIGA | G7: 30000000 | H7: 0 | I7: UD CAKE SALES/ ALADJI MAIGA_500MT@148K XOF_AVANCE 2_FACT PROFORMA 1002 | J7: SALES/ UD CAKES
B8: TOTAL | C8: =SUM(C5:C7) -> 435654840 | E8: 46055 | F8: AMADOU ABDOUL GANIOU/ ALADJI MAIGA | G8: 14000000 | H8: 0 | I8: UD CAKE SALES/ ALADJI MAIGA_500MT@148K XOF_AVANCE 3_FACT PROFORMA 1002 | J8: SALES/ UD CAKES
E9: 46056 | F9: GOUNON MAHUSSI OCEANE | G9: 15300000 | H9: 0 | I9: UD CAKE SALES/ MME OCEANE_100MT@153K XOF | J9: SALES/ UD CAKES
E10: 46064 | F10: GOUNON MAHUSSI OCEANE | G10: 30600000 | H10: 0 | I10: UD CAKE SALES/ MME OCEANE_200MT@158K XOF_AVANCE 1 | J10: SALES/ UD CAKES
E11: 46069 | F11: GOUNON MAHUSSI OCEANE | G11: 1000000 | H11: 0 | I11: UD CAKE SALES/ MME OCEANE_200MT@158K XOF_REGLEMENT | J11: SALES/ UD CAKES
E12: 46077 | F12: ENTREPRISE SIBY MOHAMED-EXPORT | G12: 3200000 | H12: 0 | I12: UD CAKE SALES 540 MT@ 150K TO MAURTANIA CLIENT | J12: SALES/ UD CAKES
E13: 46085 | F13: AMADOU ABDOUL GANIOU/ ALADJI MAIGA | G13: 358160 | H13: 0 | I13: UD CAKE_SALES_2MT@148K | J13: SALES/ UD CAKES
E14: 46128 | F14: AMADOU ABDOUL GANIOU/ ALADJI MAIGA | G14: 50000000 | H14: 0 | I14: UD CAKE SALES/ ALADJI MAIGA_1000MT@155K XOF_AVANCE 1_FACT PROFORMA 1011 | J14: SALES/ UD CAKES
E15: 46129 | F15: ADETONAH DAMIEN/ DERE IMPORT EXPORT | G15: 25000000 | H15: 0 | I15: UD CAKE SALES/ DAMIAN_1500MT@155K XOF_AVANCE 1_FACT PROFORMA 1012 | J15: SALES/ UD CAKES
E16: 46129 | F16: ADETONAH DAMIEN/ DERE IMPORT EXPORT | G16: 50000000 | H16: 0 | I16: UD CAKE SALES/ DAMIAN_1500MT@155K XOF_AVANCE 2_FACT PROFORMA 1012 | J16: SALES/ UD CAKES
E17: 46132 | F17: AMADOU ABDOUL GANIOU/ ALADJI MAIGA | G17: 27500000 | H17: 0 | I17: UD CAKE SALES/ ALADJI MAIGA_1000MT@155K XOF_AVANCE 2_FACT PROFORMA 1011 | J17: SALES/ UD CAKES
E18: 46133 | F18: UNIRISE SARL/SHEIK & MARIAM SENEGAL | G18: 15360000 | H18: 0 | I18: UD CAKE SALES/ UNIRISE SHEIK & MARIAM SEN_192MT@160K XOF_AVANCE 1_FACT PROFORMA 1007 | J18: SALES/ UD CAKES
E19: 46132 | F19: UNIRISE SARL/SHEIK & MARIAM SENEGAL | G19: 7680000 | H19: 0 | I19: UD CAKE SALES/ UNIRISE SHEIK & MARIAM SEN_192MT@160K XOF_AVANCE 1_FACT PROFORMA 1007 | J19: SALES/ UD CAKES
E20: 46134 | F20: UNIRISE SARL/SHEIK & MARIAM SENEGAL | G20: 7680000 | H20: 0 | I20: UD CAKE SALES/ UNIRISE SHEIK & MARIAM SEN_192MT@160K XOF_RGLMT_FACT PROFORMA 1007 | J20: SALES/ UD CAKES

Sheet ACHAT_MP_(DEBIT)
E3: PURCHASE OF SOYA | G3: =SUBTOTAL(9,G5:G5000) -> 129952400
B4: PRODUIT | C4: MONTANT DEBIT | E4: DATE | F4: DESCRIPTION | G4: AMT | H4: CH NO | I4: MOTIF | J4: CATEGORIE
B5: PURCHASE OF SOYA | C5: =G3 -> 129952400 | E5: {=_xlfn.CHOOSECOLS(_xlfn._xlws.FILTER(STATEMENT!A3:H5000,STATEMENT!H3:H5000="PURCHASE OF SOYA"),1,2,4,6,7,8)} -> 46022 | F5: KIKI FLORENT/ JOSPIN | G5: 20653060 | H5: 3898137 | I5: SOYA PURCHASE | J5: PURCHASE OF SOYA
E6: 46022 | F6: GOUDOU DOSSOU ROMAIN | G6: 26548700 | H6: 3898138 | I6: SOYA PURCHASE | J6: PURCHASE OF SOYA
B7: TOTAL | C7: =SUM(C5:C6) -> 129952400 | E7: 46022 | F7: VLAVONOU ZINSOU PIERRE | G7: 20020200 | H7: 3898139 | I7: SOYA PURCHASE | J7: PURCHASE OF SOYA
E8: 46024 | F8: GOUNOU GOUGNON ELISABETH | G8: 22816000 | H8: 3898140 | I8: SOYA PURCHASE | J8: PURCHASE OF SOYA
E9: 46022 | F9: DAA-HINGBANOU A. ZANMENOU VIRG | G9: 21529800 | H9: 3898142 | I9: SOYA PURCHASE | J9: PURCHASE OF SOYA
E10: 46024 | F10: HOUEDANOU ENAGNON JUSTIN | G10: 18384640 | H10: 3898143 | I10: SOYA PURCHASE | J10: PURCHASE OF SOYA

Sheet DEPENCES_EXP ACC_(DEBIT)
F3: BFU | H3: =SUBTOTAL(9,H5:H5000) -> 69234186 | M3: EXP/ FRET PAYMENT | O3: =SUBTOTAL(9,O5:O10) -> 0
B4: PRODUIT | C4: MONTANT DEBIT | F4: DATE | G4: DESCRIPTION | H4: AMT | I4: CH NO | J4: MOTIF | K4: CATEGORIE | M4: DATE | N4: DESCRIPTION | O4: AMT | P4: CH NO | Q4: MOTIF | R4: CATEGORIE
B5: BFU | C5: =H3 -> 69234186 | F5: {=_xlfn.CHOOSECOLS(_xlfn._xlws.FILTER(STATEMENT!A3:H5000,STATEMENT!H3:H5000="BFU"),1,2,4,6,7,8)} -> 46064 | G5: SEGUB GUCE | H5: 3588261 | I5: 0 | J5: USN-26029936_265903694_Shea Butter | K5: BFU | M5: {=_xlfn.CHOOSECOLS(_xlfn._xlws.FILTER(STATEMENT!A3:H273,STATEMENT!H3:H273="EXP/ FRET PAYMENT"),1,2,4,6,7,8)} -> #VALUE!
F6: 46064 | G6: SEGUB GUCE | H6: 1038681 | I6: 0 | J6: USN-26029942_MEDUCT183752_Shea Doc | K6: BFU
F7: 46064 | G7: SEGUB GUCE | H7: 2006594 | I7: 0 | J7: USN-26029947_MEDUCT184040_Shea Butter | K7: BFU
B8: TOTAL | C8: =SUM(C5:C7) -> 69234186 | F8: 46064 | G8: SEGUB GUCE | H8: 2007439 | I8: 0 | J8: USN-26030058_MEDUCT184412_Shea Butter | K8: BFU
F9: 46064 | G9: SEGUB GUCE | H9: 1224773 | I9: 0 | J9: USN-26030075_MEDUCT183984_Shea Butter | K9: BFU
F10: 46065 | G10: SEGUB GUCE | H10: 2399616 | I10: 0 | J10: USN-26030010_MEDUCT183943_Shea Butter | K10: BFU
F11: 46066 | G11: SEGUB GUCE | H11: 1953418 | I11: 0 | J11: USN-26032271_TMR260093EFC_ | K11: BFU
F12: 46070 | G12: SEGUB GUCE | H12: 2011384 | I12: 0 | J12: USN-26032428_MEDUCT184644_Shea Butter | K12: BFU
F13: 46072 | G13: SEGUB GUCE | H13: 1053192 | I13: 0 | J13: USN-26034909_MEDUCT185039_Shea Doc | K13: BFU
F14: 46073 | G14: SEGUB GUCE | H14: 3574035 | I14: 0 | J14: USN-26034867_MEDUCT185070_Shea Butter | K14: BFU
F15: 46077 | G15: SEGUB GUCE | H15: 153161 | I15: 0 | J15: USN-26037812__ | K15: BFU
F16: 46085 | G16: SEGUB GUCE | H16: 1808977 | I16: 0 | J16: USN-26043603_266361527/267487925_UD CAKE | K16: BFU
F17: 46177 | G17: SEGUB GUCE | H17: 8357398 | I17: 0 | J17: PAYEMENT BFU USN-26125069 POUR BL 270866616 | K17: BFU
F18: 46178 | G18: SEGUB GUCE | H18: 8298216 | I18: 0 | J18: PAYEMENT BFU USN-26126443 POUR BL 270866825 | K18: BFU
F19: 46178 | G19: SEGUB GUCE | H19: 8236768 | I19: 0 | J19: PAYEMENT BFU USN-26127384 POUR BL 270942127 | K19: BFU
F20: 46178 | G20: SEGUB GUCE | H20: 8278183 | I20: 0 | J20: PAYEMENT BFU USN-26126441 POUR BL 270942248 | K20: BFU | O20: =SUM(O5:O18) -> 0 | P20: DEBIT
F21: 46177 | G21: SEGUB GUCE | H21: 8767837 | I21: 0 | J21: PAYEMENT BFU USN-26125053 POUR BL 270942275 | K21: BFU
F22: 46178 | G22: SEGUB GUCE | H22: 1330921 | I22: 0 | J22: PAYEMENT BFU USN-26127276 POUR BL 271284995 | K22: BFU
F23: 46186 | G23: SEGUB GUCE | H23: 1845557 | I23: 0 | J23: PAYEMENT BFU USN-26132380 POUR BL 271285265 | K23: BFU
F24: 46188 | G24: SEGUB GUCE | H24: 1299775 | I24: 0 | J24: USN-26136780_271486702_Soya crude oil | K24: BFU

Sheet AUTRES_DEPENSES_(DEBIT)
E3: CONSTRUCTION | G3: =SUBTOTAL(9,G5:G5000) -> 2467834 | L3: LABOUR WORK | N3: =SUBTOTAL(9,N5:N5000) -> 5965855 | S3: SERVICES | U3: =SUBTOTAL(9,U5:U5000) -> 14885163 | Z3: TRANSPORT/COTTON SEED | AB3: =SUBTOTAL(9,AB5:AB5000) -> 7313443 | AG3: DGI | AI3: =SUBTOTAL(9,AI5:AI5000) -> 1722431
B4: PRODUIT | C4: MONTANT DEBIT | E4: DATE | F4: DESCRIPTION | G4: AMT | H4: CH NO | I4: MOTIF | J4: CATEGRIE | L4: DATE | M4: DESCRIPTION | N4: AMT | O4: CH NO | P4: MOTIF | Q4: CATEGRIE | S4: DATE | T4: DESCRIPTION | U4: AMT | V4: CH NO | W4: MOTIF | X4: CATEGRIE | Z4: DATE | AA4: DESCRIPTION | AB4: AMT | AC4: CH NO | AD4: MOTIF | AE4: CATEGRIE | AG4: DATE | AH4: DESCRIPTION | AI4: AMT | AJ4: CH NO | AK4: MOTIF | AL4: CATEGRIE
B5: CONSTRUCTION | C5: =G3 -> 2467834 | E5: {=_xlfn.CHOOSECOLS(_xlfn._xlws.FILTER(STATEMENT!A3:H5000,STATEMENT!H3:H5000="CONSTRUCTION"),1,2,4,6,7,8)} -> 46182 | F5: NOCIBE | G5: 2467834 | H5: 3898155 | I5: ACHAT DE CIMENT 09/06/2026 | J5: CONSTRUCTION | L5: {=_xlfn.CHOOSECOLS(_xlfn._xlws.FILTER(STATEMENT!A3:H5000,STATEMENT!H3:H5000="LABOUR WORK"),1,2,4,6,7,8)} -> 46154 | M5: IDRISSOU APHISSOU | N5: 1150000 | O5: 0 | P5: OLABI LABOUR SOYA ACC | Q5: LABOUR WORK | S5: {=_xlfn.CHOOSECOLS(_xlfn._xlws.FILTER(STATEMENT!A3:H5000,STATEMENT!H3:H5000="SERVICES"),1,2,4,6,7,8)} -> 46035 | T5: ACE GLOBAL | U5: 1067000 | V5: 0 | W5: Paiement de facture Octobre 2025 (Ref ) | X5: SERVICES | Z5: {=_xlfn.CHOOSECOLS(_xlfn._xlws.FILTER(STATEMENT!A3:H5000,STATEMENT!H3:H5000="TRANSPORT/COTTON SEED"),1,2,4,6,7,8)} -> 46024 | AA5: CERCLE DE DIEU | AB5: 5000000 | AC5: 3898141 | AD5: COTTON SEED TRANSPORT ACC/ ELIE | AE5: TRANSPORT/COTTON SEED | AG5: {=_xlfn.CHOOSECOLS(_xlfn._xlws.FILTER(STATEMENT!A3:H5000,STATEMENT!H3:H5000="DGI"),1,2,4,6,7,8)} -> 46183 | AH5: DGI | AI5: 43200 | AJ5: 0 | AK5: 0 | AL5: DGI
B6: LABOUR WORK | C6: =N3 -> 5965855 | L6: 46157 | M6: OLAITAN COMMUNICATION | N6: 2036146 | O6: 0 | P6: OLABI LABOUR SOYA ACC_EM01767228-12 (1044360 XOF)_EM01767228-11 (1054760)- AIB 3% | Q6: LABOUR WORK | S6: 46140 | T6: ABDULSALAM OLAKOUNLE/ ODJE NIGERIA CONTRACTOR | U6: 1500000 | V6: 0 | W6: OJ REAL ETP WORK , NIGERIA COTRACTER, PIPILINE WORK, BOILER OIL MILL | X6: SERVICES | Z6: 46177 | AA6: OLAITAN COMMUNICATION | AB6: 1328459 | AC6: 3898151 | AD6: PRESTATION DE MANUTENTION GRAINE DE COTON/SOJA/KARITE | AE6: TRANSPORT/COTTON SEED | AG6: 46183 | AH6: DGI | AI6: 580285 | AJ6: 0 | AK6: 0 | AL6: DGI
B7: SERVICES | C7: =U3 -> 14885163 | L7: 46170 | M7: ETS DOS ESPOIR ET FILS | N7: 279709 | O7: 0 | P7: LABOUR WORK_EM01335995-329 (288360 XOF)- AIB 3% | Q7: LABOUR WORK | S7: 46139 | T7: CONTRELEC GDIZ | U7: 4538163 | V7: 0 | W7: PAYMENT CONTRELEC / CHEQUE CERTIFIE | X7: SERVICES | Z7: 46182 | AA7: OLAITAN COMMUNICATION | AB7: 984984 | AC7: 3898153 | AD7: PRESTATION DE MANUTENTION GRAINE DE COTON/SOJA/KARITE | AE7: TRANSPORT/COTTON SEED | AG7: 46183 | AH7: DGI | AI7: 1098946 | AJ7: 0 | AK7: 0 | AL7: DGI
B8: TRANSPORT/COTTON SEED | C8: =AB3 -> 7313443 | L8: 46182 | M8: OLAITAN COMMUNICATION | N8: 2500000 | O8: 3898154 | P8: OLABI LABOUR WORK SOYA ACCOMPTE | Q8: LABOUR WORK | S8: 46245 | T8: SALARY JULY | U8: 3280000 | V8: 0 | W8: ORDRE DE VIREMENT SALAIRE MAI 2026 | X8: SERVICES
B9: DGI | C9: =AI3 -> 1722431 | S9: 46248 | T9: ADIGNON SYLVAIN / CASH SALARY | U9: 4500000 | V9: 3898158 | W9: NAP EMPLOYEE CASH SALARY | X9: SERVICES
B14: TOTAL | C14: =SUM(C5:C13) -> 32354726

Sheet SUIVI CHEQUIER
B3: Date | C3: DESCRIPTION | D3: MONTANT | E3: NUM DE CHEQUE | F3: MOTIF
B4: 46113 | C4: ALFRED RAJIBER | D4: 7000000 | E4: 5447277 | F4: EXPORT ACC
B5: 46115 | C5: BON BERGER | D5: 2384300 | E5: 5447278 | F5: COTTON SEED TRANSPORT
B6: 46120 | C6: KPATINDE AKODEA EMMANUEL | D6: 1260000 | E6: 5447279 | F6: HOUSE RENT OF AJAY BABO MACH TO AUGUST
C7: CANCELED | E7: 5447280 | F7: CANCELED
C8: ELI COTTON SEED | D8: 10000000 | E8: 5447281 | F8: ACC
C9: ELI COTTON SEED | D9: 4496460 | E9: 5447282 | F9: ACC
B10: 46120 | C10: SUPER SONIC | D10: 428400 | E10: 5447283 | F10: DRUM HYDRAULIC PURCHASE
B11: 46120 | C11: ETS WYM DJIBRIL ALBARKA | D11: 302931 | E11: 5447284 | F11: UD CAKE LABOUR
C12: CANCELED | E12: 5447285 | F12: CANCELED
C13: CANCELED | E13: 5447286 | F13: CANCELED
B14: 46122 | C14: REMISE POUR MITC | D14: 60000000 | E14: 5447287 | F14: Depot pour MITC
B15: 46132 | C15: GABIN | D15: 39500 | E15: 5447288 | F15: COTTON SEED
B16: 46125 | C16: DIDIER | D16: 1200000 | E16: 5447289 | F16: RENT OF GLO HOUSE MARCH TO SEPT
C17: CANCELED | E17: 5447290 | F17: CANCELED
C18: CANCELED | E18: 5447291 | F18: CANCELED
B19: 46126 | C19: HELIOS SECURITY | D19: 349200 | E19: 5447292 | F19: SECURITY GDIZ
B20: 46126 | C20: REMISE POUR MITC | D20: 80000000 | E20: 5447293 | F20: Depot pour MITC
B21: 46128 | C21: IDRISSOU APHISSOU | D21: 501917 | E21: 5447294 | F21: OLABI LABOUR WORK COTTON SEED
B22: 46128 | C22: IDRISSOU APHISSOU | D22: 1000000 | E22: 5447295 | F22: OLABI LABOUR SOYA ACC
B23: 46127 | C23: REMISE POUR MITC | D23: 105000000 | E23: 5447296 | F23: Depot pour MITC
C24: CANCELED | E24: 5447297 | F24: CANCELED
B25: 46129 | C25: ETS DOS ESPOIR ET FILS | D25: 396158 | E25: 5447298 | F25: LABOUR WORK
C26: CANCELED | E26: 5447299 | F26: CANCELED
B27: 46139 | C27: AJEYA BABU NARALASETTI | D27: 250000 | E27: 5447300 | F27: HOUSE RENT OF AJEYA BABU
B28: 46170 | C28: UD CAKE LABOUR WORK | D28: 226972 | E28: 5822101 | F28: LABOUR WORK
B29: 46147 | C29: TRANS SOHA | D29: 6000000 | E29: 5822102 | F29: EXPORT ACC
B30: 46147 | D30: 25000000 | E30: 5822103 | F30: RETRAIT POUR NAP
B31: 46149 | C31: REMISE POUR MITC | D31: 120000000 | E31: 5822104 | F31: Depot pour MITC
C32: CANCELED | E32: 5822105 | F32: CANCELED
C33: OLABI LABOUR WORK | D33: 1875495 | E33: 5822106
B34: 46163 | C34: CHABI BORO HALISSOU | D34: 14481500 | E34: 5822107 | F34: PURCHASE OF SOYA
B35: 46163 | C35: AFFO MOUSSA IBRAHIM | D35: 20000000 | E35: 5822108 | F35: PURCHASE OF SOYA
B36: 46163 | C36: HOUEDANOU JUSTIN | D36: 14005640 | E36: 5822109 | F36: PURCHASE OF SOYA
B37: 46164 | C37: TRANS SOHA | D37: 7000000 | E37: 5822110 | F37: EXPORT ACC
B38: 46164 | C38: TCHANIGA SAMSON | D38: 11144000 | E38: 5822111 | F38: PURCHASE OF SOYA
C39: CANCELED | E39: 5822112 | F39: CANCELED
B40: 46164 | C40: CASIMIR | D40: 27176800 | E40: 5822113 | F40: PURCHASE OF SOYA
B41: 46164 | C41: LEONARD | D41: 12921440 | E41: 5822114 | F41: PURCHASE OF SOYA
B42: 46170 | C42: REMISE POUR MITC | D42: 120000000 | E42: 5822115 | F42: Depot pour MITC

Sheet CHEQUE GIVEB ON COMPANYS NAME,
B2: BON BERGER | G2: SUPER SONIC | L2: HELIOS SECURITY | Q2: OLABI
A3: DATE | B3: AMT | C3: CH NO | D3: REASON | F3: DATE | G3: AMT | H3: CH NO | I3: REASON | K3: DATE | L3: AMT | M3: CH NO | N3: REASON | P3: DATE | Q3: AMT | R3: CH NO | S3: REASON | V3: ETS WYM DJIBRIL ALBARKA
A4: 46115 | B4: 2384300 | C4: 5447278 | D4: COTTON SEED TRANSPORT | F4: 46119 | G4: 428400 | H4: 5447283 | I4: DRUM HYDRAULIC PURCHASE | K4: 46126 | L4: 349200 | M4: 5447292 | N4: SECURITY GDIZ | P4: 46128 | Q4: 501917 | R4: 5447294 | S4: OLABI LABOUR WORK COTTON SEED | U4: DATE | V4: AMT | W4: CH NO | X4: REASON
P5: 46128 | Q5: 1000000 | R5: 5447295 | S5: OLABI LABOUR SOYA ACC | U5: 46120 | V5: 302931 | W5: 5447284 | X5: UD CAKE LABOUR
P6: 46038 | Q6: 774522 | R6: 5447242 | S6: OLABI LABOUR (COTTON-UD CAKE-SHEA NUT)
P7: 46055 | Q7: 3000000 | R7: 5447252 | S7: OLABI LABOUR SOYA ACC
P8: 46055 | Q8: 2630430 | R8: 5447251 | S8: OLABI LABOUR COTTON- UD CAKE- SHEA
P9: 46062 | Q9: 2960667 | R9: 5447255 | S9: OLABI LABOUR COTTON- UD CAKE- SHEA
P10: 46112 | Q10: 2000000 | R10: 5447272 | S10: OLABI LABOUR SOYA ACC
P11: 46112 | Q11: 788678 | R11: 5447271 | S11: OLABI LABOUR COTTON- UD CAKE- SHEA
P12: 46164 | Q12: 1875495 | R12: 5822106 | S12: OLABI LABOUR WORK COTTON SEED
B16: ETS DOS ESPOIR | G16: CERCLE DE DIEU | L16: ACE GLOBAL | Q16: STE UNITED TRADEX SARL
A17: DATE | B17: AMT | C17: CH NO | D17: REASON | F17: DATE | G17: AMT | H17: CH NO | I17: REASON | K17: DATE | L17: AMT | M17: CH NO | N17: REASON | P17: DATE | Q17: AMT | R17: CH NO | S17: REASON
A18: 46045 | B18: 2000000 | C18: 5447243 | D18: LABOUR WORK | F18: 46045 | G18: 3000000 | H18: 5447245 | I18: COTTON SEED TRANSPORT | K18: 46056 | L18: 2134000 | M18: 5447250 | P18: 46056 | Q18: 1070000 | R18: 5447248 | S18: ACHAT DE MOTO
A19: 46049 | B19: 1000000 | C19: 5447246 | D19: LABOUR WORK | F19: 46051 | G19: 9000000 | H19: 5447249 | I19: COTTON SEED TRANSPORT
A20: 46057 | B20: 594760 | C20: 5447253 | D20: LABOUR WORK | F20: 46093 | G20: 7500000 | H20: 5447260 | I20: COTTON SEED TRANSPORT
A21: 46112 | B21: 385371 | C21: 5447275 | D21: LABOUR WORK | F21: 46112 | G21: 10000000 | H21: 5447281 | I21: COTTON SEED TRANSPORT/ AVANCE TRANSPORT NIKKI
A22: 46129 | B22: 396158 | C22: 5447298 | D22: LABOUR WORK | F22: 46112 | G22: 4496460 | H22: 5447282 | I22: COTTON SEED TRANSPORT / SOLD ANCIEN COMPTE

Sheet UD CAKE
C3: SAMBA | H3: MENANYI NICOLAS | M3: DANIEL | R3: BANTHAL | W3: KA AZIZ
B4: DATE | C4: AMT | D4: CH NO | E4: REASON | G4: DATE | H4: AMT | I4: CH NO | J4: REASON | L4: DATE | M4: AMT | N4: CH NO | O4: REASON | Q4: DATE | R4: AMT | S4: CH NO | T4: REASON | V4: DATE | W4: AMT | X4: CH NO | Y4: REASON
B5: 46034 | C5: 5500000 | D5: VERSEMENT | E5: UD CAKE SALES | G5: 46107 | H5: 32000000 | I5: VERSEMENT | J5: UD CAKE SALES | L5: 46125 | M5: 87000000 | N5: VERSEMENT | O5: UD CAKE SALES | Q5: 46127 | R5: 51840000 | S5: VERSEMENT | T5: UD CAKE SALES | V5: 46133 | W5: 46080000 | X5: VERSEMENT | Y5: UD CAKE SALES
B6: 46038 | C6: 14500000 | D6: VERSEMENT | E6: UD CAKE SALES_100MT_160K/MT | G6: 46141 | H6: 41250000 | I6: VERSEMENT | J6: UD CAKE SALES
B7: 46038 | C7: 1500000 | D7: VERSEMENT
B8: 46043 | C8: 14500000 | D8: VERSEMENT | E8: UD CAKE SALES
B9: 46045 | C9: 14500000 | D9: VERSEMENT | E9: UD CAKE SALES
B10: 46051 | C10: 21750000 | D10: VERSEMENT | E10: UD CAKE SALES
B11: 46051 | C11: 14500000 | D11: VERSEMENT | E11: UD CAKE SALES
B12: 46058 | C12: 23000000 | D12: VERSEMENT | E12: UD CAKE SALES
B13: 46078 | C13: 20000000 | D13: VERSEMENT | E13: UD CAKE SALES
B14: 46079 | C14: 32000000 | D14: VERSEMENT | E14: UD CAKE SALES
B15: 46091 | C15: 4000000 | D15: VERSEMENT | E15: UD CAKE SALES
B16: 46122 | C16: 16000000 | D16: VERSEMENT | E16: UD CAKE SALES
B17: 46126 | C17: 16000000 | D17: VERSEMENT | E17: UD CAKE SALES
