Workbook

Sheet FICHE (2)
E4: STE NAP SARL
D7: PLOT NO 14 GLODJIGBE ECONIMIC ZONEREPUBLIC OF BENIN RCCM RB / COT / 21 B 30710, IFU 3202113334014 TEL: +229 0194940414, 0197974506
F11: Bon de paiement
D13: Date | E13: 46177 | G13: Prestataires/Fournisseurs | H13: HOUNKONSI FLORENT
D14: No de transaction | E14: CC0004-2026
D15: Type d'operation | E15: SERVICE | G15: Nom du bénéficiaire | H15: HOUNKONSI FLORENT
D16: Produit | E16: ENTRETIEN | G16: Num. Pieces d'identite | H16: 8505929556
G17: Date d'expiration | H17: 24/03/2031
G18: Addresse /Telephone | H18: 0196199915
D20: Details des operations
D21: Numero de facture | E21: Description/Objet du paiement | G21: Montant | H21: Observation
E22: NETTOYAGE BUREAU | G22: 20000 | H22: -
E23: NETTOYAGE TANK | G23: 3000 | H23: -
F24: Montant Total | G24: =SUM(G22:G23) -> 23000
D26: Montant en lettre : | E26: Vingt trois mille francs CFA
G29: Mode paiement | H29: ESPECES
G30: Numero de cheque | H30: -
G31: Banque | H31: CAISSE
D33: Manager logistics | F33: Comptablité | H33: Bénéficiaire
D37: visa | F37: visa | H37: visa
D38: NB: Toute remise de chèque doit être confirmée par signature du bénéficiaire et accompagnée d’une copie du chèque et pièce pour fins de traçabilité.

Sheet Mvt Caisse
D3: STE NAP SARL
D6: PLOT NO 14 GLODJIGBE ECONIMIC ZONEREPUBLIC OF BENIN RCCM RB / COT / 21 B 30710, IFU 3202113334014 TEL: +229 0194940414, 0197974506
E10: MOUVEMENT DE CAISSE
C13: DATE | D13: LIBELLE | E13: MOTIF | F13: DEBIT | G13: CREDIT | H13: SOLDE
D14: SOLDE INITIAL

Sheet DEPENSES
B3: Date | C3: No de transaction | D3: Type d'operation | E3: Produit | F3: Prestataires/Fournisseurs | G3: Nom du bénéficiaire | H3: Num. Pieces d'identite | I3: Date d'expiration | J3: Addresse /Telephone | K3: Ref doc | L3: Description/Objet du paiement | M3: Montant | N3: Observation | O3: Montant en lettre | P3: Mode paiement | Q3: Numero de cheque | R3: Banque
B4: 46175 | C4: CC-0001-2026 | D4: EXPORT | E4: FRET EXPORT | F4: ALFRED | G4: SOGLO MARTIAL | H4: 7506116519 | I4: 48001 | J4: 0197601003 | K4: BJCOOA260021857/ EBKG15552571 _MEDUCT182978 | L4: ACHAT BL-MANIPULATION-FRAIS SEGUB-TIMBRE-ACHAT PLOMB | M4: 49658 | N4: PAYE | O4: Quarante neuf mille six cent ciquante huit francs CFA | P4: ESPECES | Q4: - | R4: CAISSE
B5: 46175 | C5: CC-0001-2026 | D5: EXPORT | E5: FRET EXPORT | F5: ALFRED | G5: SOGLO MARTIAL | H5: 7506116519 | I5: 48001 | J5: 0197601003 | K5: BJCOOPX260001101/ EBKG15552571 _MEDUCT182978 | L5: INTERNATIONAL SHIPS AND PORT SECURITY (ISPS) | M5: 41300 | N5: PAYE | O5: Quarante un mille trois cents francs CFA | P5: ESPECES | Q5: - | R5: CAISSE
B6: 46175 | C6: CC-0001-2026 | D6: EXPORT | E6: FRET EXPORT | F6: ALFRED | G6: SOGLO MARTIAL | H6: 7506116519 | I6: 48001 | J6: 0197601003 | K6: BJCOOA260025613/ EBKG15552571 _MEDUCT182978 | L6: FRAIS DE RETARD BL | M6: 29500 | N6: PAYE | O6: Vingt neuf mille cinq cent franc CFA | P6: ESPECES | R6: CAISSE
B7: 46175 | C7: CC-0001-2026 | D7: EXPORT | E7: FRET EXPORT | F7: ALFRED | G7: SOGLO MARTIAL | H7: 7506116519 | I7: 48001 | J7: 0197601003 | K7: BJCOOA260030030/ EBKG15552571 _MEDUCT182978 | L7: LETTRE DE GARANTIE | M7: 17966 | N7: PAYE | O7: Dix sept mille soixante six francs CFA | P7: ESPECES | R7: CAISSE
B8: 46175 | C8: CC-0001-2026 | D8: EXPORT | E8: FRET EXPORT | F8: ALFRED | G8: SOGLO MARTIAL | H8: 7506116519 | I8: 48001 | J8: 0197601003 | K8: BJCOOA260030014/ EBKG15552571 _MEDUCT182978 | L8: COMMISION EXP CHARGES FOR EQUIPMENT | M8: 189768 | N8: PAYE | O8: Qatre vingt seize six cent quatre vingt deux francs CFA | P8: ESPECES | R8: CAISSE
B9: 46175 | C9: CC-0001-2026 | D9: EXPORT | E9: FRET EXPORT | F9: ALFRED | G9: SOGLO MARTIAL | H9: 7506116519 | I9: 48001 | J9: 0197601003 | K9: BJCOOA260030252/ EBKG15552571 _MEDUCT182978 | L9: FRAIS DE RETARD BL | M9: 70800 | N9: PAYE | O9: Soixante mille francs CFA | P9: ESPECES | R9: CAISSE
B10: 46175 | C10: CC-0001-2026 | D10: EXPORT | E10: FRET EXPORT | F10: ALFRED | G10: SOGLO MARTIAL | H10: 7506116519 | I10: 48001 | J10: 0197601003 | K10: BJCOOP260009286/ EBKG15552571 _MEDUCT182978 | L10: COMMISSION EXP CHARGES FOR EQUIPMENT | M10: 6325772 | N10: PAYE | O10: Six millions trois cent vingt cinq mille sept cent soixante douze francs CFA | P10: ESPECES | R10: CAISSE
B11: 46175 | C11: CC-0002-2026 | D11: PURCHASE | E11: SOYABEAN | F11: HOUEDANOU ENAGNON JUSTIN | G11: HOUEDANOU ENAGNON JUSTIN | H11: 2546545404 | I11: 28/2/2031 | J11: 0197684561 | K11: WEIGHMENT TICKET ATRAL : 6615 _ 39380 KG | L11: PURCHASE OF SOYABEAN | M11: 2000000 | N11: AVANCE | O11: Deux millions francs CFA | P11: ESPECES | R11: CAISSE
B12: 46175 | C12: CC-0003-2026 | D12: SERVICE | E12: TRANSFERT DHL | F12: DHL | G12: DHL | H12: - | I12: - | J12: benincustomerservice@dhl.com | K12: WAYBILL : 7171660414 | L12: TRANSFERT DE DOCUMENT PAR DHL (COO_267756955) | M12: 63902 | N12: PAYE | O12: Soixante trois mille neuf cents deux francs CFA | P12: MOBILE MONEY | Q12: - | R12: CAISSE
B13: 46177 | C13: CC0004-2026 | D13: SERVICE | E13: ENTRETIEN | F13: HOUNKONSI FLORENT | G13: HOUNKONSI FLORENT | H13: 8505929556 | I13: 24/03/2031 | J13: 0196199915 | L13: NETOYAGE BUREAU | M13: 20000 | N13: PAYE | O13: Vingt mille franc CFA | P13: ESPECES | R13: CAISSE
B14: 46177 | C14: CC0004-2026 | D14: SERVICE | E14: ENTRETIEN | F14: HOUNKONSI FLORENT | G14: HOUNKONSI FLORENT | H14: 8505929556 | I14: 24/03/2031 | J14: 0196199915 | L14: NETOYAGE TANK | M14: 3000 | N14: PAYE | O14: Trois mille franc CFA | P14: ESPECES | R14: CAISSE
B15: 46183 | C15: CC-0005-2026 | D15: EXPORT | E15: SERVICE TRANSIT | F15: TRANS SOHA | G15: TRANS SOHA | H15: - | I15: - | J15: - | K15: Facture Administrative 265000443 | L15: FACTURE POUR RETOUR VIDE DE 01 TC DE 20' TLLU2296161(22G1)//BOOKING 271486702 | M15: 46879 | N15: PAYE | O15: Qarante sux huit cents soixante dix neuf | P15: ESPECES | Q15: - | R15: CAISSE
B16: 46183 | C16: CC-0006-2026 | D16: SERVICE | E16: SALARY | F16: EMPLOYE USINE | G16: ADIGNON SYLVAIN | H16: 8188560503 | I16: 48094 | J16: 01 95 55 78 89 | K16: - | L16: SALARY AND LOCAL ALLOWANCE MAY 2026 | M16: 7592333 | N16: PAYE | O16: Sept millions neuf cents quatre vingt douze mille trois cents trente mille francs CFA | P16: ESPECES | Q16: - | R16: CAISSE
B17: 46189 | C17: CC-0007-2026 | D17: SERVICE | E17: SALARY | F17: HOUNVLESSI HOSPICE | G17: HOUNVLESSI HOSPICE | H17: 21PP35301 | I17: 21/11/2027 | L17: SALARY MAY 2026 | M17: 250000 | N17: PAYE | O17: Deux cent cinquante mille francs CFA | P17: ESPECES | R17: CAISSE
B18: 46195 | C18: CC-0008-2026 | D18: SERVICE | E18: TRANSFERT DHL | F18: DHL | G18: DHL | H18: - | I18: - | J18: benincustomerservice@dhl.com | K18: WAYBILL : 2489910581 | L18: TRANSFERT DE DOCUMENT PAR DHL | M18: 63902 | N18: PAYE | O18: Soixante trois mille neuf cents deux francs CFA | P18: MOBILE MONEY | Q18: - | R18: CAISSE
B19: 46197 | C19: CC-0009-2026 | D19: SERVICE | E19: TRANSFERT DHL | F19: DHL | G19: DHL | H19: - | I19: - | J19: benincustomerservice@dhl.com | K19: WAYBILL : 9550147524/9250148891/9250152796 | L19: TRANSFERT DE DOCUMENT PAR DHL | M19: 191706 | N19: PAYE | O19: Cent quatre vingt onze mille sept cent six francs CFA | P19: MOBILE MONEY | Q19: - | R19: CAISSE
B20: 46197 | C20: CC-0010-2026 | D20: EXPORT | E20: COQ/COW | F20: GLOHI GEOFRANE | G20: GLOHI GEOFRANE | H20: - | I20: - | J20: - | K20: - | L20: ETABLISSEMENT DE COQ & COW | M20: 500000 | N20: PAYE | O20: Cinq cent dix mille francs CFA | P20: ESPECES | Q20: - | R20: CAISSE
B21: 46198 | C21: CC-0011-2026 | D21: EXPORT | E21: COQ/COW | F21: GLOHI GEOFRANE | G21: GLOHI GEOFRANE | H21: - | I21: - | J21: - | K21: - | L21: ETABLISSEMENT DE COQ & COW | M21: 200000 | N21: PAYE | O21: Deux cent mille francs CFA | P21: ESPECES | Q21: - | R21: CAISSE
B22: 46198 | C22: CC-0012-2026 | D22: SERVICE | E22: SERVICE | F22: STE DE PAPETERIE MODERNE | G22: STE DE PAPETERIE MODERNE | H22: - | I22: - | J22: - | K22: - | L22: ACHAT DE FOURNITURE BUREAU | M22: 3227 | N22: PAYE | O22: Trois mille deux cent vingt sept francs CFA | P22: ESPECES | Q22: - | R22: CAISSE
B23: 46198 | C23: CC-0013-2026 | D23: SERVICE | E23: SERVICE | F23: MARILOG AFRICA | G23: MARILOG AFRICA | H23: - | I23: - | J23: - | K23: - | L23: VERIFICATION DE STOCK USINE DE GDIZ & SITE DE SEKOU | M23: 1500000 | N23: PAYE | O23: Un million cinq cent mille francs CFA | P23: VIREMENT | Q23: - | R23: ECOBANK BENIN
B24: 46198 | C24: CC-0014-2026 | D24: SERVICE | E24: SERVICE | F24: LA GRACE DE DIEU | G24: LA GRACE DE DIEU | H24: - | I24: - | J24: - | K24: - | L24: ESSENCE | M24: 20000 | N24: PAYE | O24: Vingt mille franc CFA | P24: ESPECES | Q24: - | R24: CAISSE
B25: 46198 | C25: CC-0015-2026 | D25: SERVICE | E25: SERVICE | F25: CERCLE DE DIEU | G25: CERCLE DE DIEU | H25: - | I25: - | J25: - | K25: - | L25: LABOUR WORK SOYA ACC | M25: 192904 | N25: PAYE | O25: Cent quatre vingt douze mille neuf cent quatre francs CFA | P25: ESPECES | Q25: - | R25: CAISSE
B26: 46175 | C26: CC-0016-2026 | D26: SERVICE | E26: TRANSFERT DHL | F26: DHL | G26: DHL | H26: - | I26: - | J26: benincustomerservice@dhl.com | K26: WAYBILL : 7018927156 | L26: TRANSFERT DE DOCUMENT PAR DHL | M26: 63902 | N26: PAYE | O26: Soixante trois mille neuf cents deux francs CFA | P26: MOBILE MONEY | Q26: - | R26: CAISSE
B27: 46200 | C27: CC-0017-2026 | D27: SERVICE | E27: TRANSFERT DHL | F27: DHL | G27: DHL | H27: - | I27: - | J27: benincustomerservice@dhl.com | K27: WAYBILL : 1790527410 | L27: TRANSFERT DE DOCUMENT PAR DHL | M27: 127804 | N27: PAYE | O27: Cent vingt sept mille huit cent quatre francs CFA | P27: MOBILE MONEY | Q27: - | R27: CAISSE
B28: 46199 | C28: CC-0018-2026 | D28: EXPORT | E28: TELEX | F28: MAERSK | G28: MAERSK | H28: - | I28: - | J28: - | K28: - | L28: REQUEST OF TELEX BL269555573 | M28: 20491 | N28: PAYE | O28: Vingt mille quatre cent quatre vingt onze francs CFA | P28: ESPECES | Q28: - | R28: CAISSE
B29: 46199 | C29: CC-0019-2026 | D29: SERVICE | E29: SERVICE | F29: VIGAN JUSTIN | G29: VIGAN JUSTIN | H29: - | I29: - | J29: - | K29: - | L29: LABOUR WORK SOYA ACC | M29: 190162 | N29: PAYE | O29: Cent quatre vingt dix mille cent soixante deux francs CFA | P29: ESPECES | Q29: - | R29: CAISSE
... B32: 46212 | C32: CC-0022-2026 | D32: SERVICE | E32: TRANSFERT DHL | F32: DHL | G32: DHL | H32: - | I32: - | J32: benincustomerservice@dhl.com | K32: WAYBILL : 6192239734 | L32: TRANSFERT DE DOCUMENT PAR DHL | M32: 63902 | N32: PAYE | O32: Soixante trois mille neuf cents deux francs CFA | P32: MOBILE MONEY | Q32: - | R32: CAISSE
B33: 46221 | C33: CC-0023-2026 | D33: SERVICE | E33: SERVICE | F33: JUSTIN VIGAN | G33: JUSTIN VIGAN | H33: 20921662429826 | I33: 47997 | J33: 8924266129 | K33: No 058/PS-26 | L33: LABOUR WORK SOYA ACC | M33: 107939 | N33: PAYE | O33: Cent sept mille neuf cent trente neuf francs CFA | P33: ESPECES | Q33: - | R33: CAISSE
B34: 46219 | C34: CC-0024-2026 | D34: SERVICE | E34: TRANSFERT DHL | F34: DHL | G34: DHL | H34: - | I34: - | J34: benincustomerservice@dhl.com | K34: WAYBILL : 6192239734 | L34: TRANSFERT DE DOCUMENT PAR DHL | M34: 63902 | N34: PAYE | O34: Soixante trois mille neuf cents deux francs CFA | P34: MOBILE MONEY | Q34: - | R34: CAISSE
B35: 46216 | C35: CC-0025-2026 | D35: SERVICE | E35: SERVICE | F35: STE PAPETERIE MODERNE SARL | G35: STE PAPETERIE MODERNE SARL | H35: - | I35: - | J35: - | K35: FACTURE 13195 | L35: ACHAT DE FOURNITURE BUREAU | M35: 41448 | N35: PAYE | O35: Quarante un mille quatre cent quarante huit francs CFA | P35: ESPECES | Q35: - | R35: CAISSE
B36: 46216 | C36: CC-0026-2026 | D36: SERVICE | E36: SERVICE | F36: CBP | G36: CBP | H36: - | I36: - | J36: - | K36: FACTURE 35059-2026 | L36: ACHAT DE FOURNITURE BUREAU | M36: 11850 | N36: PAYE | O36: Onze mille huit cent cinquante francs CFA | P36: ESPECES | Q36: - | R36: CAISSE
B37: 46216 | C37: CC-0027-2026 | D37: SERVICE | E37: SERVICE | F37: SONAEC | G37: SONAEC | H37: - | I37: - | J37: - | K37: FACTURE CC246704 | L37: ACHAT DE FOURNITURE BUREAU | M37: 48300 | N37: PAYE | O37: Quarante huit mille trois cent francs CFA | P37: ESPECES | Q37: - | R37: CAISSE
B38: 46200 | C38: CC-0028-2026 | D38: SERVICE | E38: SERVICE | F38: IDRISSOU APHISSOU | G38: IDRISSOU APHISSOU | H38: 5924678990 | I38: 30/8/2027 | J38: 0196109481 | K38: - | L38: LABOUR WORK SOYA ACC | M38: 1500000 | N38: AVANCE | O38: Un million cinq cent mille francs CFA | P38: ESPECES | Q38: - | R38: CAISSE
B39: 46216 | C39: CC-0029-2026 | D39: SERVICE | E39: SERVICE | F39: SBEE | G39: SBEE | H39: - | I39: - | J39: - | K39: REF 2559224 | L39: PAIEMENT FACTURE D'ELECTRICITE SBEE/ ZE PLAQUE | M39: 20200 | N39: PAYE | O39: Vingt mille deux cents francs CFA | P39: ESPECES | Q39: - | R39: CAISSE
B40: 46220 | C40: CC-0030-2026 | D40: SERVICE | E40: SALARY | F40: EMPLOYE USINE | G40: ADIGNON SYLVAIN | H40: 8188560503 | I40: 48094 | J40: 01 95 55 78 89 | K40: - | L40: SALARY AND LOCAL ALLOWANCE JUIN 2026 | M40: 2930000 | N40: PAYE | O40: Deux millions neuf cent trente mille francs CFA | P40: ESPECES | Q40: - | R40: CAISSE
B41: 46218 | C41: CC-0031-2026 | D41: SERVICE | E41: SERVICE | F41: MARILOG AFRICA | G41: MARILOG AFRICA | H41: - | I41: - | J41: - | K41: 270-FACT | L41: VERIFICATION DE STOCK USINE DE GDIZ & SITE DE SEKOU | M41: 1500000 | N41: PAYE | O41: Un million cinq cent mille francs CFA | P41: VIREMENT | Q41: - | R41: ECOBANK BENIN
B42: 46221 | C42: CC-0032-2026 | D42: SERVICE | E42: SERVICE | F42: STE PAPETERIE MODERNE SARL | G42: STE PAPETERIE MODERNE SARL | H42: - | I42: - | J42: - | K42: - | L42: ACHAT DE FOURNITURE BUREAU | M42: 3026 | N42: PAYE | O42: Trois mille vingt six francs CFA | P42: ESPECES | Q42: - | R42: CAISSE
B43: 46227 | C43: CC-0033-2026 | D43: SERVICE | E43: SERVICE | F43: SBEE | G43: SBEE | H43: - | I43: - | J43: - | K43: REF 2627531 | L43: PAIEMENT FACTURE D'ELECTRICITE SBEE/ AJAY BABU | M43: 50000 | N43: PAYE | O43: Cinquante mille francs CFA | P43: MOBILE MONEY | Q43: - | R43: CAISSE
B44: 46227 | C44: CC-0034-2026 | D44: SERVICE | E44: SERVICE | F44: SBEE | G44: SBEE | H44: - | I44: - | J44: - | K44: REF aaec52a885 | L44: PAIEMENT FACTURE D'ELECTRICITE SBEE/ MAISON GLO | M44: 100000 | N44: PAYE | O44: Cent mille francs CFA | P44: MOBILE MONEY | Q44: - | R44: CAISSE
...

Sheet FICHE
D3: `
E4: STE NAP SARL
D7: PLOT NO 14 GLODJIGBE ECONIMIC ZONEREPUBLIC OF BENIN RCCM RB / COT / 21 B 30710, IFU 3202113334014 TEL: +229 0194940414, 0197974506
F11: Bon de paiement
D13: Date | E13: =_xlfn.XLOOKUP($E$14,DEPENSES!C:C,DEPENSES!B:B) -> 46311 | G13: Prestataires/Fournisseurs | H13: =_xlfn.XLOOKUP($E$14,DEPENSES!C:C,DEPENSES!F:F) -> AHEGNI CASIMIR
D14: No de transaction | E14: CHQ-0391-2026
D15: Type d'operation | E15: =_xlfn.XLOOKUP($E$14,DEPENSES!C:C,DEPENSES!D:D) -> PURCHASE | G15: Nom du percepteur | H15: =_xlfn.XLOOKUP($E$14,DEPENSES!C:C,DEPENSES!G:G) -> AHEGNI HIPPOLYTE
D16: Produit | E16: =_xlfn.XLOOKUP($E$14,DEPENSES!C:C,DEPENSES!E:E) -> SHEA | G16: Num. Pieces d'identite | H16: =_xlfn.XLOOKUP($E$14,DEPENSES!C:C,DEPENSES!H:H) -> 20411113178625
G17: Date d'expiration | H17: =_xlfn.XLOOKUP($E$14,DEPENSES!C:C,DEPENSES!I:I) -> 46585
G18: Addresse /Telephone | H18: =_xlfn.XLOOKUP($E$14,DEPENSES!C:C,DEPENSES!J:J) -> 0196034539
D20: Details des operations
D21: Ref Doc | E21: Description/Objet du paiement | G21: Montant | H21: Observation
D22: =_xlfn.XLOOKUP($E$14,DEPENSES!C:C,DEPENSES!K:K) -> CB6370RB/BY4656RB_50.0 MT & CA5858RB/AC1719RB_45.46 MT | E22: =_xlfn.XLOOKUP($E$14,DEPENSES!C:C,DEPENSES!L:L) -> PURCHASE OF SHEA | G22: =_xlfn.XLOOKUP($E$14,DEPENSES!C:C,DEPENSES!M:M) -> 29611200 | H22: =_xlfn.XLOOKUP($E$14,DEPENSES!C:C,DEPENSES!N:N) -> PAYE
F24: Montant Total | G24: =SUM(G22:G23) -> 29611200
D26: Montant en lettre : | F26: =_xlfn.XLOOKUP($E$14,DEPENSES!C:C,DEPENSES!O:O) -> Vingt neuf millions Six cent onze mille Deux cent francs CFA
G29: Mode paiement | H29: =_xlfn.XLOOKUP($E$14,DEPENSES!C:C,DEPENSES!P:P) -> CHEQUE
G30: Numero de cheque | H30: =_xlfn.XLOOKUP($E$14,DEPENSES!C:C,DEPENSES!Q:Q) -> 2000755
G31: Banque | H31: =_xlfn.XLOOKUP($E$14,DEPENSES!C:C,DEPENSES!R:R) -> ECOBANK BENIN
D33: Manager logistics | F33: Comptablité | H33: Bénéficiaire
D37: visa | F37: visa | H37: visa
D38: NB: Toute remise de chèque doit être confirmée par signature du bénéficiaire et accompagnée d’une copie du chèque et pièce pour fins de traçabilité.

Sheet VERSEMENTS
C2: SUIVI DES VERSEMENTS
C3: DATE | D3: DOC REF | E3: NOM DU DEPOSANT | F3: MOTIF DE VERSEMENT | G3: MONTANT | H3: BANQUE
C4: 46174 | D4: M33CHDP261520548 | E4: GARBA IBRAHIM | F4: RECETTE | G4: 16000000 | H4: ECOBANK BENIN
C5: 46176 | D5: BD0410563 | E5: SHARMA RISHI | F5: RECETTE | G5: 700000 | H5: ATLANTIC BANK BENIN
C6: 46177 | E6: PAN TRADING | G6: 75477008 | H6: ECOBANK BENIN
C7: 46181 | D7: INVOICE NAP-1033-2026 AND NAP-1043-2026 | E7: PAN TRADING | G7: 70229590 | H7: ECOBANK BENIN
C8: 46182 | E8: VERSEMENT D'ESPECE PAR MITC | G8: 12000000 | H8: ECOBANK BENIN
C9: 46182 | E9: VERSEMENT D'ESPECE PAR MITC | G9: 13000000 | H9: ECOBANK BENIN
C10: 46183 | D10: INVOICE NAP-1038-2026A | E10: MAHARASHTRA SOLVENT EXTRACTION-EXPORT | G10: 6129482 | H10: ECOBANK BENIN
C11: 46183 | D11: M33CHDP261660033 | E11: AFFO MOUSSA IBRAHIM | F11: RECETTE | G11: 16000000 | H11: ECOBANK BENIN
C12: 46177 | D12: 4839552 | E12: BENIN COTON | G12: 54916680 | H12: BIIC
C13: 46186 | D13: 30601 | E13: AFFO MOUSSA IBRAHIM | F13: RECETTE | G13: 999900 | H13: BIIC
C14: 46182 | D14: 30499 | E14: AFFO MOUSSA IBRAHIM | F14: RECETTE | G14: 8000000 | H14: BIIC
C15: 46195 | D15: M33CHDP261730035 | E15: AFFO MOUSSA IBRAHIM | F15: RECETTE | G15: 8000000 | H15: ECOBANK BENIN
C16: 46195 | D16: M33CHDP261730036 | E16: AFFO MOUSSA IBRAHIM | F16: RECETTE | G16: 16000000 | H16: ECOBANK BENIN
C17: 46195 | D17: M33CHDP261730530 | E17: GARBA IBRAHIM | F17: RECETTE | G17: 16000000 | H17: ECOBANK BENIN
C18: 46195 | D18: M33CHDP261730531 | E18: GARBA IBRAHIM | F18: RECETTE | G18: 10000000 | H18: ECOBANK BENIN
C22: 46206 | D22: INVOICE NAP-1080-2026 | E22: SANJAY SOYA PRIVATE LIMITED | G22: 80960262 | H22: ATLANTIC BANK BENIN
C23: 46206 | D23: INVOICE NAP-1083-2026 | E23: SANJAY SOYA PRIVATE LIMITED | G23: 77936295 | H23: ATLANTIC BANK BENIN
C24: 46209 | D24: M33CHDP261870033 | E24: SHARMA RISHI | F24: RECETTE | G24: 2000000 | H24: ECOBANK BENIN
