Workbook
Name L_Beneficiaires: OFFSET(Listes!$A$2,0,0,MAX(1,COUNTA(Listes!$A$2:$A$100)),1)
Name L_Comptes: OFFSET(Listes!$E$2,0,0,MAX(1,COUNTA(Listes!$E$2:$E$100)),1)
Name L_Domaines: OFFSET(Listes!$C$2,0,0,MAX(1,COUNTA(Listes!$C$2:$C$100)),1)
Name L_Fournisseurs: OFFSET(Fournisseurs!#REF!,0,0,MAX(1,COUNTA(Fournisseurs!$B$6:$B$103)),1)
Name L_Modes: OFFSET(Listes!$D$2,0,0,MAX(1,COUNTA(Listes!$D$2:$D$100)),1)
Name L_Produits: OFFSET(Listes!$G$2,0,0,MAX(1,COUNTA(Listes!$G$2:$G$100)),1)
Name L_Statuts: OFFSET(Listes!$F$2,0,0,MAX(1,COUNTA(Listes!$F$2:$F$100)),1)
Name L_StatutsDech: OFFSET(Listes!$H$2,0,0,MAX(1,COUNTA(Listes!$H$2:$H$100)),1)
Name L_Types: OFFSET(Listes!$B$2,0,0,MAX(1,COUNTA(Listes!$B$2:$B$100)),1)
Name P_Max: Listes!$K$3
Name P_Min: Listes!$K$2

Sheet Controle_Paiement
A1: Contrôle avant paiement d'un fournisseur
A2: À faire AVANT de valider un paiement fournisseur : choisissez le fournisseur et saisissez le montant que vous comptez payer (2 cellules jaunes). La feuille vérifie si les camions sont déchargés et dit si le paiement est couvert par les livraisons ou s'il s'agira d'une avance. Cette feuille ne modifie rien : le paiement s'enregistre ensuite dans Paiements.
A4: Fournisseur
A5: Montant à payer (FCFA)
A7: Ce que montrent les déchargements
A8: Camions déchargés (statut « Fait ») | B8: =IF($B$4="","",COUNTIFS(Dechargements!$C$5:$C$1002,$B$4,Dechargements!$H$5:$H$1002,"Fait"))
A9: Poids déchargé (kg) | B9: =IF($B$4="","",SUMIFS(Dechargements!$E$5:$E$1002,Dechargements!$C$5:$C$1002,$B$4,Dechargements!$H$5:$H$1002,"Fait"))
A10: Montant livré (camions déchargés) | B10: =IF($B$4="","",SUMIFS(Dechargements!$G$5:$G$1002,Dechargements!$C$5:$C$1002,$B$4,Dechargements!$H$5:$H$1002,"Fait"))
A11: Camions pas encore déchargés (en cours / non fait) | B11: =IF($B$4="","",COUNTIFS(Dechargements!$C$5:$C$1002,$B$4)-$B$8-COUNTIFS(Dechargements!$C$5:$C$1002,$B$4,Dechargements!$H$5:$H$1002,"Annulé"))
A12: Montant de ces camions (non payable tant que non déchargé) | B12: =IF($B$4="","",SUMIFS(Dechargements!$G$5:$G$1002,Dechargements!$C$5:$C$1002,$B$4)-$B$10-SUMIFS(Dechargements!$G$5:$G$1002,Dechargements!$C$5:$C$1002,$B$4,Dechargements!$H$5:$H$1002,"Annulé"))
A13: Déjà payé | B13: =IF($B$4="","",SUMIFS(Paiements!$I$5:$I$2000,Paiements!$C$5:$C$2000,$B$4,Paiements!$L$5:$L$2000,"Payé"))
A14: Paiements déjà enregistrés « En attente » | B14: =IF($B$4="","",SUMIFS(Paiements!$I$5:$I$2000,Paiements!$C$5:$C$2000,$B$4,Paiements!$L$5:$L$2000,"En attente"))
A15: Reste à payer sur les livraisons déchargées (après paiements en attente) | B15: =IF($B$4="","",MAX(0,$B$10-$B$13-$B$14))
A16: Avance déjà versée (pas encore couverte par des livraisons) | B16: =IF($B$4="","",MAX(0,$B$13-$B$10))
A17: Dépassement du paiement prévu (si positif = ce sera une avance) | B17: =IF(OR($B$4="",$B$5=""),"",$B$5-$B$15)
A19: Décision
A20: =IF($B$4="","Choisissez un fournisseur (cellule jaune).",IF(OR($B$5="",$B$5<=0),"Saisissez le montant à payer (cellule jaune).",IF($B$5<=$B$15,"AUTORISÉ : camions déchargés, le montant est couvert par les livraisons non payées.","ATTENTION : ce paiement dépasse les livraisons déchargées non payées"&IF($B$11>0," ("&$B$11&" camion(s) pas encore déchargé(s))","")&". Ce serait une AVANCE : validation du responsable nécessaire."))) -> Choisissez un fournisseur (cellule jaune).
A22: Camions de ce fournisseur pas encore payés (à vérifier)
A23: Date | B23: N° camion | C23: Poids (kg) | D23: Montant | E23: Déchargement | F23: Situation paiement
A24: =IF($H24="","",INDEX(Dechargements!$A$5:$A$1002,$H24)) | B24: =IF($H24="","",INDEX(Dechargements!$B$5:$B$1002,$H24)) | C24: =IF($H24="","",INDEX(Dechargements!$E$5:$E$1002,$H24)) | D24: =IF($H24="","",INDEX(Dechargements!$G$5:$G$1002,$H24)) | E24: =IF($H24="","",INDEX(Dechargements!$H$5:$H$1002,$H24)) | F24: =IF($H24="","",INDEX(Dechargements!$J$5:$J$1002,$H24)) | H24: =IF($B$4="","",IFERROR(MATCH(1,Dechargements!$L$5:$L$1002,0),""))
A25: =IF($H25="","",INDEX(Dechargements!$A$5:$A$1002,$H25)) | B25: =IF($H25="","",INDEX(Dechargements!$B$5:$B$1002,$H25)) | C25: =IF($H25="","",INDEX(Dechargements!$E$5:$E$1002,$H25)) | D25: =IF($H25="","",INDEX(Dechargements!$G$5:$G$1002,$H25)) | E25: =IF($H25="","",INDEX(Dechargements!$H$5:$H$1002,$H25)) | F25: =IF($H25="","",INDEX(Dechargements!$J$5:$J$1002,$H25)) | H25: =IF($H24="","",IFERROR($H24+MATCH(1,INDEX(Dechargements!$L$5:$L$1002,$H24+1):INDEX(Dechargements!$L$5:$L$1002,1000),0),""))
A26: =IF($H26="","",INDEX(Dechargements!$A$5:$A$1002,$H26)) | B26: =IF($H26="","",INDEX(Dechargements!$B$5:$B$1002,$H26)) | C26: =IF($H26="","",INDEX(Dechargements!$E$5:$E$1002,$H26)) | D26: =IF($H26="","",INDEX(Dechargements!$G$5:$G$1002,$H26)) | E26: =IF($H26="","",INDEX(Dechargements!$H$5:$H$1002,$H26)) | F26: =IF($H26="","",INDEX(Dechargements!$J$5:$J$1002,$H26)) | H26: =IF($H25="","",IFERROR($H25+MATCH(1,INDEX(Dechargements!$L$5:$L$1002,$H25+1):INDEX(Dechargements!$L$5:$L$1002,1000),0),""))
A27: =IF($H27="","",INDEX(Dechargements!$A$5:$A$1002,$H27)) | B27: =IF($H27="","",INDEX(Dechargements!$B$5:$B$1002,$H27)) | C27: =IF($H27="","",INDEX(Dechargements!$E$5:$E$1002,$H27)) | D27: =IF($H27="","",INDEX(Dechargements!$G$5:$G$1002,$H27)) | E27: =IF($H27="","",INDEX(Dechargements!$H$5:$H$1002,$H27)) | F27: =IF($H27="","",INDEX(Dechargements!$J$5:$J$1002,$H27)) | H27: =IF($H26="","",IFERROR($H26+MATCH(1,INDEX(Dechargements!$L$5:$L$1002,$H26+1):INDEX(Dechargements!$L$5:$L$1002,1000),0),""))
A28: =IF($H28="","",INDEX(Dechargements!$A$5:$A$1002,$H28)) | B28: =IF($H28="","",INDEX(Dechargements!$B$5:$B$1002,$H28)) | C28: =IF($H28="","",INDEX(Dechargements!$E$5:$E$1002,$H28)) | D28: =IF($H28="","",INDEX(Dechargements!$G$5:$G$1002,$H28)) | E28: =IF($H28="","",INDEX(Dechargements!$H$5:$H$1002,$H28)) | F28: =IF($H28="","",INDEX(Dechargements!$J$5:$J$1002,$H28)) | H28: =IF($H27="","",IFERROR($H27+MATCH(1,INDEX(Dechargements!$L$5:$L$1002,$H27+1):INDEX(Dechargements!$L$5:$L$1002,1000),0),""))
A29: =IF($H29="","",INDEX(Dechargements!$A$5:$A$1002,$H29)) | B29: =IF($H29="","",INDEX(Dechargements!$B$5:$B$1002,$H29)) | C29: =IF($H29="","",INDEX(Dechargements!$E$5:$E$1002,$H29)) | D29: =IF($H29="","",INDEX(Dechargements!$G$5:$G$1002,$H29)) | E29: =IF($H29="","",INDEX(Dechargements!$H$5:$H$1002,$H29)) | F29: =IF($H29="","",INDEX(Dechargements!$J$5:$J$1002,$H29)) | H29: =IF($H28="","",IFERROR($H28+MATCH(1,INDEX(Dechargements!$L$5:$L$1002,$H28+1):INDEX(Dechargements!$L$5:$L$1002,1000),0),""))
A30: =IF($H30="","",INDEX(Dechargements!$A$5:$A$1002,$H30)) | B30: =IF($H30="","",INDEX(Dechargements!$B$5:$B$1002,$H30)) | C30: =IF($H30="","",INDEX(Dechargements!$E$5:$E$1002,$H30)) | D30: =IF($H30="","",INDEX(Dechargements!$G$5:$G$1002,$H30)) | E30: =IF($H30="","",INDEX(Dechargements!$H$5:$H$1002,$H30)) | F30: =IF($H30="","",INDEX(Dechargements!$J$5:$J$1002,$H30)) | H30: =IF($H29="","",IFERROR($H29+MATCH(1,INDEX(Dechargements!$L$5:$L$1002,$H29+1):INDEX(Dechargements!$L$5:$L$1002,1000),0),""))
A31: =IF($H31="","",INDEX(Dechargements!$A$5:$A$1002,$H31)) | B31: =IF($H31="","",INDEX(Dechargements!$B$5:$B$1002,$H31)) | C31: =IF($H31="","",INDEX(Dechargements!$E$5:$E$1002,$H31)) | D31: =IF($H31="","",INDEX(Dechargements!$G$5:$G$1002,$H31)) | E31: =IF($H31="","",INDEX(Dechargements!$H$5:$H$1002,$H31)) | F31: =IF($H31="","",INDEX(Dechargements!$J$5:$J$1002,$H31)) | H31: =IF($H30="","",IFERROR($H30+MATCH(1,INDEX(Dechargements!$L$5:$L$1002,$H30+1):INDEX(Dechargements!$L$5:$L$1002,1000),0),""))
A32: =IF($H32="","",INDEX(Dechargements!$A$5:$A$1002,$H32)) | B32: =IF($H32="","",INDEX(Dechargements!$B$5:$B$1002,$H32)) | C32: =IF($H32="","",INDEX(Dechargements!$E$5:$E$1002,$H32)) | D32: =IF($H32="","",INDEX(Dechargements!$G$5:$G$1002,$H32)) | E32: =IF($H32="","",INDEX(Dechargements!$H$5:$H$1002,$H32)) | F32: =IF($H32="","",INDEX(Dechargements!$J$5:$J$1002,$H32)) | H32: =IF($H31="","",IFERROR($H31+MATCH(1,INDEX(Dechargements!$L$5:$L$1002,$H31+1):INDEX(Dechargements!$L$5:$L$1002,1000),0),""))
A33: =IF($H33="","",INDEX(Dechargements!$A$5:$A$1002,$H33)) | B33: =IF($H33="","",INDEX(Dechargements!$B$5:$B$1002,$H33)) | C33: =IF($H33="","",INDEX(Dechargements!$E$5:$E$1002,$H33)) | D33: =IF($H33="","",INDEX(Dechargements!$G$5:$G$1002,$H33)) | E33: =IF($H33="","",INDEX(Dechargements!$H$5:$H$1002,$H33)) | F33: =IF($H33="","",INDEX(Dechargements!$J$5:$J$1002,$H33)) | H33: =IF($H32="","",IFERROR($H32+MATCH(1,INDEX(Dechargements!$L$5:$L$1002,$H32+1):INDEX(Dechargements!$L$5:$L$1002,1000),0),""))
A34: =IF($H34="","",INDEX(Dechargements!$A$5:$A$1002,$H34)) | B34: =IF($H34="","",INDEX(Dechargements!$B$5:$B$1002,$H34)) | C34: =IF($H34="","",INDEX(Dechargements!$E$5:$E$1002,$H34)) | D34: =IF($H34="","",INDEX(Dechargements!$G$5:$G$1002,$H34)) | E34: =IF($H34="","",INDEX(Dechargements!$H$5:$H$1002,$H34)) | F34: =IF($H34="","",INDEX(Dechargements!$J$5:$J$1002,$H34)) | H34: =IF($H33="","",IFERROR($H33+MATCH(1,INDEX(Dechargements!$L$5:$L$1002,$H33+1):INDEX(Dechargements!$L$5:$L$1002,1000),0),""))
A35: =IF($H35="","",INDEX(Dechargements!$A$5:$A$1002,$H35)) | B35: =IF($H35="","",INDEX(Dechargements!$B$5:$B$1002,$H35)) | C35: =IF($H35="","",INDEX(Dechargements!$E$5:$E$1002,$H35)) | D35: =IF($H35="","",INDEX(Dechargements!$G$5:$G$1002,$H35)) | E35: =IF($H35="","",INDEX(Dechargements!$H$5:$H$1002,$H35)) | F35: =IF($H35="","",INDEX(Dechargements!$J$5:$J$1002,$H35)) | H35: =IF($H34="","",IFERROR($H34+MATCH(1,INDEX(Dechargements!$L$5:$L$1002,$H34+1):INDEX(Dechargements!$L$5:$L$1002,1000),0),""))
A36: =IF($H36="","",INDEX(Dechargements!$A$5:$A$1002,$H36)) | B36: =IF($H36="","",INDEX(Dechargements!$B$5:$B$1002,$H36)) | C36: =IF($H36="","",INDEX(Dechargements!$E$5:$E$1002,$H36)) | D36: =IF($H36="","",INDEX(Dechargements!$G$5:$G$1002,$H36)) | E36: =IF($H36="","",INDEX(Dechargements!$H$5:$H$1002,$H36)) | F36: =IF($H36="","",INDEX(Dechargements!$J$5:$J$1002,$H36)) | H36: =IF($H35="","",IFERROR($H35+MATCH(1,INDEX(Dechargements!$L$5:$L$1002,$H35+1):INDEX(Dechargements!$L$5:$L$1002,1000),0),""))
... A43: =IF($H43="","",INDEX(Dechargements!$A$5:$A$1002,$H43)) | B43: =IF($H43="","",INDEX(Dechargements!$B$5:$B$1002,$H43)) | C43: =IF($H43="","",INDEX(Dechargements!$E$5:$E$1002,$H43)) | D43: =IF($H43="","",INDEX(Dechargements!$G$5:$G$1002,$H43)) | E43: =IF($H43="","",INDEX(Dechargements!$H$5:$H$1002,$H43)) | F43: =IF($H43="","",INDEX(Dechargements!$J$5:$J$1002,$H43)) | H43: =IF($H42="","",IFERROR($H42+MATCH(1,INDEX(Dechargements!$L$5:$L$1002,$H42+1):INDEX(Dechargements!$L$5:$L$1002,1000),0),""))
A44: =IF(COUNT($H$24:$H$43)>=20,"Seuls les 20 premiers camions sont affichés : filtrez la feuille Dechargements pour voir les autres.","")

Sheet Paiements
A1: Suivi des paiements
A2: Une ligne = un paiement. Remplissez les cellules sous l'en-tête bleu (à partir de la ligne 5). Les colonnes Beneficiaire, Type_Beneficiaire, Domaine, Mode_Paiement, Compte_Bancaire et Statut proposent une liste déroulante (à modifier dans la feuille Listes). Pour payer un fournisseur, écrivez son nom exactement comme dans la feuille Fournisseurs : le compte du fournisseur se met à jour tout seul. Avant de valider un paiement fournisseur, consultez la feuille Controle_Paiement. Seuls les paiements « Payé » comptent dans les totaux ; « En attente » = reste à payer ; « Annulé » est ignoré. Montants en FCFA. La ligne 5 est un exemple : remplacez-la ou supprimez-la.
A4: Date_Paiement | B4: N_Piece | C4: Beneficiaire/Fournisseur | D4: Type_Beneficiaire/Percepteurs | E4: Adresse/Téléphone | F4: Description | G4: Type d'Opération | H4: Domaine | I4: Montant | J4: Mode_Paiement | K4: Compte_Bancaire | L4: Statut | M4: Observations

Sheet Synthese
A1: Synthèse des paiements
A2: Tout se calcule automatiquement à partir des autres feuilles. Seules les 2 cellules jaunes se modifient.
A3: Année | B3: =YEAR(TODAY()) -> 2026 | C3: Par défaut : mois en cours. Tapez une autre année / un autre mois pour changer la période.
A4: Mois (1 à 12) | B4: =MONTH(TODAY()) -> 10
A6: Total payé – mois choisi | B6: =SUMIFS(Paiements!$I$5:$I$2000,Paiements!$L$5:$L$2000,"Payé",Paiements!$A$5:$A$2000,">="&DATE($B$3,$B$4,1),Paiements!$A$5:$A$2000,"<"&DATE($B$3,$B$4+1,1)) -> 0
A7: Total payé – toutes périodes | B7: =SUMIFS(Paiements!$I$5:$I$2000,Paiements!$L$5:$L$2000,"Payé") -> 0
A8: Reste à payer (statut « En attente ») | B8: =SUMIFS(Paiements!$I$5:$I$2000,Paiements!$L$5:$L$2000,"En attente") -> 0
A9: Nombre de paiements en attente | B9: =COUNTIFS(Paiements!$L$5:$L$2000,"En attente") -> 0
A10: Dû aux fournisseurs (livraisons non payées) | B10: =Fournisseurs!K4 -> 0
A11: Avances versées aux fournisseurs (à couvrir) | B11: =Fournisseurs!L4 -> 0
A13: Total par domaine
A14: Domaine | B14: Payé (mois choisi) | C14: Payé (total) | D14: En attente
A15: =IF(Listes!C2="","",Listes!C2) -> ACHAT | B15: =IF($A15="","",SUMIFS(Paiements!$I$5:$I$2000,Paiements!$G$5:$G$2000,$A15,Paiements!$L$5:$L$2000,"Payé",Paiements!$A$5:$A$2000,">="&DATE($B$3,$B$4,1),Paiements!$A$5:$A$2000,"<"&DATE($B$3,$B$4+1,1))) -> 0 | C15: =IF($A15="","",SUMIFS(Paiements!$I$5:$I$2000,Paiements!$G$5:$G$2000,$A15,Paiements!$L$5:$L$2000,"Payé")) -> 0 | D15: =IF($A15="","",SUMIFS(Paiements!$I$5:$I$2000,Paiements!$G$5:$G$2000,$A15,Paiements!$L$5:$L$2000,"En attente")) -> 0
A16: =IF(Listes!C3="","",Listes!C3) -> LOGISTIQUE | B16: =IF($A16="","",SUMIFS(Paiements!$I$5:$I$2000,Paiements!$G$5:$G$2000,$A16,Paiements!$L$5:$L$2000,"Payé",Paiements!$A$5:$A$2000,">="&DATE($B$3,$B$4,1),Paiements!$A$5:$A$2000,"<"&DATE($B$3,$B$4+1,1))) -> 0 | C16: =IF($A16="","",SUMIFS(Paiements!$I$5:$I$2000,Paiements!$G$5:$G$2000,$A16,Paiements!$L$5:$L$2000,"Payé")) -> 0 | D16: =IF($A16="","",SUMIFS(Paiements!$I$5:$I$2000,Paiements!$G$5:$G$2000,$A16,Paiements!$L$5:$L$2000,"En attente")) -> 0
A17: =IF(Listes!C4="","",Listes!C4) -> PRODUCTION | B17: =IF($A17="","",SUMIFS(Paiements!$I$5:$I$2000,Paiements!$G$5:$G$2000,$A17,Paiements!$L$5:$L$2000,"Payé",Paiements!$A$5:$A$2000,">="&DATE($B$3,$B$4,1),Paiements!$A$5:$A$2000,"<"&DATE($B$3,$B$4+1,1))) -> 0 | C17: =IF($A17="","",SUMIFS(Paiements!$I$5:$I$2000,Paiements!$G$5:$G$2000,$A17,Paiements!$L$5:$L$2000,"Payé")) -> 0 | D17: =IF($A17="","",SUMIFS(Paiements!$I$5:$I$2000,Paiements!$G$5:$G$2000,$A17,Paiements!$L$5:$L$2000,"En attente")) -> 0
A18: =IF(Listes!C5="","",Listes!C5) -> BANQUE | B18: =IF($A18="","",SUMIFS(Paiements!$I$5:$I$2000,Paiements!$G$5:$G$2000,$A18,Paiements!$L$5:$L$2000,"Payé",Paiements!$A$5:$A$2000,">="&DATE($B$3,$B$4,1),Paiements!$A$5:$A$2000,"<"&DATE($B$3,$B$4+1,1))) -> 0 | C18: =IF($A18="","",SUMIFS(Paiements!$I$5:$I$2000,Paiements!$G$5:$G$2000,$A18,Paiements!$L$5:$L$2000,"Payé")) -> 0 | D18: =IF($A18="","",SUMIFS(Paiements!$I$5:$I$2000,Paiements!$G$5:$G$2000,$A18,Paiements!$L$5:$L$2000,"En attente")) -> 0
A19: =IF(Listes!C6="","",Listes!C6) | B19: =IF($A19="","",SUMIFS(Paiements!$I$5:$I$2000,Paiements!$G$5:$G$2000,$A19,Paiements!$L$5:$L$2000,"Payé",Paiements!$A$5:$A$2000,">="&DATE($B$3,$B$4,1),Paiements!$A$5:$A$2000,"<"&DATE($B$3,$B$4+1,1))) | C19: =IF($A19="","",SUMIFS(Paiements!$I$5:$I$2000,Paiements!$G$5:$G$2000,$A19,Paiements!$L$5:$L$2000,"Payé")) | D19: =IF($A19="","",SUMIFS(Paiements!$I$5:$I$2000,Paiements!$G$5:$G$2000,$A19,Paiements!$L$5:$L$2000,"En attente"))
A20: =IF(Listes!C7="","",Listes!C7) | B20: =IF($A20="","",SUMIFS(Paiements!$I$5:$I$2000,Paiements!$G$5:$G$2000,$A20,Paiements!$L$5:$L$2000,"Payé",Paiements!$A$5:$A$2000,">="&DATE($B$3,$B$4,1),Paiements!$A$5:$A$2000,"<"&DATE($B$3,$B$4+1,1))) | C20: =IF($A20="","",SUMIFS(Paiements!$I$5:$I$2000,Paiements!$G$5:$G$2000,$A20,Paiements!$L$5:$L$2000,"Payé")) | D20: =IF($A20="","",SUMIFS(Paiements!$I$5:$I$2000,Paiements!$G$5:$G$2000,$A20,Paiements!$L$5:$L$2000,"En attente"))
A21: =IF(Listes!C8="","",Listes!C8) | B21: =IF($A21="","",SUMIFS(Paiements!$I$5:$I$2000,Paiements!$G$5:$G$2000,$A21,Paiements!$L$5:$L$2000,"Payé",Paiements!$A$5:$A$2000,">="&DATE($B$3,$B$4,1),Paiements!$A$5:$A$2000,"<"&DATE($B$3,$B$4+1,1))) | C21: =IF($A21="","",SUMIFS(Paiements!$I$5:$I$2000,Paiements!$G$5:$G$2000,$A21,Paiements!$L$5:$L$2000,"Payé")) | D21: =IF($A21="","",SUMIFS(Paiements!$I$5:$I$2000,Paiements!$G$5:$G$2000,$A21,Paiements!$L$5:$L$2000,"En attente"))
A22: =IF(Listes!C9="","",Listes!C9) | B22: =IF($A22="","",SUMIFS(Paiements!$I$5:$I$2000,Paiements!$G$5:$G$2000,$A22,Paiements!$L$5:$L$2000,"Payé",Paiements!$A$5:$A$2000,">="&DATE($B$3,$B$4,1),Paiements!$A$5:$A$2000,"<"&DATE($B$3,$B$4+1,1))) | C22: =IF($A22="","",SUMIFS(Paiements!$I$5:$I$2000,Paiements!$G$5:$G$2000,$A22,Paiements!$L$5:$L$2000,"Payé")) | D22: =IF($A22="","",SUMIFS(Paiements!$I$5:$I$2000,Paiements!$G$5:$G$2000,$A22,Paiements!$L$5:$L$2000,"En attente"))
A23: TOTAL | B23: =SUM(B15:B22) -> 0 | C23: =SUM(C15:C22) -> 0 | D23: =SUM(D15:D22) -> 0
A25: Total par compte bancaire
A26: Compte bancaire | B26: Payé (mois choisi) | C26: Payé (total) | D26: En attente
A27: =IF(Listes!E2="","",Listes!E2) -> ECOBANK | B27: =IF($A27="","",SUMIFS(Paiements!$I$5:$I$2000,Paiements!$K$5:$K$2000,$A27,Paiements!$L$5:$L$2000,"Payé",Paiements!$A$5:$A$2000,">="&DATE($B$3,$B$4,1),Paiements!$A$5:$A$2000,"<"&DATE($B$3,$B$4+1,1))) -> 0 | C27: =IF($A27="","",SUMIFS(Paiements!$I$5:$I$2000,Paiements!$K$5:$K$2000,$A27,Paiements!$L$5:$L$2000,"Payé")) -> 0 | D27: =IF($A27="","",SUMIFS(Paiements!$I$5:$I$2000,Paiements!$K$5:$K$2000,$A27,Paiements!$L$5:$L$2000,"En attente")) -> 0
A28: =IF(Listes!E3="","",Listes!E3) -> BIIC | B28: =IF($A28="","",SUMIFS(Paiements!$I$5:$I$2000,Paiements!$K$5:$K$2000,$A28,Paiements!$L$5:$L$2000,"Payé",Paiements!$A$5:$A$2000,">="&DATE($B$3,$B$4,1),Paiements!$A$5:$A$2000,"<"&DATE($B$3,$B$4+1,1))) -> 0 | C28: =IF($A28="","",SUMIFS(Paiements!$I$5:$I$2000,Paiements!$K$5:$K$2000,$A28,Paiements!$L$5:$L$2000,"Payé")) -> 0 | D28: =IF($A28="","",SUMIFS(Paiements!$I$5:$I$2000,Paiements!$K$5:$K$2000,$A28,Paiements!$L$5:$L$2000,"En attente")) -> 0
A29: =IF(Listes!E4="","",Listes!E4) -> BGFI | B29: =IF($A29="","",SUMIFS(Paiements!$I$5:$I$2000,Paiements!$K$5:$K$2000,$A29,Paiements!$L$5:$L$2000,"Payé",Paiements!$A$5:$A$2000,">="&DATE($B$3,$B$4,1),Paiements!$A$5:$A$2000,"<"&DATE($B$3,$B$4+1,1))) -> 0 | C29: =IF($A29="","",SUMIFS(Paiements!$I$5:$I$2000,Paiements!$K$5:$K$2000,$A29,Paiements!$L$5:$L$2000,"Payé")) -> 0 | D29: =IF($A29="","",SUMIFS(Paiements!$I$5:$I$2000,Paiements!$K$5:$K$2000,$A29,Paiements!$L$5:$L$2000,"En attente")) -> 0
A30: =IF(Listes!E5="","",Listes!E5) -> Atlantique | B30: =IF($A30="","",SUMIFS(Paiements!$I$5:$I$2000,Paiements!$K$5:$K$2000,$A30,Paiements!$L$5:$L$2000,"Payé",Paiements!$A$5:$A$2000,">="&DATE($B$3,$B$4,1),Paiements!$A$5:$A$2000,"<"&DATE($B$3,$B$4+1,1))) -> 0 | C30: =IF($A30="","",SUMIFS(Paiements!$I$5:$I$2000,Paiements!$K$5:$K$2000,$A30,Paiements!$L$5:$L$2000,"Payé")) -> 0 | D30: =IF($A30="","",SUMIFS(Paiements!$I$5:$I$2000,Paiements!$K$5:$K$2000,$A30,Paiements!$L$5:$L$2000,"En attente")) -> 0
A31: =IF(Listes!E6="","",Listes!E6) -> Caisse | B31: =IF($A31="","",SUMIFS(Paiements!$I$5:$I$2000,Paiements!$K$5:$K$2000,$A31,Paiements!$L$5:$L$2000,"Payé",Paiements!$A$5:$A$2000,">="&DATE($B$3,$B$4,1),Paiements!$A$5:$A$2000,"<"&DATE($B$3,$B$4+1,1))) -> 0 | C31: =IF($A31="","",SUMIFS(Paiements!$I$5:$I$2000,Paiements!$K$5:$K$2000,$A31,Paiements!$L$5:$L$2000,"Payé")) -> 0 | D31: =IF($A31="","",SUMIFS(Paiements!$I$5:$I$2000,Paiements!$K$5:$K$2000,$A31,Paiements!$L$5:$L$2000,"En attente")) -> 0
A32: =IF(Listes!E7="","",Listes!E7) | B32: =IF($A32="","",SUMIFS(Paiements!$I$5:$I$2000,Paiements!$K$5:$K$2000,$A32,Paiements!$L$5:$L$2000,"Payé",Paiements!$A$5:$A$2000,">="&DATE($B$3,$B$4,1),Paiements!$A$5:$A$2000,"<"&DATE($B$3,$B$4+1,1))) | C32: =IF($A32="","",SUMIFS(Paiements!$I$5:$I$2000,Paiements!$K$5:$K$2000,$A32,Paiements!$L$5:$L$2000,"Payé")) | D32: =IF($A32="","",SUMIFS(Paiements!$I$5:$I$2000,Paiements!$K$5:$K$2000,$A32,Paiements!$L$5:$L$2000,"En attente"))
A33: =IF(Listes!E8="","",Listes!E8) | B33: =IF($A33="","",SUMIFS(Paiements!$I$5:$I$2000,Paiements!$K$5:$K$2000,$A33,Paiements!$L$5:$L$2000,"Payé",Paiements!$A$5:$A$2000,">="&DATE($B$3,$B$4,1),Paiements!$A$5:$A$2000,"<"&DATE($B$3,$B$4+1,1))) | C33: =IF($A33="","",SUMIFS(Paiements!$I$5:$I$2000,Paiements!$K$5:$K$2000,$A33,Paiements!$L$5:$L$2000,"Payé")) | D33: =IF($A33="","",SUMIFS(Paiements!$I$5:$I$2000,Paiements!$K$5:$K$2000,$A33,Paiements!$L$5:$L$2000,"En attente"))
A34: =IF(Listes!E9="","",Listes!E9) | B34: =IF($A34="","",SUMIFS(Paiements!$I$5:$I$2000,Paiements!$K$5:$K$2000,$A34,Paiements!$L$5:$L$2000,"Payé",Paiements!$A$5:$A$2000,">="&DATE($B$3,$B$4,1),Paiements!$A$5:$A$2000,"<"&DATE($B$3,$B$4+1,1))) | C34: =IF($A34="","",SUMIFS(Paiements!$I$5:$I$2000,Paiements!$K$5:$K$2000,$A34,Paiements!$L$5:$L$2000,"Payé")) | D34: =IF($A34="","",SUMIFS(Paiements!$I$5:$I$2000,Paiements!$K$5:$K$2000,$A34,Paiements!$L$5:$L$2000,"En attente"))
A35: TOTAL | B35: =SUM(B27:B34) -> 0 | C35: =SUM(C27:C34) -> 0 | D35: =SUM(D27:D34) -> 0
A37: Total par mode de paiement
A38: Mode de paiement | B38: Payé (mois choisi) | C38: Payé (total) | D38: En attente
A39: =IF(Listes!D2="","",Listes!D2) -> Chèque | B39: =IF($A39="","",SUMIFS(Paiements!$I$5:$I$2000,Paiements!$J$5:$J$2000,$A39,Paiements!$L$5:$L$2000,"Payé",Paiements!$A$5:$A$2000,">="&DATE($B$3,$B$4,1),Paiements!$A$5:$A$2000,"<"&DATE($B$3,$B$4+1,1))) -> 0 | C39: =IF($A39="","",SUMIFS(Paiements!$I$5:$I$2000,Paiements!$J$5:$J$2000,$A39,Paiements!$L$5:$L$2000,"Payé")) -> 0 | D39: =IF($A39="","",SUMIFS(Paiements!$I$5:$I$2000,Paiements!$J$5:$J$2000,$A39,Paiements!$L$5:$L$2000,"En attente")) -> 0
A40: =IF(Listes!D3="","",Listes!D3) -> Virement | B40: =IF($A40="","",SUMIFS(Paiements!$I$5:$I$2000,Paiements!$J$5:$J$2000,$A40,Paiements!$L$5:$L$2000,"Payé",Paiements!$A$5:$A$2000,">="&DATE($B$3,$B$4,1),Paiements!$A$5:$A$2000,"<"&DATE($B$3,$B$4+1,1))) -> 0 | C40: =IF($A40="","",SUMIFS(Paiements!$I$5:$I$2000,Paiements!$J$5:$J$2000,$A40,Paiements!$L$5:$L$2000,"Payé")) -> 0 | D40: =IF($A40="","",SUMIFS(Paiements!$I$5:$I$2000,Paiements!$J$5:$J$2000,$A40,Paiements!$L$5:$L$2000,"En attente")) -> 0
A41: =IF(Listes!D4="","",Listes!D4) -> Espèces | B41: =IF($A41="","",SUMIFS(Paiements!$I$5:$I$2000,Paiements!$J$5:$J$2000,$A41,Paiements!$L$5:$L$2000,"Payé",Paiements!$A$5:$A$2000,">="&DATE($B$3,$B$4,1),Paiements!$A$5:$A$2000,"<"&DATE($B$3,$B$4+1,1))) -> 0 | C41: =IF($A41="","",SUMIFS(Paiements!$I$5:$I$2000,Paiements!$J$5:$J$2000,$A41,Paiements!$L$5:$L$2000,"Payé")) -> 0 | D41: =IF($A41="","",SUMIFS(Paiements!$I$5:$I$2000,Paiements!$J$5:$J$2000,$A41,Paiements!$L$5:$L$2000,"En attente")) -> 0
A42: =IF(Listes!D5="","",Listes!D5) -> Prélèvement | B42: =IF($A42="","",SUMIFS(Paiements!$I$5:$I$2000,Paiements!$J$5:$J$2000,$A42,Paiements!$L$5:$L$2000,"Payé",Paiements!$A$5:$A$2000,">="&DATE($B$3,$B$4,1),Paiements!$A$5:$A$2000,"<"&DATE($B$3,$B$4+1,1))) -> 0 | C42: =IF($A42="","",SUMIFS(Paiements!$I$5:$I$2000,Paiements!$J$5:$J$2000,$A42,Paiements!$L$5:$L$2000,"Payé")) -> 0 | D42: =IF($A42="","",SUMIFS(Paiements!$I$5:$I$2000,Paiements!$J$5:$J$2000,$A42,Paiements!$L$5:$L$2000,"En attente")) -> 0
A43: =IF(Listes!D6="","",Listes!D6) | B43: =IF($A43="","",SUMIFS(Paiements!$I$5:$I$2000,Paiements!$J$5:$J$2000,$A43,Paiements!$L$5:$L$2000,"Payé",Paiements!$A$5:$A$2000,">="&DATE($B$3,$B$4,1),Paiements!$A$5:$A$2000,"<"&DATE($B$3,$B$4+1,1))) | C43: =IF($A43="","",SUMIFS(Paiements!$I$5:$I$2000,Paiements!$J$5:$J$2000,$A43,Paiements!$L$5:$L$2000,"Payé")) | D43: =IF($A43="","",SUMIFS(Paiements!$I$5:$I$2000,Paiements!$J$5:$J$2000,$A43,Paiements!$L$5:$L$2000,"En attente"))
A44: =IF(Listes!D7="","",Listes!D7) | B44: =IF($A44="","",SUMIFS(Paiements!$I$5:$I$2000,Paiements!$J$5:$J$2000,$A44,Paiements!$L$5:$L$2000,"Payé",Paiements!$A$5:$A$2000,">="&DATE($B$3,$B$4,1),Paiements!$A$5:$A$2000,"<"&DATE($B$3,$B$4+1,1))) | C44: =IF($A44="","",SUMIFS(Paiements!$I$5:$I$2000,Paiements!$J$5:$J$2000,$A44,Paiements!$L$5:$L$2000,"Payé")) | D44: =IF($A44="","",SUMIFS(Paiements!$I$5:$I$2000,Paiements!$J$5:$J$2000,$A44,Paiements!$L$5:$L$2000,"En attente"))
...

Sheet Fournisseurs
B1: Compte des fournisseurs
B2: Écrivez chaque fournisseur dans les colonnes A et B seulement (cellules jaunes). Tout le reste se calcule à partir des feuilles Dechargements et Paiements. Livré = camions au statut « Fait ». Solde = livré − payé : positif = on lui doit de l'argent ; négatif = on lui a avancé de l'argent (avance pas encore couverte par des livraisons déchargées). Seuls les paiements « Payé » sont comptés ; « En attente » est affiché à part. Montants en FCFA. La ligne 6 est un exemple à remplacer.
B3: =IF(SUMPRODUCT((Paiements!$D$5:$D$2000="Fournisseur")*(Paiements!$C$5:$C$2000<>"")*(COUNTIF($B$6:$B$103,Paiements!$C$5:$C$2000)=0))=0,"","ATTENTION : "&SUMPRODUCT((Paiements!$D$5:$D$2000="Fournisseur")*(Paiements!$C$5:$C$2000<>"")*(COUNTIF($B$6:$B$103,Paiements!$C$5:$C$2000)=0))&" paiement(s) de type Fournisseur portent un nom absent de cette liste : vérifiez l'orthographe dans la feuille Paiements.")
B4: TOTAL | D4: =SUM(D6:D103) -> 0 | E4: =SUM(E6:E103) -> 0 | F4: =SUM(F6:F103) -> 0 | G4: =SUM(G6:G103) -> 0 | H4: =SUM(H6:H103) -> 0 | I4: =SUM(I6:I103) -> 0 | J4: =SUM(J6:J103) -> 0 | K4: =SUM(K6:K103) -> 0 | L4: =SUM(L6:L103) -> 0
A5: CODE FRS | B5: Fournisseur | C5: Telephone | D5: Camions_Decharges | E5: Poids_Decharge_Kg | F5: Montant_Livre | G5: Livraisons_Non_Terminees | H5: Total_Paye | I5: Paiements_En_Attente | J5: Solde_Livre_moins_Paye | K5: Reste_A_Payer (on lui doit) | L5: Avance_Restante (avancé) | M5: Situation
A6: FRS00001 | B6: TCHANIGA SAMSON | D6: =IF($B6="","",COUNTIFS(Dechargements!$C$5:$C$1002,$B6,Dechargements!$H$5:$H$1002,"Fait")) -> 0 | E6: =IF($B6="","",SUMIFS(Dechargements!$E$5:$E$1002,Dechargements!$C$5:$C$1002,$B6,Dechargements!$H$5:$H$1002,"Fait")) -> 0 | F6: =IF($B6="","",SUMIFS(Dechargements!$G$5:$G$1002,Dechargements!$C$5:$C$1002,$B6,Dechargements!$H$5:$H$1002,"Fait")) -> 0 | G6: =IF($B6="","",SUMIFS(Dechargements!$G$5:$G$1002,Dechargements!$C$5:$C$1002,$B6)-$F6-SUMIFS(Dechargements!$G$5:$G$1002,Dechargements!$C$5:$C$1002,$B6,Dechargements!$H$5:$H$1002,"Annulé")) -> 0 | H6: =IF($B6="","",SUMIFS(Paiements!$I$5:$I$2000,Paiements!$C$5:$C$2000,$B6,Paiements!$L$5:$L$2000,"Payé")) -> 0 | I6: =IF($B6="","",SUMIFS(Paiements!$I$5:$I$2000,Paiements!$C$5:$C$2000,$B6,Paiements!$L$5:$L$2000,"En attente")) -> 0 | J6: =IF($B6="","",$F6-$H6) -> 0 | K6: =IF($B6="","",MAX(0,$J6)) -> 0 | L6: =IF($B6="","",MAX(0,-$J6)) -> 0 | M6: =IF($B6="","",IF(AND($F6=0,$H6=0,$G6=0),"Aucun mouvement",IF($J6>0,"On lui doit",IF($J6<0,"Avancé","Soldé")))) -> Aucun mouvement
A7: FRS00002 | B7: ISMAEL WASSIOU/ Mme ELISABETH | D7: =IF($B7="","",COUNTIFS(Dechargements!$C$5:$C$1002,$B7,Dechargements!$H$5:$H$1002,"Fait")) -> 0 | E7: =IF($B7="","",SUMIFS(Dechargements!$E$5:$E$1002,Dechargements!$C$5:$C$1002,$B7,Dechargements!$H$5:$H$1002,"Fait")) -> 0 | F7: =IF($B7="","",SUMIFS(Dechargements!$G$5:$G$1002,Dechargements!$C$5:$C$1002,$B7,Dechargements!$H$5:$H$1002,"Fait")) -> 0 | G7: =IF($B7="","",SUMIFS(Dechargements!$G$5:$G$1002,Dechargements!$C$5:$C$1002,$B7)-$F7-SUMIFS(Dechargements!$G$5:$G$1002,Dechargements!$C$5:$C$1002,$B7,Dechargements!$H$5:$H$1002,"Annulé")) -> 0 | H7: =IF($B7="","",SUMIFS(Paiements!$I$5:$I$2000,Paiements!$C$5:$C$2000,$B7,Paiements!$L$5:$L$2000,"Payé")) -> 0 | I7: =IF($B7="","",SUMIFS(Paiements!$I$5:$I$2000,Paiements!$C$5:$C$2000,$B7,Paiements!$L$5:$L$2000,"En attente")) -> 0 | J7: =IF($B7="","",$F7-$H7) -> 0 | K7: =IF($B7="","",MAX(0,$J7)) -> 0 | L7: =IF($B7="","",MAX(0,-$J7)) -> 0 | M7: =IF($B7="","",IF(AND($F7=0,$H7=0,$G7=0),"Aucun mouvement",IF($J7>0,"On lui doit",IF($J7<0,"Avancé","Soldé")))) -> Aucun mouvement
A8: FRS00003 | B8: BADAROU SAID | D8: =IF($B8="","",COUNTIFS(Dechargements!$C$5:$C$1002,$B8,Dechargements!$H$5:$H$1002,"Fait")) -> 0 | E8: =IF($B8="","",SUMIFS(Dechargements!$E$5:$E$1002,Dechargements!$C$5:$C$1002,$B8,Dechargements!$H$5:$H$1002,"Fait")) -> 0 | F8: =IF($B8="","",SUMIFS(Dechargements!$G$5:$G$1002,Dechargements!$C$5:$C$1002,$B8,Dechargements!$H$5:$H$1002,"Fait")) -> 0 | G8: =IF($B8="","",SUMIFS(Dechargements!$G$5:$G$1002,Dechargements!$C$5:$C$1002,$B8)-$F8-SUMIFS(Dechargements!$G$5:$G$1002,Dechargements!$C$5:$C$1002,$B8,Dechargements!$H$5:$H$1002,"Annulé")) -> 0 | H8: =IF($B8="","",SUMIFS(Paiements!$I$5:$I$2000,Paiements!$C$5:$C$2000,$B8,Paiements!$L$5:$L$2000,"Payé")) -> 0 | I8: =IF($B8="","",SUMIFS(Paiements!$I$5:$I$2000,Paiements!$C$5:$C$2000,$B8,Paiements!$L$5:$L$2000,"En attente")) -> 0 | J8: =IF($B8="","",$F8-$H8) -> 0 | K8: =IF($B8="","",MAX(0,$J8)) -> 0 | L8: =IF($B8="","",MAX(0,-$J8)) -> 0 | M8: =IF($B8="","",IF(AND($F8=0,$H8=0,$G8=0),"Aucun mouvement",IF($J8>0,"On lui doit",IF($J8<0,"Avancé","Soldé")))) -> Aucun mouvement
A9: FRS00004 | B9: ISMAEL WASSIOU | D9: =IF($B9="","",COUNTIFS(Dechargements!$C$5:$C$1002,$B9,Dechargements!$H$5:$H$1002,"Fait")) -> 0 | E9: =IF($B9="","",SUMIFS(Dechargements!$E$5:$E$1002,Dechargements!$C$5:$C$1002,$B9,Dechargements!$H$5:$H$1002,"Fait")) -> 0 | F9: =IF($B9="","",SUMIFS(Dechargements!$G$5:$G$1002,Dechargements!$C$5:$C$1002,$B9,Dechargements!$H$5:$H$1002,"Fait")) -> 0 | G9: =IF($B9="","",SUMIFS(Dechargements!$G$5:$G$1002,Dechargements!$C$5:$C$1002,$B9)-$F9-SUMIFS(Dechargements!$G$5:$G$1002,Dechargements!$C$5:$C$1002,$B9,Dechargements!$H$5:$H$1002,"Annulé")) -> 0 | H9: =IF($B9="","",SUMIFS(Paiements!$I$5:$I$2000,Paiements!$C$5:$C$2000,$B9,Paiements!$L$5:$L$2000,"Payé")) -> 0 | I9: =IF($B9="","",SUMIFS(Paiements!$I$5:$I$2000,Paiements!$C$5:$C$2000,$B9,Paiements!$L$5:$L$2000,"En attente")) -> 0 | J9: =IF($B9="","",$F9-$H9) -> 0 | K9: =IF($B9="","",MAX(0,$J9)) -> 0 | L9: =IF($B9="","",MAX(0,-$J9)) -> 0 | M9: =IF($B9="","",IF(AND($F9=0,$H9=0,$G9=0),"Aucun mouvement",IF($J9>0,"On lui doit",IF($J9<0,"Avancé","Soldé")))) -> Aucun mouvement
A10: FRS00005 | B10: ALLASSANE MARWANE | D10: =IF($B10="","",COUNTIFS(Dechargements!$C$5:$C$1002,$B10,Dechargements!$H$5:$H$1002,"Fait")) -> 0 | E10: =IF($B10="","",SUMIFS(Dechargements!$E$5:$E$1002,Dechargements!$C$5:$C$1002,$B10,Dechargements!$H$5:$H$1002,"Fait")) -> 0 | F10: =IF($B10="","",SUMIFS(Dechargements!$G$5:$G$1002,Dechargements!$C$5:$C$1002,$B10,Dechargements!$H$5:$H$1002,"Fait")) -> 0 | G10: =IF($B10="","",SUMIFS(Dechargements!$G$5:$G$1002,Dechargements!$C$5:$C$1002,$B10)-$F10-SUMIFS(Dechargements!$G$5:$G$1002,Dechargements!$C$5:$C$1002,$B10,Dechargements!$H$5:$H$1002,"Annulé")) -> 0 | H10: =IF($B10="","",SUMIFS(Paiements!$I$5:$I$2000,Paiements!$C$5:$C$2000,$B10,Paiements!$L$5:$L$2000,"Payé")) -> 0 | I10: =IF($B10="","",SUMIFS(Paiements!$I$5:$I$2000,Paiements!$C$5:$C$2000,$B10,Paiements!$L$5:$L$2000,"En attente")) -> 0 | J10: =IF($B10="","",$F10-$H10) -> 0 | K10: =IF($B10="","",MAX(0,$J10)) -> 0 | L10: =IF($B10="","",MAX(0,-$J10)) -> 0 | M10: =IF($B10="","",IF(AND($F10=0,$H10=0,$G10=0),"Aucun mouvement",IF($J10>0,"On lui doit",IF($J10<0,"Avancé","Soldé")))) -> Aucun mouvement
A11: FRS00006 | B11: VLAVONOU PIERRE | D11: =IF($B11="","",COUNTIFS(Dechargements!$C$5:$C$1002,$B11,Dechargements!$H$5:$H$1002,"Fait")) -> 0 | E11: =IF($B11="","",SUMIFS(Dechargements!$E$5:$E$1002,Dechargements!$C$5:$C$1002,$B11,Dechargements!$H$5:$H$1002,"Fait")) -> 0 | F11: =IF($B11="","",SUMIFS(Dechargements!$G$5:$G$1002,Dechargements!$C$5:$C$1002,$B11,Dechargements!$H$5:$H$1002,"Fait")) -> 0 | G11: =IF($B11="","",SUMIFS(Dechargements!$G$5:$G$1002,Dechargements!$C$5:$C$1002,$B11)-$F11-SUMIFS(Dechargements!$G$5:$G$1002,Dechargements!$C$5:$C$1002,$B11,Dechargements!$H$5:$H$1002,"Annulé")) -> 0 | H11: =IF($B11="","",SUMIFS(Paiements!$I$5:$I$2000,Paiements!$C$5:$C$2000,$B11,Paiements!$L$5:$L$2000,"Payé")) -> 0 | I11: =IF($B11="","",SUMIFS(Paiements!$I$5:$I$2000,Paiements!$C$5:$C$2000,$B11,Paiements!$L$5:$L$2000,"En attente")) -> 0 | J11: =IF($B11="","",$F11-$H11) -> 0 | K11: =IF($B11="","",MAX(0,$J11)) -> 0 | L11: =IF($B11="","",MAX(0,-$J11)) -> 0 | M11: =IF($B11="","",IF(AND($F11=0,$H11=0,$G11=0),"Aucun mouvement",IF($J11>0,"On lui doit",IF($J11<0,"Avancé","Soldé")))) -> Aucun mouvement
A12: FRS00007 | B12: BRISSO BIO ALIDOU | D12: =IF($B12="","",COUNTIFS(Dechargements!$C$5:$C$1002,$B12,Dechargements!$H$5:$H$1002,"Fait")) -> 0 | E12: =IF($B12="","",SUMIFS(Dechargements!$E$5:$E$1002,Dechargements!$C$5:$C$1002,$B12,Dechargements!$H$5:$H$1002,"Fait")) -> 0 | F12: =IF($B12="","",SUMIFS(Dechargements!$G$5:$G$1002,Dechargements!$C$5:$C$1002,$B12,Dechargements!$H$5:$H$1002,"Fait")) -> 0 | G12: =IF($B12="","",SUMIFS(Dechargements!$G$5:$G$1002,Dechargements!$C$5:$C$1002,$B12)-$F12-SUMIFS(Dechargements!$G$5:$G$1002,Dechargements!$C$5:$C$1002,$B12,Dechargements!$H$5:$H$1002,"Annulé")) -> 0 | H12: =IF($B12="","",SUMIFS(Paiements!$I$5:$I$2000,Paiements!$C$5:$C$2000,$B12,Paiements!$L$5:$L$2000,"Payé")) -> 0 | I12: =IF($B12="","",SUMIFS(Paiements!$I$5:$I$2000,Paiements!$C$5:$C$2000,$B12,Paiements!$L$5:$L$2000,"En attente")) -> 0 | J12: =IF($B12="","",$F12-$H12) -> 0 | K12: =IF($B12="","",MAX(0,$J12)) -> 0 | L12: =IF($B12="","",MAX(0,-$J12)) -> 0 | M12: =IF($B12="","",IF(AND($F12=0,$H12=0,$G12=0),"Aucun mouvement",IF($J12>0,"On lui doit",IF($J12<0,"Avancé","Soldé")))) -> Aucun mouvement
A13: FRS00008 | B13: HERVE KOBOLOU | D13: =IF($B13="","",COUNTIFS(Dechargements!$C$5:$C$1002,$B13,Dechargements!$H$5:$H$1002,"Fait")) -> 0 | E13: =IF($B13="","",SUMIFS(Dechargements!$E$5:$E$1002,Dechargements!$C$5:$C$1002,$B13,Dechargements!$H$5:$H$1002,"Fait")) -> 0 | F13: =IF($B13="","",SUMIFS(Dechargements!$G$5:$G$1002,Dechargements!$C$5:$C$1002,$B13,Dechargements!$H$5:$H$1002,"Fait")) -> 0 | G13: =IF($B13="","",SUMIFS(Dechargements!$G$5:$G$1002,Dechargements!$C$5:$C$1002,$B13)-$F13-SUMIFS(Dechargements!$G$5:$G$1002,Dechargements!$C$5:$C$1002,$B13,Dechargements!$H$5:$H$1002,"Annulé")) -> 0 | H13: =IF($B13="","",SUMIFS(Paiements!$I$5:$I$2000,Paiements!$C$5:$C$2000,$B13,Paiements!$L$5:$L$2000,"Payé")) -> 0 | I13: =IF($B13="","",SUMIFS(Paiements!$I$5:$I$2000,Paiements!$C$5:$C$2000,$B13,Paiements!$L$5:$L$2000,"En attente")) -> 0 | J13: =IF($B13="","",$F13-$H13) -> 0 | K13: =IF($B13="","",MAX(0,$J13)) -> 0 | L13: =IF($B13="","",MAX(0,-$J13)) -> 0 | M13: =IF($B13="","",IF(AND($F13=0,$H13=0,$G13=0),"Aucun mouvement",IF($J13>0,"On lui doit",IF($J13<0,"Avancé","Soldé")))) -> Aucun mouvement
A14: FRS00009 | B14: GOUDO DOSSOU ROMAIN | D14: =IF($B14="","",COUNTIFS(Dechargements!$C$5:$C$1002,$B14,Dechargements!$H$5:$H$1002,"Fait")) -> 0 | E14: =IF($B14="","",SUMIFS(Dechargements!$E$5:$E$1002,Dechargements!$C$5:$C$1002,$B14,Dechargements!$H$5:$H$1002,"Fait")) -> 0 | F14: =IF($B14="","",SUMIFS(Dechargements!$G$5:$G$1002,Dechargements!$C$5:$C$1002,$B14,Dechargements!$H$5:$H$1002,"Fait")) -> 0 | G14: =IF($B14="","",SUMIFS(Dechargements!$G$5:$G$1002,Dechargements!$C$5:$C$1002,$B14)-$F14-SUMIFS(Dechargements!$G$5:$G$1002,Dechargements!$C$5:$C$1002,$B14,Dechargements!$H$5:$H$1002,"Annulé")) -> 0 | H14: =IF($B14="","",SUMIFS(Paiements!$I$5:$I$2000,Paiements!$C$5:$C$2000,$B14,Paiements!$L$5:$L$2000,"Payé")) -> 0 | I14: =IF($B14="","",SUMIFS(Paiements!$I$5:$I$2000,Paiements!$C$5:$C$2000,$B14,Paiements!$L$5:$L$2000,"En attente")) -> 0 | J14: =IF($B14="","",$F14-$H14) -> 0 | K14: =IF($B14="","",MAX(0,$J14)) -> 0 | L14: =IF($B14="","",MAX(0,-$J14)) -> 0 | M14: =IF($B14="","",IF(AND($F14=0,$H14=0,$G14=0),"Aucun mouvement",IF($J14>0,"On lui doit",IF($J14<0,"Avancé","Soldé")))) -> Aucun mouvement
A15: FRS00010 | B15: COMLAN MAHOUSSE JOSPIN | D15: =IF($B15="","",COUNTIFS(Dechargements!$C$5:$C$1002,$B15,Dechargements!$H$5:$H$1002,"Fait")) -> 0 | E15: =IF($B15="","",SUMIFS(Dechargements!$E$5:$E$1002,Dechargements!$C$5:$C$1002,$B15,Dechargements!$H$5:$H$1002,"Fait")) -> 0 | F15: =IF($B15="","",SUMIFS(Dechargements!$G$5:$G$1002,Dechargements!$C$5:$C$1002,$B15,Dechargements!$H$5:$H$1002,"Fait")) -> 0 | G15: =IF($B15="","",SUMIFS(Dechargements!$G$5:$G$1002,Dechargements!$C$5:$C$1002,$B15)-$F15-SUMIFS(Dechargements!$G$5:$G$1002,Dechargements!$C$5:$C$1002,$B15,Dechargements!$H$5:$H$1002,"Annulé")) -> 0 | H15: =IF($B15="","",SUMIFS(Paiements!$I$5:$I$2000,Paiements!$C$5:$C$2000,$B15,Paiements!$L$5:$L$2000,"Payé")) -> 0 | I15: =IF($B15="","",SUMIFS(Paiements!$I$5:$I$2000,Paiements!$C$5:$C$2000,$B15,Paiements!$L$5:$L$2000,"En attente")) -> 0 | J15: =IF($B15="","",$F15-$H15) -> 0 | K15: =IF($B15="","",MAX(0,$J15)) -> 0 | L15: =IF($B15="","",MAX(0,-$J15)) -> 0 | M15: =IF($B15="","",IF(AND($F15=0,$H15=0,$G15=0),"Aucun mouvement",IF($J15>0,"On lui doit",IF($J15<0,"Avancé","Soldé")))) -> Aucun mouvement
A16: FRS00011 | B16: CHIGBLO FERDINAND | D16: =IF($B16="","",COUNTIFS(Dechargements!$C$5:$C$1002,$B16,Dechargements!$H$5:$H$1002,"Fait")) -> 0 | E16: =IF($B16="","",SUMIFS(Dechargements!$E$5:$E$1002,Dechargements!$C$5:$C$1002,$B16,Dechargements!$H$5:$H$1002,"Fait")) -> 0 | F16: =IF($B16="","",SUMIFS(Dechargements!$G$5:$G$1002,Dechargements!$C$5:$C$1002,$B16,Dechargements!$H$5:$H$1002,"Fait")) -> 0 | G16: =IF($B16="","",SUMIFS(Dechargements!$G$5:$G$1002,Dechargements!$C$5:$C$1002,$B16)-$F16-SUMIFS(Dechargements!$G$5:$G$1002,Dechargements!$C$5:$C$1002,$B16,Dechargements!$H$5:$H$1002,"Annulé")) -> 0 | H16: =IF($B16="","",SUMIFS(Paiements!$I$5:$I$2000,Paiements!$C$5:$C$2000,$B16,Paiements!$L$5:$L$2000,"Payé")) -> 0 | I16: =IF($B16="","",SUMIFS(Paiements!$I$5:$I$2000,Paiements!$C$5:$C$2000,$B16,Paiements!$L$5:$L$2000,"En attente")) -> 0 | J16: =IF($B16="","",$F16-$H16) -> 0 | K16: =IF($B16="","",MAX(0,$J16)) -> 0 | L16: =IF($B16="","",MAX(0,-$J16)) -> 0 | M16: =IF($B16="","",IF(AND($F16=0,$H16=0,$G16=0),"Aucun mouvement",IF($J16>0,"On lui doit",IF($J16<0,"Avancé","Soldé")))) -> Aucun mouvement
A17: FRS00012 | B17: ROLAND ADANHONDJI | D17: =IF($B17="","",COUNTIFS(Dechargements!$C$5:$C$1002,$B17,Dechargements!$H$5:$H$1002,"Fait")) -> 0 | E17: =IF($B17="","",SUMIFS(Dechargements!$E$5:$E$1002,Dechargements!$C$5:$C$1002,$B17,Dechargements!$H$5:$H$1002,"Fait")) -> 0 | F17: =IF($B17="","",SUMIFS(Dechargements!$G$5:$G$1002,Dechargements!$C$5:$C$1002,$B17,Dechargements!$H$5:$H$1002,"Fait")) -> 0 | G17: =IF($B17="","",SUMIFS(Dechargements!$G$5:$G$1002,Dechargements!$C$5:$C$1002,$B17)-$F17-SUMIFS(Dechargements!$G$5:$G$1002,Dechargements!$C$5:$C$1002,$B17,Dechargements!$H$5:$H$1002,"Annulé")) -> 0 | H17: =IF($B17="","",SUMIFS(Paiements!$I$5:$I$2000,Paiements!$C$5:$C$2000,$B17,Paiements!$L$5:$L$2000,"Payé")) -> 0 | I17: =IF($B17="","",SUMIFS(Paiements!$I$5:$I$2000,Paiements!$C$5:$C$2000,$B17,Paiements!$L$5:$L$2000,"En attente")) -> 0 | J17: =IF($B17="","",$F17-$H17) -> 0 | K17: =IF($B17="","",MAX(0,$J17)) -> 0 | L17: =IF($B17="","",MAX(0,-$J17)) -> 0 | M17: =IF($B17="","",IF(AND($F17=0,$H17=0,$G17=0),"Aucun mouvement",IF($J17>0,"On lui doit",IF($J17<0,"Avancé","Soldé")))) -> Aucun mouvement
... A67: FRS00062 | B67: ALEXANDRE | D67: =IF($B67="","",COUNTIFS(Dechargements!$C$5:$C$1002,$B67,Dechargements!$H$5:$H$1002,"Fait")) -> 0 | E67: =IF($B67="","",SUMIFS(Dechargements!$E$5:$E$1002,Dechargements!$C$5:$C$1002,$B67,Dechargements!$H$5:$H$1002,"Fait")) -> 0 | F67: =IF($B67="","",SUMIFS(Dechargements!$G$5:$G$1002,Dechargements!$C$5:$C$1002,$B67,Dechargements!$H$5:$H$1002,"Fait")) -> 0 | G67: =IF($B67="","",SUMIFS(Dechargements!$G$5:$G$1002,Dechargements!$C$5:$C$1002,$B67)-$F67-SUMIFS(Dechargements!$G$5:$G$1002,Dechargements!$C$5:$C$1002,$B67,Dechargements!$H$5:$H$1002,"Annulé")) -> 0 | H67: =IF($B67="","",SUMIFS(Paiements!$I$5:$I$2000,Paiements!$C$5:$C$2000,$B67,Paiements!$L$5:$L$2000,"Payé")) -> 0 | I67: =IF($B67="","",SUMIFS(Paiements!$I$5:$I$2000,Paiements!$C$5:$C$2000,$B67,Paiements!$L$5:$L$2000,"En attente")) -> 0 | J67: =IF($B67="","",$F67-$H67) -> 0 | K67: =IF($B67="","",MAX(0,$J67)) -> 0 | L67: =IF($B67="","",MAX(0,-$J67)) -> 0 | M67: =IF($B67="","",IF(AND($F67=0,$H67=0,$G67=0),"Aucun mouvement",IF($J67>0,"On lui doit",IF($J67<0,"Avancé","Soldé")))) -> Aucun mouvement
D68: =IF($B68="","",COUNTIFS(Dechargements!$C$5:$C$1002,$B68,Dechargements!$H$5:$H$1002,"Fait")) | E68: =IF($B68="","",SUMIFS(Dechargements!$E$5:$E$1002,Dechargements!$C$5:$C$1002,$B68,Dechargements!$H$5:$H$1002,"Fait")) | F68: =IF($B68="","",SUMIFS(Dechargements!$G$5:$G$1002,Dechargements!$C$5:$C$1002,$B68,Dechargements!$H$5:$H$1002,"Fait")) | G68: =IF($B68="","",SUMIFS(Dechargements!$G$5:$G$1002,Dechargements!$C$5:$C$1002,$B68)-$F68-SUMIFS(Dechargements!$G$5:$G$1002,Dechargements!$C$5:$C$1002,$B68,Dechargements!$H$5:$H$1002,"Annulé")) | H68: =IF($B68="","",SUMIFS(Paiements!$I$5:$I$2000,Paiements!$C$5:$C$2000,$B68,Paiements!$L$5:$L$2000,"Payé")) | I68: =IF($B68="","",SUMIFS(Paiements!$I$5:$I$2000,Paiements!$C$5:$C$2000,$B68,Paiements!$L$5:$L$2000,"En attente")) | J68: =IF($B68="","",$F68-$H68) | K68: =IF($B68="","",MAX(0,$J68)) | L68: =IF($B68="","",MAX(0,-$J68)) | M68: =IF($B68="","",IF(AND($F68=0,$H68=0,$G68=0),"Aucun mouvement",IF($J68>0,"On lui doit",IF($J68<0,"Avancé","Soldé"))))
D69: =IF($B69="","",COUNTIFS(Dechargements!$C$5:$C$1002,$B69,Dechargements!$H$5:$H$1002,"Fait")) | E69: =IF($B69="","",SUMIFS(Dechargements!$E$5:$E$1002,Dechargements!$C$5:$C$1002,$B69,Dechargements!$H$5:$H$1002,"Fait")) | F69: =IF($B69="","",SUMIFS(Dechargements!$G$5:$G$1002,Dechargements!$C$5:$C$1002,$B69,Dechargements!$H$5:$H$1002,"Fait")) | G69: =IF($B69="","",SUMIFS(Dechargements!$G$5:$G$1002,Dechargements!$C$5:$C$1002,$B69)-$F69-SUMIFS(Dechargements!$G$5:$G$1002,Dechargements!$C$5:$C$1002,$B69,Dechargements!$H$5:$H$1002,"Annulé")) | H69: =IF($B69="","",SUMIFS(Paiements!$I$5:$I$2000,Paiements!$C$5:$C$2000,$B69,Paiements!$L$5:$L$2000,"Payé")) | I69: =IF($B69="","",SUMIFS(Paiements!$I$5:$I$2000,Paiements!$C$5:$C$2000,$B69,Paiements!$L$5:$L$2000,"En attente")) | J69: =IF($B69="","",$F69-$H69) | K69: =IF($B69="","",MAX(0,$J69)) | L69: =IF($B69="","",MAX(0,-$J69)) | M69: =IF($B69="","",IF(AND($F69=0,$H69=0,$G69=0),"Aucun mouvement",IF($J69>0,"On lui doit",IF($J69<0,"Avancé","Soldé"))))
D70: =IF($B70="","",COUNTIFS(Dechargements!$C$5:$C$1002,$B70,Dechargements!$H$5:$H$1002,"Fait")) | E70: =IF($B70="","",SUMIFS(Dechargements!$E$5:$E$1002,Dechargements!$C$5:$C$1002,$B70,Dechargements!$H$5:$H$1002,"Fait")) | F70: =IF($B70="","",SUMIFS(Dechargements!$G$5:$G$1002,Dechargements!$C$5:$C$1002,$B70,Dechargements!$H$5:$H$1002,"Fait")) | G70: =IF($B70="","",SUMIFS(Dechargements!$G$5:$G$1002,Dechargements!$C$5:$C$1002,$B70)-$F70-SUMIFS(Dechargements!$G$5:$G$1002,Dechargements!$C$5:$C$1002,$B70,Dechargements!$H$5:$H$1002,"Annulé")) | H70: =IF($B70="","",SUMIFS(Paiements!$I$5:$I$2000,Paiements!$C$5:$C$2000,$B70,Paiements!$L$5:$L$2000,"Payé")) | I70: =IF($B70="","",SUMIFS(Paiements!$I$5:$I$2000,Paiements!$C$5:$C$2000,$B70,Paiements!$L$5:$L$2000,"En attente")) | J70: =IF($B70="","",$F70-$H70) | K70: =IF($B70="","",MAX(0,$J70)) | L70: =IF($B70="","",MAX(0,-$J70)) | M70: =IF($B70="","",IF(AND($F70=0,$H70=0,$G70=0),"Aucun mouvement",IF($J70>0,"On lui doit",IF($J70<0,"Avancé","Soldé"))))
D71: =IF($B71="","",COUNTIFS(Dechargements!$C$5:$C$1002,$B71,Dechargements!$H$5:$H$1002,"Fait")) | E71: =IF($B71="","",SUMIFS(Dechargements!$E$5:$E$1002,Dechargements!$C$5:$C$1002,$B71,Dechargements!$H$5:$H$1002,"Fait")) | F71: =IF($B71="","",SUMIFS(Dechargements!$G$5:$G$1002,Dechargements!$C$5:$C$1002,$B71,Dechargements!$H$5:$H$1002,"Fait")) | G71: =IF($B71="","",SUMIFS(Dechargements!$G$5:$G$1002,Dechargements!$C$5:$C$1002,$B71)-$F71-SUMIFS(Dechargements!$G$5:$G$1002,Dechargements!$C$5:$C$1002,$B71,Dechargements!$H$5:$H$1002,"Annulé")) | H71: =IF($B71="","",SUMIFS(Paiements!$I$5:$I$2000,Paiements!$C$5:$C$2000,$B71,Paiements!$L$5:$L$2000,"Payé")) | I71: =IF($B71="","",SUMIFS(Paiements!$I$5:$I$2000,Paiements!$C$5:$C$2000,$B71,Paiements!$L$5:$L$2000,"En attente")) | J71: =IF($B71="","",$F71-$H71) | K71: =IF($B71="","",MAX(0,$J71)) | L71: =IF($B71="","",MAX(0,-$J71)) | M71: =IF($B71="","",IF(AND($F71=0,$H71=0,$G71=0),"Aucun mouvement",IF($J71>0,"On lui doit",IF($J71<0,"Avancé","Soldé"))))
D72: =IF($B72="","",COUNTIFS(Dechargements!$C$5:$C$1002,$B72,Dechargements!$H$5:$H$1002,"Fait")) | E72: =IF($B72="","",SUMIFS(Dechargements!$E$5:$E$1002,Dechargements!$C$5:$C$1002,$B72,Dechargements!$H$5:$H$1002,"Fait")) | F72: =IF($B72="","",SUMIFS(Dechargements!$G$5:$G$1002,Dechargements!$C$5:$C$1002,$B72,Dechargements!$H$5:$H$1002,"Fait")) | G72: =IF($B72="","",SUMIFS(Dechargements!$G$5:$G$1002,Dechargements!$C$5:$C$1002,$B72)-$F72-SUMIFS(Dechargements!$G$5:$G$1002,Dechargements!$C$5:$C$1002,$B72,Dechargements!$H$5:$H$1002,"Annulé")) | H72: =IF($B72="","",SUMIFS(Paiements!$I$5:$I$2000,Paiements!$C$5:$C$2000,$B72,Paiements!$L$5:$L$2000,"Payé")) | I72: =IF($B72="","",SUMIFS(Paiements!$I$5:$I$2000,Paiements!$C$5:$C$2000,$B72,Paiements!$L$5:$L$2000,"En attente")) | J72: =IF($B72="","",$F72-$H72) | K72: =IF($B72="","",MAX(0,$J72)) | L72: =IF($B72="","",MAX(0,-$J72)) | M72: =IF($B72="","",IF(AND($F72=0,$H72=0,$G72=0),"Aucun mouvement",IF($J72>0,"On lui doit",IF($J72<0,"Avancé","Soldé"))))
D73: =IF($B73="","",COUNTIFS(Dechargements!$C$5:$C$1002,$B73,Dechargements!$H$5:$H$1002,"Fait")) | E73: =IF($B73="","",SUMIFS(Dechargements!$E$5:$E$1002,Dechargements!$C$5:$C$1002,$B73,Dechargements!$H$5:$H$1002,"Fait")) | F73: =IF($B73="","",SUMIFS(Dechargements!$G$5:$G$1002,Dechargements!$C$5:$C$1002,$B73,Dechargements!$H$5:$H$1002,"Fait")) | G73: =IF($B73="","",SUMIFS(Dechargements!$G$5:$G$1002,Dechargements!$C$5:$C$1002,$B73)-$F73-SUMIFS(Dechargements!$G$5:$G$1002,Dechargements!$C$5:$C$1002,$B73,Dechargements!$H$5:$H$1002,"Annulé")) | H73: =IF($B73="","",SUMIFS(Paiements!$I$5:$I$2000,Paiements!$C$5:$C$2000,$B73,Paiements!$L$5:$L$2000,"Payé")) | I73: =IF($B73="","",SUMIFS(Paiements!$I$5:$I$2000,Paiements!$C$5:$C$2000,$B73,Paiements!$L$5:$L$2000,"En attente")) | J73: =IF($B73="","",$F73-$H73) | K73: =IF($B73="","",MAX(0,$J73)) | L73: =IF($B73="","",MAX(0,-$J73)) | M73: =IF($B73="","",IF(AND($F73=0,$H73=0,$G73=0),"Aucun mouvement",IF($J73>0,"On lui doit",IF($J73<0,"Avancé","Soldé"))))
D74: =IF($B74="","",COUNTIFS(Dechargements!$C$5:$C$1002,$B74,Dechargements!$H$5:$H$1002,"Fait")) | E74: =IF($B74="","",SUMIFS(Dechargements!$E$5:$E$1002,Dechargements!$C$5:$C$1002,$B74,Dechargements!$H$5:$H$1002,"Fait")) | F74: =IF($B74="","",SUMIFS(Dechargements!$G$5:$G$1002,Dechargements!$C$5:$C$1002,$B74,Dechargements!$H$5:$H$1002,"Fait")) | G74: =IF($B74="","",SUMIFS(Dechargements!$G$5:$G$1002,Dechargements!$C$5:$C$1002,$B74)-$F74-SUMIFS(Dechargements!$G$5:$G$1002,Dechargements!$C$5:$C$1002,$B74,Dechargements!$H$5:$H$1002,"Annulé")) | H74: =IF($B74="","",SUMIFS(Paiements!$I$5:$I$2000,Paiements!$C$5:$C$2000,$B74,Paiements!$L$5:$L$2000,"Payé")) | I74: =IF($B74="","",SUMIFS(Paiements!$I$5:$I$2000,Paiements!$C$5:$C$2000,$B74,Paiements!$L$5:$L$2000,"En attente")) | J74: =IF($B74="","",$F74-$H74) | K74: =IF($B74="","",MAX(0,$J74)) | L74: =IF($B74="","",MAX(0,-$J74)) | M74: =IF($B74="","",IF(AND($F74=0,$H74=0,$G74=0),"Aucun mouvement",IF($J74>0,"On lui doit",IF($J74<0,"Avancé","Soldé"))))
D75: =IF($B75="","",COUNTIFS(Dechargements!$C$5:$C$1002,$B75,Dechargements!$H$5:$H$1002,"Fait")) | E75: =IF($B75="","",SUMIFS(Dechargements!$E$5:$E$1002,Dechargements!$C$5:$C$1002,$B75,Dechargements!$H$5:$H$1002,"Fait")) | F75: =IF($B75="","",SUMIFS(Dechargements!$G$5:$G$1002,Dechargements!$C$5:$C$1002,$B75,Dechargements!$H$5:$H$1002,"Fait")) | G75: =IF($B75="","",SUMIFS(Dechargements!$G$5:$G$1002,Dechargements!$C$5:$C$1002,$B75)-$F75-SUMIFS(Dechargements!$G$5:$G$1002,Dechargements!$C$5:$C$1002,$B75,Dechargements!$H$5:$H$1002,"Annulé")) | H75: =IF($B75="","",SUMIFS(Paiements!$I$5:$I$2000,Paiements!$C$5:$C$2000,$B75,Paiements!$L$5:$L$2000,"Payé")) | I75: =IF($B75="","",SUMIFS(Paiements!$I$5:$I$2000,Paiements!$C$5:$C$2000,$B75,Paiements!$L$5:$L$2000,"En attente")) | J75: =IF($B75="","",$F75-$H75) | K75: =IF($B75="","",MAX(0,$J75)) | L75: =IF($B75="","",MAX(0,-$J75)) | M75: =IF($B75="","",IF(AND($F75=0,$H75=0,$G75=0),"Aucun mouvement",IF($J75>0,"On lui doit",IF($J75<0,"Avancé","Soldé"))))
D76: =IF($B76="","",COUNTIFS(Dechargements!$C$5:$C$1002,$B76,Dechargements!$H$5:$H$1002,"Fait")) | E76: =IF($B76="","",SUMIFS(Dechargements!$E$5:$E$1002,Dechargements!$C$5:$C$1002,$B76,Dechargements!$H$5:$H$1002,"Fait")) | F76: =IF($B76="","",SUMIFS(Dechargements!$G$5:$G$1002,Dechargements!$C$5:$C$1002,$B76,Dechargements!$H$5:$H$1002,"Fait")) | G76: =IF($B76="","",SUMIFS(Dechargements!$G$5:$G$1002,Dechargements!$C$5:$C$1002,$B76)-$F76-SUMIFS(Dechargements!$G$5:$G$1002,Dechargements!$C$5:$C$1002,$B76,Dechargements!$H$5:$H$1002,"Annulé")) | H76: =IF($B76="","",SUMIFS(Paiements!$I$5:$I$2000,Paiements!$C$5:$C$2000,$B76,Paiements!$L$5:$L$2000,"Payé")) | I76: =IF($B76="","",SUMIFS(Paiements!$I$5:$I$2000,Paiements!$C$5:$C$2000,$B76,Paiements!$L$5:$L$2000,"En attente")) | J76: =IF($B76="","",$F76-$H76) | K76: =IF($B76="","",MAX(0,$J76)) | L76: =IF($B76="","",MAX(0,-$J76)) | M76: =IF($B76="","",IF(AND($F76=0,$H76=0,$G76=0),"Aucun mouvement",IF($J76>0,"On lui doit",IF($J76<0,"Avancé","Soldé"))))
D77: =IF($B77="","",COUNTIFS(Dechargements!$C$5:$C$1002,$B77,Dechargements!$H$5:$H$1002,"Fait")) | E77: =IF($B77="","",SUMIFS(Dechargements!$E$5:$E$1002,Dechargements!$C$5:$C$1002,$B77,Dechargements!$H$5:$H$1002,"Fait")) | F77: =IF($B77="","",SUMIFS(Dechargements!$G$5:$G$1002,Dechargements!$C$5:$C$1002,$B77,Dechargements!$H$5:$H$1002,"Fait")) | G77: =IF($B77="","",SUMIFS(Dechargements!$G$5:$G$1002,Dechargements!$C$5:$C$1002,$B77)-$F77-SUMIFS(Dechargements!$G$5:$G$1002,Dechargements!$C$5:$C$1002,$B77,Dechargements!$H$5:$H$1002,"Annulé")) | H77: =IF($B77="","",SUMIFS(Paiements!$I$5:$I$2000,Paiements!$C$5:$C$2000,$B77,Paiements!$L$5:$L$2000,"Payé")) | I77: =IF($B77="","",SUMIFS(Paiements!$I$5:$I$2000,Paiements!$C$5:$C$2000,$B77,Paiements!$L$5:$L$2000,"En attente")) | J77: =IF($B77="","",$F77-$H77) | K77: =IF($B77="","",MAX(0,$J77)) | L77: =IF($B77="","",MAX(0,-$J77)) | M77: =IF($B77="","",IF(AND($F77=0,$H77=0,$G77=0),"Aucun mouvement",IF($J77>0,"On lui doit",IF($J77<0,"Avancé","Soldé"))))
D78: =IF($B78="","",COUNTIFS(Dechargements!$C$5:$C$1002,$B78,Dechargements!$H$5:$H$1002,"Fait")) | E78: =IF($B78="","",SUMIFS(Dechargements!$E$5:$E$1002,Dechargements!$C$5:$C$1002,$B78,Dechargements!$H$5:$H$1002,"Fait")) | F78: =IF($B78="","",SUMIFS(Dechargements!$G$5:$G$1002,Dechargements!$C$5:$C$1002,$B78,Dechargements!$H$5:$H$1002,"Fait")) | G78: =IF($B78="","",SUMIFS(Dechargements!$G$5:$G$1002,Dechargements!$C$5:$C$1002,$B78)-$F78-SUMIFS(Dechargements!$G$5:$G$1002,Dechargements!$C$5:$C$1002,$B78,Dechargements!$H$5:$H$1002,"Annulé")) | H78: =IF($B78="","",SUMIFS(Paiements!$I$5:$I$2000,Paiements!$C$5:$C$2000,$B78,Paiements!$L$5:$L$2000,"Payé")) | I78: =IF($B78="","",SUMIFS(Paiements!$I$5:$I$2000,Paiements!$C$5:$C$2000,$B78,Paiements!$L$5:$L$2000,"En attente")) | J78: =IF($B78="","",$F78-$H78) | K78: =IF($B78="","",MAX(0,$J78)) | L78: =IF($B78="","",MAX(0,-$J78)) | M78: =IF($B78="","",IF(AND($F78=0,$H78=0,$G78=0),"Aucun mouvement",IF($J78>0,"On lui doit",IF($J78<0,"Avancé","Soldé"))))
D79: =IF($B79="","",COUNTIFS(Dechargements!$C$5:$C$1002,$B79,Dechargements!$H$5:$H$1002,"Fait")) | E79: =IF($B79="","",SUMIFS(Dechargements!$E$5:$E$1002,Dechargements!$C$5:$C$1002,$B79,Dechargements!$H$5:$H$1002,"Fait")) | F79: =IF($B79="","",SUMIFS(Dechargements!$G$5:$G$1002,Dechargements!$C$5:$C$1002,$B79,Dechargements!$H$5:$H$1002,"Fait")) | G79: =IF($B79="","",SUMIFS(Dechargements!$G$5:$G$1002,Dechargements!$C$5:$C$1002,$B79)-$F79-SUMIFS(Dechargements!$G$5:$G$1002,Dechargements!$C$5:$C$1002,$B79,Dechargements!$H$5:$H$1002,"Annulé")) | H79: =IF($B79="","",SUMIFS(Paiements!$I$5:$I$2000,Paiements!$C$5:$C$2000,$B79,Paiements!$L$5:$L$2000,"Payé")) | I79: =IF($B79="","",SUMIFS(Paiements!$I$5:$I$2000,Paiements!$C$5:$C$2000,$B79,Paiements!$L$5:$L$2000,"En attente")) | J79: =IF($B79="","",$F79-$H79) | K79: =IF($B79="","",MAX(0,$J79)) | L79: =IF($B79="","",MAX(0,-$J79)) | M79: =IF($B79="","",IF(AND($F79=0,$H79=0,$G79=0),"Aucun mouvement",IF($J79>0,"On lui doit",IF($J79<0,"Avancé","Soldé"))))
... D103: =IF($B103="","",COUNTIFS(Dechargements!$C$5:$C$1002,$B103,Dechargements!$H$5:$H$1002,"Fait")) | E103: =IF($B103="","",SUMIFS(Dechargements!$E$5:$E$1002,Dechargements!$C$5:$C$1002,$B103,Dechargements!$H$5:$H$1002,"Fait")) | F103: =IF($B103="","",SUMIFS(Dechargements!$G$5:$G$1002,Dechargements!$C$5:$C$1002,$B103,Dechargements!$H$5:$H$1002,"Fait")) | G103: =IF($B103="","",SUMIFS(Dechargements!$G$5:$G$1002,Dechargements!$C$5:$C$1002,$B103)-$F103-SUMIFS(Dechargements!$G$5:$G$1002,Dechargements!$C$5:$C$1002,$B103,Dechargements!$H$5:$H$1002,"Annulé")) | H103: =IF($B103="","",SUMIFS(Paiements!$I$5:$I$2000,Paiements!$C$5:$C$2000,$B103,Paiements!$L$5:$L$2000,"Payé")) | I103: =IF($B103="","",SUMIFS(Paiements!$I$5:$I$2000,Paiements!$C$5:$C$2000,$B103,Paiements!$L$5:$L$2000,"En attente")) | J103: =IF($B103="","",$F103-$H103) | K103: =IF($B103="","",MAX(0,$J103)) | L103: =IF($B103="","",MAX(0,-$J103)) | M103: =IF($B103="","",IF(AND($F103=0,$H103=0,$G103=0),"Aucun mouvement",IF($J103>0,"On lui doit",IF($J103<0,"Avancé","Soldé"))))

Sheet Dechargements
A1: Déchargements (réception des camions)
A2: Une ligne = un camion déchargé. Saisissez la date, le N° du camion, le fournisseur, le produit, le poids pesé (kg) et le prix du kg (en général de 300 à 345 FCFA, réglable dans Listes). Le montant se calcule tout seul : poids × prix. Mettez le statut « Fait » seulement quand le camion est entièrement déchargé : seuls les camions « Fait » peuvent être payés. Colonnes grises = automatiques, ne pas écrire dedans. Les paiements sont imputés du camion le plus ancien au plus récent : gardez la liste dans l'ordre chronologique. Montants en FCFA. La ligne 5 est un exemple à supprimer.
A4: Date_Dechargement | B4: N_Camion | C4: Fournisseur | D4: Produit | E4: Poids_Kg | F4: Prix_Kg | G4: Montant_Total | H4: Statut_Dechargement | I4: Reste_A_Payer | J4: Situation_Paiement | K4: Observations | L4: aide
G5: =IF(OR($E5="",$F5=""),"",ROUND($E5*$F5,0)) | I5: =IF(OR($C5="",$G5="",$H5<>"Fait"),"",MIN($G5,MAX(0,SUMIFS($G$5:$G5,$C$5:$C5,$C5,$H$5:$H5,"Fait")-SUMIFS(Paiements!$I$5:$I$2000,Paiements!$C$5:$C$2000,$C5,Paiements!$L$5:$L$2000,"Payé")))) | J5: =IF(OR($C5="",$G5=""),"",IF($H5="Annulé","Annulé",IF($H5<>"Fait","Non payable (déchargement non fait)",IF($I5=0,"Payé",IF($I5<$G5,"Partiellement payé","À payer"))))) | L5: =IF(AND($C5<>"",$C5=Controle_Paiement!$B$4,$J5<>"Payé",$J5<>"Annulé",$J5<>""),1,"")
G6: =IF(OR($E6="",$F6=""),"",ROUND($E6*$F6,0)) | I6: =IF(OR($C6="",$G6="",$H6<>"Fait"),"",MIN($G6,MAX(0,SUMIFS($G$5:$G6,$C$5:$C6,$C6,$H$5:$H6,"Fait")-SUMIFS(Paiements!$I$5:$I$2000,Paiements!$C$5:$C$2000,$C6,Paiements!$L$5:$L$2000,"Payé")))) | J6: =IF(OR($C6="",$G6=""),"",IF($H6="Annulé","Annulé",IF($H6<>"Fait","Non payable (déchargement non fait)",IF($I6=0,"Payé",IF($I6<$G6,"Partiellement payé","À payer"))))) | L6: =IF(AND($C6<>"",$C6=Controle_Paiement!$B$4,$J6<>"Payé",$J6<>"Annulé",$J6<>""),1,"")
G7: =IF(OR($E7="",$F7=""),"",ROUND($E7*$F7,0)) | I7: =IF(OR($C7="",$G7="",$H7<>"Fait"),"",MIN($G7,MAX(0,SUMIFS($G$5:$G7,$C$5:$C7,$C7,$H$5:$H7,"Fait")-SUMIFS(Paiements!$I$5:$I$2000,Paiements!$C$5:$C$2000,$C7,Paiements!$L$5:$L$2000,"Payé")))) | J7: =IF(OR($C7="",$G7=""),"",IF($H7="Annulé","Annulé",IF($H7<>"Fait","Non payable (déchargement non fait)",IF($I7=0,"Payé",IF($I7<$G7,"Partiellement payé","À payer"))))) | L7: =IF(AND($C7<>"",$C7=Controle_Paiement!$B$4,$J7<>"Payé",$J7<>"Annulé",$J7<>""),1,"")
G8: =IF(OR($E8="",$F8=""),"",ROUND($E8*$F8,0)) | I8: =IF(OR($C8="",$G8="",$H8<>"Fait"),"",MIN($G8,MAX(0,SUMIFS($G$5:$G8,$C$5:$C8,$C8,$H$5:$H8,"Fait")-SUMIFS(Paiements!$I$5:$I$2000,Paiements!$C$5:$C$2000,$C8,Paiements!$L$5:$L$2000,"Payé")))) | J8: =IF(OR($C8="",$G8=""),"",IF($H8="Annulé","Annulé",IF($H8<>"Fait","Non payable (déchargement non fait)",IF($I8=0,"Payé",IF($I8<$G8,"Partiellement payé","À payer"))))) | L8: =IF(AND($C8<>"",$C8=Controle_Paiement!$B$4,$J8<>"Payé",$J8<>"Annulé",$J8<>""),1,"")
G9: =IF(OR($E9="",$F9=""),"",ROUND($E9*$F9,0)) | I9: =IF(OR($C9="",$G9="",$H9<>"Fait"),"",MIN($G9,MAX(0,SUMIFS($G$5:$G9,$C$5:$C9,$C9,$H$5:$H9,"Fait")-SUMIFS(Paiements!$I$5:$I$2000,Paiements!$C$5:$C$2000,$C9,Paiements!$L$5:$L$2000,"Payé")))) | J9: =IF(OR($C9="",$G9=""),"",IF($H9="Annulé","Annulé",IF($H9<>"Fait","Non payable (déchargement non fait)",IF($I9=0,"Payé",IF($I9<$G9,"Partiellement payé","À payer"))))) | L9: =IF(AND($C9<>"",$C9=Controle_Paiement!$B$4,$J9<>"Payé",$J9<>"Annulé",$J9<>""),1,"")
G10: =IF(OR($E10="",$F10=""),"",ROUND($E10*$F10,0)) | I10: =IF(OR($C10="",$G10="",$H10<>"Fait"),"",MIN($G10,MAX(0,SUMIFS($G$5:$G10,$C$5:$C10,$C10,$H$5:$H10,"Fait")-SUMIFS(Paiements!$I$5:$I$2000,Paiements!$C$5:$C$2000,$C10,Paiements!$L$5:$L$2000,"Payé")))) | J10: =IF(OR($C10="",$G10=""),"",IF($H10="Annulé","Annulé",IF($H10<>"Fait","Non payable (déchargement non fait)",IF($I10=0,"Payé",IF($I10<$G10,"Partiellement payé","À payer"))))) | L10: =IF(AND($C10<>"",$C10=Controle_Paiement!$B$4,$J10<>"Payé",$J10<>"Annulé",$J10<>""),1,"")
G11: =IF(OR($E11="",$F11=""),"",ROUND($E11*$F11,0)) | I11: =IF(OR($C11="",$G11="",$H11<>"Fait"),"",MIN($G11,MAX(0,SUMIFS($G$5:$G11,$C$5:$C11,$C11,$H$5:$H11,"Fait")-SUMIFS(Paiements!$I$5:$I$2000,Paiements!$C$5:$C$2000,$C11,Paiements!$L$5:$L$2000,"Payé")))) | J11: =IF(OR($C11="",$G11=""),"",IF($H11="Annulé","Annulé",IF($H11<>"Fait","Non payable (déchargement non fait)",IF($I11=0,"Payé",IF($I11<$G11,"Partiellement payé","À payer"))))) | L11: =IF(AND($C11<>"",$C11=Controle_Paiement!$B$4,$J11<>"Payé",$J11<>"Annulé",$J11<>""),1,"")
G12: =IF(OR($E12="",$F12=""),"",ROUND($E12*$F12,0)) | I12: =IF(OR($C12="",$G12="",$H12<>"Fait"),"",MIN($G12,MAX(0,SUMIFS($G$5:$G12,$C$5:$C12,$C12,$H$5:$H12,"Fait")-SUMIFS(Paiements!$I$5:$I$2000,Paiements!$C$5:$C$2000,$C12,Paiements!$L$5:$L$2000,"Payé")))) | J12: =IF(OR($C12="",$G12=""),"",IF($H12="Annulé","Annulé",IF($H12<>"Fait","Non payable (déchargement non fait)",IF($I12=0,"Payé",IF($I12<$G12,"Partiellement payé","À payer"))))) | L12: =IF(AND($C12<>"",$C12=Controle_Paiement!$B$4,$J12<>"Payé",$J12<>"Annulé",$J12<>""),1,"")
G13: =IF(OR($E13="",$F13=""),"",ROUND($E13*$F13,0)) | I13: =IF(OR($C13="",$G13="",$H13<>"Fait"),"",MIN($G13,MAX(0,SUMIFS($G$5:$G13,$C$5:$C13,$C13,$H$5:$H13,"Fait")-SUMIFS(Paiements!$I$5:$I$2000,Paiements!$C$5:$C$2000,$C13,Paiements!$L$5:$L$2000,"Payé")))) | J13: =IF(OR($C13="",$G13=""),"",IF($H13="Annulé","Annulé",IF($H13<>"Fait","Non payable (déchargement non fait)",IF($I13=0,"Payé",IF($I13<$G13,"Partiellement payé","À payer"))))) | L13: =IF(AND($C13<>"",$C13=Controle_Paiement!$B$4,$J13<>"Payé",$J13<>"Annulé",$J13<>""),1,"")
G14: =IF(OR($E14="",$F14=""),"",ROUND($E14*$F14,0)) | I14: =IF(OR($C14="",$G14="",$H14<>"Fait"),"",MIN($G14,MAX(0,SUMIFS($G$5:$G14,$C$5:$C14,$C14,$H$5:$H14,"Fait")-SUMIFS(Paiements!$I$5:$I$2000,Paiements!$C$5:$C$2000,$C14,Paiements!$L$5:$L$2000,"Payé")))) | J14: =IF(OR($C14="",$G14=""),"",IF($H14="Annulé","Annulé",IF($H14<>"Fait","Non payable (déchargement non fait)",IF($I14=0,"Payé",IF($I14<$G14,"Partiellement payé","À payer"))))) | L14: =IF(AND($C14<>"",$C14=Controle_Paiement!$B$4,$J14<>"Payé",$J14<>"Annulé",$J14<>""),1,"")
G15: =IF(OR($E15="",$F15=""),"",ROUND($E15*$F15,0)) | I15: =IF(OR($C15="",$G15="",$H15<>"Fait"),"",MIN($G15,MAX(0,SUMIFS($G$5:$G15,$C$5:$C15,$C15,$H$5:$H15,"Fait")-SUMIFS(Paiements!$I$5:$I$2000,Paiements!$C$5:$C$2000,$C15,Paiements!$L$5:$L$2000,"Payé")))) | J15: =IF(OR($C15="",$G15=""),"",IF($H15="Annulé","Annulé",IF($H15<>"Fait","Non payable (déchargement non fait)",IF($I15=0,"Payé",IF($I15<$G15,"Partiellement payé","À payer"))))) | L15: =IF(AND($C15<>"",$C15=Controle_Paiement!$B$4,$J15<>"Payé",$J15<>"Annulé",$J15<>""),1,"")
G16: =IF(OR($E16="",$F16=""),"",ROUND($E16*$F16,0)) | I16: =IF(OR($C16="",$G16="",$H16<>"Fait"),"",MIN($G16,MAX(0,SUMIFS($G$5:$G16,$C$5:$C16,$C16,$H$5:$H16,"Fait")-SUMIFS(Paiements!$I$5:$I$2000,Paiements!$C$5:$C$2000,$C16,Paiements!$L$5:$L$2000,"Payé")))) | J16: =IF(OR($C16="",$G16=""),"",IF($H16="Annulé","Annulé",IF($H16<>"Fait","Non payable (déchargement non fait)",IF($I16=0,"Payé",IF($I16<$G16,"Partiellement payé","À payer"))))) | L16: =IF(AND($C16<>"",$C16=Controle_Paiement!$B$4,$J16<>"Payé",$J16<>"Annulé",$J16<>""),1,"")
